Workbook

Sheet Расчёт
A1: Waystar Group · Расчёт оплаты 75/25 по показателям
A2: Итого = 75%×Оклад + (25%×Оклад)×Выполнение×Коэффициент компании×Стоп-фактор (переменная — предел 150%)
A4: Коэффициент компании (по чистой прибыли, 0,7–1,3): | F4: 1 | G4: ← 100% плана прибыли = 1,00
A6: № | B6: Сотрудник | C6: Должность | D6: Линия | E6: Оклад (100%), ₸ | F6: Постоянная 75%, ₸ | G6: Переменная целевая 25%, ₸ | H6: Выполнение | I6: Стоп-фактор | J6: Переменная к выплате, ₸ | K6: ИТОГО к выплате, ₸ | L6: Разница к текущему, ₸
A7: 1 | B7: Аманбекова Айгуль | C7: Отдел персонала (руководитель) | D7: Поддержка | E7: 1246243 | F7: =E7*0.75 | G7: =E7*0.25 | H7: =Показатели!E11 | I7: 1 | J7: =G7*MIN(1.5,H7*$F$4*I7) | K7: =F7+J7 | L7: =K7-E7
A8: 2 | B8: Аубакиров Алимбек | C8: Финансовый директор | D8: Передовая | E8: 4347889 | F8: =E8*0.75 | G8: =E8*0.25 | H8: =Показатели!E20 | I8: 1 | J8: =G8*MIN(1.5,H8*$F$4*I8) | K8: =F8+J8 | L8: =K8-E8
A9: 3 | B9: Байльденова Шолпан | C9: Менеджер по персоналу | D9: Поддержка | E9: 614931 | F9: =E9*0.75 | G9: =E9*0.25 | H9: =Показатели!E29 | I9: 1 | J9: =G9*MIN(1.5,H9*$F$4*I9) | K9: =F9+J9 | L9: =K9-E9
A10: 4 | B10: Данияр Алим | C10: Генеральный директор | D10: Передовая | E10: 1246243 | F10: =E10*0.75 | G10: =E10*0.25 | H10: =Показатели!E38 | I10: 1 | J10: =G10*MIN(1.5,H10*$F$4*I10) | K10: =F10+J10 | L10: =K10-E10
A11: 5 | B11: Доолоткулов Данияр | C11: Начальник отдела логистики | D11: Передовая | E11: 1246243 | F11: =E11*0.75 | G11: =E11*0.25 | H11: =Показатели!E47 | I11: 1 | J11: =G11*MIN(1.5,H11*$F$4*I11) | K11: =F11+J11 | L11: =K11-E11
A12: 6 | B12: Жунусова Камила | C12: Менеджер по логистике | D12: Передовая | E12: 230896 | F12: =E12*0.75 | G12: =E12*0.25 | H12: =Показатели!E56 | I12: 1 | J12: =G12*MIN(1.5,H12*$F$4*I12) | K12: =F12+J12 | L12: =K12-E12
A13: 7 | B13: Сейтқадыр Дарын | C13: Менеджер по логистике | D13: Передовая | E13: 236143 | F13: =E13*0.75 | G13: =E13*0.25 | H13: =Показатели!E65 | I13: 1 | J13: =G13*MIN(1.5,H13*$F$4*I13) | K13: =F13+J13 | L13: =K13-E13
A14: 8 | B14: Серикбаев Адиль | C14: Президент | D14: Передовая | E14: 6000139 | F14: =E14*0.75 | G14: =E14*0.25 | H14: =Показатели!E74 | I14: 1 | J14: =G14*MIN(1.5,H14*$F$4*I14) | K14: =F14+J14 | L14: =K14-E14
A15: 9 | B15: Таджимурадова Асем | C15: Менеджер по закрытию | D15: Передовая | E15: 378788 | F15: =E15*0.75 | G15: =E15*0.25 | H15: =Показатели!E82 | I15: 1 | J15: =G15*MIN(1.5,H15*$F$4*I15) | K15: =F15+J15 | L15: =K15-E15
A16: 10 | B16: Ташметов Сакен | C16: Юрист | D16: Поддержка | E16: 1246243 | F16: =E16*0.75 | G16: =E16*0.25 | H16: =Показатели!E91 | I16: 1 | J16: =G16*MIN(1.5,H16*$F$4*I16) | K16: =F16+J16 | L16: =K16-E16
A17: 11 | B17: Унбетпаев Ернар | C17: Операционный директор | D17: Передовая | E17: 1873611 | F17: =E17*0.75 | G17: =E17*0.25 | H17: =Показатели!E100 | I17: 1 | J17: =G17*MIN(1.5,H17*$F$4*I17) | K17: =F17+J17 | L17: =K17-E17
A18: 12 | B18: Белова Полина | C18: Менеджер по логистике (младший) | D18: Передовая | E18: 173011 | F18: =E18*0.75 | G18: =E18*0.25 | H18: =Показатели!E109 | I18: 1 | J18: =G18*MIN(1.5,H18*$F$4*I18) | K18: =F18+J18 | L18: =K18-E18
A19: 13 | B19: Сибагатов Хамардин | C19: Менеджер по логистике (старший) | D19: Передовая | E19: 993718 | F19: =E19*0.75 | G19: =E19*0.25 | H19: =Показатели!E118 | I19: 1 | J19: =G19*MIN(1.5,H19*$F$4*I19) | K19: =F19+J19 | L19: =K19-E19
B20: ИТОГО | E20: =SUM(E7:E19) | F20: =SUM(F7:F19) | G20: =SUM(G7:G19) | J20: =SUM(J7:J19) | K20: =SUM(K7:K19) | L20: =SUM(L7:L19)
B22: Фонд (оклады) в год, ₸: | E22: =E20*12 | J22: Под результатом (25%) в год: | K22: =G20*12
B23: Итого к выплате в год, ₸: | K23: =K20*12
B25: • Жёлтые ячейки — вводимые: Коэффициент компании (F4), Стоп-фактор по строке, выполнение показателей на листе «Показатели».
B26: • Передовая линия — есть личная/командная цель по прибыли (валовая/чистая); Поддержка — доля переменной на чистой прибыли компании.
B27: • Переменная = (25%×оклад) × выполнение × коэффициент компании × стоп-фактор, предел 150% целевой. При 100% и коэффициенте 1,0 «Итого» = текущему окладу.
B28: • Оклад — начисленный (база деления 75/25). Пороги и коэффициент K целей по прибыли настраиваются по управленческой отчётности.

Sheet Показатели
A1: Waystar Group · Показатели эффективности (модель 75/25)
A2: Введите фактическое выполнение по каждому показателю (жёлтые ячейки, 0–150%). Зелёные строки — цель по прибыли (валовая/чистая). Итоговый процент выполнения = сумма(вес×выполнение) переносится в лист «Расчёт».
B4: 1. Аманбекова Айгуль — Отдел персонала (руководитель) [ПОДДЕРЖКА]
B5: Показатель | C5: Вес | D5: Выполнение, % | E5: Вклад
B6: Чистая прибыль компании (общий) | C6: 0.25 | D6: 1 | E6: =C6*D6
B7: Удержание персонала / текучесть | C7: 0.25 | D7: 1 | E7: =C7*D7
B8: Срок закрытия ключевых вакансий | C8: 0.2 | D8: 1 | E8: =C8*D8
B9: Вовлечённость персонала (опрос) | C9: 0.15 | D9: 1 | E9: =C9*D9
B10: Внедрение мотивации / бюджет фонда | C10: 0.15 | D10: 1 | E10: =C10*D10
B11: Итоговое выполнение | C11: =SUM(C6:C10) | E11: =SUM(E6:E10)
B13: 2. Аубакиров Алимбек — Финансовый директор [ПЕРЕДОВАЯ ЛИНИЯ]
B14: Показатель | C14: Вес | D14: Выполнение, % | E14: Вклад
B15: Чистая прибыль компании к плану | C15: 0.35 | D15: 1 | E15: =C15*D15
B16: Запас денежных средств | C16: 0.2 | D16: 1 | E16: =C16*D16
B17: Оборот дебиторской задолженности | C17: 0.15 | D17: 1 | E17: =C17*D17
B18: Точность бюджета | C18: 0.15 | D18: 1 | E18: =C18*D18
B19: Привлечение финансирования | C19: 0.15 | D19: 1 | E19: =C19*D19
B20: Итоговое выполнение | C20: =SUM(C15:C19) | E20: =SUM(E15:E19)
B22: 3. Байльденова Шолпан — Менеджер по персоналу [ПОДДЕРЖКА]
B23: Показатель | C23: Вес | D23: Выполнение, % | E23: Вклад
B24: Чистая прибыль компании (общий) | C24: 0.25 | D24: 1 | E24: =C24*D24
B25: Срок закрытия вакансий | C25: 0.2 | D25: 1 | E25: =C25*D25
B26: Кадровый учёт без нарушений | C26: 0.2 | D26: 1 | E26: =C26*D26
B27: Точность расчёта зарплаты | C27: 0.2 | D27: 1 | E27: =C27*D27
B28: Адаптация новых сотрудников | C28: 0.15 | D28: 1 | E28: =C28*D28
B29: Итоговое выполнение | C29: =SUM(C24:C28) | E29: =SUM(E24:E28)
B31: 4. Данияр Алим — Генеральный директор [ПЕРЕДОВАЯ ЛИНИЯ]
B32: Показатель | C32: Вес | D32: Выполнение, % | E32: Вклад
B33: Чистая прибыль компании к плану | C33: 0.4 | D33: 1 | E33: =C33*D33
B34: Валовая прибыль / рентабельность | C34: 0.2 | D34: 1 | E34: =C34*D34
B35: Выручка к плану | C35: 0.2 | D35: 1 | E35: =C35*D35
B36: Выполнение годового плана | C36: 0.15 | D36: 1 | E36: =C36*D36
B37: Удержание клиентов | C37: 0.05 | D37: 1 | E37: =C37*D37
B38: Итоговое выполнение | C38: =SUM(C33:C37) | E38: =SUM(E33:E37)
B40: 5. Доолоткулов Данияр — Начальник отдела логистики [ПЕРЕДОВАЯ ЛИНИЯ]
B41: Показатель | C41: Вес | D41: Выполнение, % | E41: Вклад
B42: Валовая прибыль отдела перевозок к плану | C42: 0.4 | D42: 1 | E42: =C42*D42
B43: Соблюдение сроков доставки | C43: 0.2 | D43: 1 | E43: =C43*D43
B44: Себестоимость перевозки на рейс/тонну | C44: 0.2 | D44: 1 | E44: =C44*D44
B45: Загрузка транспорта / порожний пробег | C45: 0.1 | D45: 1 | E45: =C45*D45
...
