Workbook

Sheet Дашборд
A1: WAYSTAR GROUP · Управленческая отчётность
A2: ТОО «WayStar Group» · БИН 240340014287 · транспортно-экспедиторские услуги (ж/д цистерны и вагоны) · июль 2026 · все суммы в тенге
A4: КЛЮЧЕВЫЕ ПОКАЗАТЕЛИ ПЕРИОДА, ₸
A5: Операционная выручка | C5: Валовая прибыль | E5: Операционная прибыль
A6: ='ОПиУ'!C5 | C6: ='ОПиУ'!C13 | E6: ='ОПиУ'!C26
A7: выручка за услуги | C7: маржа 23.0% | E7: рентабельность 14.5%
A9: Операционный ден. поток | C9: Чистый результат (кассовый) | E9: Валовой оборот (5 счетов)
A10: ='ОДДС'!C12 | C10: ='ОПиУ'!C33 | E10: ='Денежные средства'!C13
A11: от операц. деятельности | C11: 12.0% от выручки | E11: 438 операций · «шум» ≈79%
A13: ЭКСПРЕСС-P&L, ₸
A14: Выручка | C14: ='ОПиУ'!C5
A15: (−) Себестоимость | C15: ='ОПиУ'!C6
A16: Валовая прибыль | C16: ='ОПиУ'!C13
A17: (−) Операционные расходы (ФОТ, админ, налоги) | C17: ='ОПиУ'!C15+'ОПиУ'!C18+'ОПиУ'!C25
A18: Операционная прибыль (EBITDA-прокси) | C18: ='ОПиУ'!C26
A19: (−) Финансовые и прочие (нетто) | C19: ='ОПиУ'!C33-'ОПиУ'!C26
A20: Чистый результат периода (кассовый) | C20: ='ОПиУ'!C33
A22: ⚠ КЛЮЧЕВЫЕ РИСКИ
A23: • Концентрация клиентов: QAZAQ-ASTYQ ≈ 49% выручки, топ-2 ≈ 70% — потеря клиента критична.
A24: • Нулевой денежный буфер: остатки по всем счетам к концу месяца ≈ 0, подушки ликвидности нет.
A25: • Валютный риск: RUB — только расход; по USD расход превышает приток; выручка в тенге.
A26: • Займы связанным лицам: выдано 48 млн ₸ (Серикбаев А.Д.) при обслуживании кредита Bank RBK.

Sheet ОПиУ
A1: Отчёт о прибылях и убытках (ОПиУ)
A2: Управленческий P&L · кассовый метод · тенге · ячейки связаны формулами с листом «Реестр операций»
A4: Показатель | C4: Сумма, ₸ | D4: % выручки
A5: ВЫРУЧКА от услуг (ТЭО, аренда вагонов/цистерн) | C5: =SUMIFS('Реестр операций'!$M$5:$M$442,'Реестр операций'!$O$5:$O$442,"Выручка") | D5: =IF($C$5=0,0,C5/$C$5)
A6: СЕБЕСТОИМОСТЬ услуг | C6: =-SUMIFS('Реестр операций'!$L$5:$L$442,'Реестр операций'!$O$5:$O$442,"Себестоимость") | D6: =IF($C$5=0,0,C6/$C$5)
A7: Зарубежные перевозчики/экспедиторы | C7: =-SUMIFS('Реестр операций'!$L$5:$L$442,'Реестр операций'!$P$5:$P$442,"Зарубежные перевозчики/экспедиторы") | D7: =IF($C$5=0,0,C7/$C$5)
A8: Тариф КТЖ (ж/д перевозки) | C8: =-SUMIFS('Реестр операций'!$L$5:$L$442,'Реестр операций'!$P$5:$P$442,"Тариф КТЖ (ж/д перевозки)") | D8: =IF($C$5=0,0,C8/$C$5)
A9: Аренда/предоставление вагонов | C9: =-SUMIFS('Реестр операций'!$L$5:$L$442,'Реестр операций'!$P$5:$P$442,"Аренда/предоставление вагонов") | D9: =IF($C$5=0,0,C9/$C$5)
A10: Операторы вагонов (КТТ и др.) | C10: =-SUMIFS('Реестр операций'!$L$5:$L$442,'Реестр операций'!$P$5:$P$442,"Операторы вагонов (КТТ и др.)") | D10: =IF($C$5=0,0,C10/$C$5)
A11: Прочие ж/д и ТЭУ услуги | C11: =-SUMIFS('Реестр операций'!$L$5:$L$442,'Реестр операций'!$P$5:$P$442,"Прочие ж/д и ТЭУ услуги") | D11: =IF($C$5=0,0,C11/$C$5)
A12: Ремонт вагонов и узлов | C12: =-SUMIFS('Реестр операций'!$L$5:$L$442,'Реестр операций'!$P$5:$P$442,"Ремонт вагонов и узлов") | D12: =IF($C$5=0,0,C12/$C$5)
A13: ВАЛОВАЯ ПРИБЫЛЬ | C13: =C5+C6 | D13: =IF($C$5=0,0,C13/$C$5)
A14: ОПЕРАЦИОННЫЕ РАСХОДЫ
A15: Фонд оплаты труда | C15: =-SUMIFS('Реестр операций'!$L$5:$L$442,'Реестр операций'!$O$5:$O$442,"ФОТ") | D15: =IF($C$5=0,0,C15/$C$5)
A16: Зарплата | C16: =-SUMIFS('Реестр операций'!$L$5:$L$442,'Реестр операций'!$P$5:$P$442,"Зарплата") | D16: =IF($C$5=0,0,C16/$C$5)
A17: Командировки и подотчёт | C17: =-SUMIFS('Реестр операций'!$L$5:$L$442,'Реестр операций'!$P$5:$P$442,"Командировки и подотчёт") | D17: =IF($C$5=0,0,C17/$C$5)
A18: Административные и офисные | C18: =-SUMIFS('Реестр операций'!$L$5:$L$442,'Реестр операций'!$O$5:$O$442,"Админ/офис") | D18: =IF($C$5=0,0,C18/$C$5)
A19: Офис, аренда помещений, хоз. | C19: =-SUMIFS('Реестр операций'!$L$5:$L$442,'Реестр операций'!$P$5:$P$442,"Офис, аренда помещений, хоз.") | D19: =IF($C$5=0,0,C19/$C$5)
A20: Проф. услуги (бухг./юр./конс.) | C20: =-SUMIFS('Реестр операций'!$L$5:$L$442,'Реестр операций'!$P$5:$P$442,"Проф. услуги (бухг./юр./конс.)") | D20: =IF($C$5=0,0,C20/$C$5)
A21: Связь и ИТ | C21: =-SUMIFS('Реестр операций'!$L$5:$L$442,'Реестр операций'!$P$5:$P$442,"Связь и ИТ") | D21: =IF($C$5=0,0,C21/$C$5)
A22: Маркетинг и представит. | C22: =-SUMIFS('Реестр операций'!$L$5:$L$442,'Реестр операций'!$P$5:$P$442,"Маркетинг и представит.") | D22: =IF($C$5=0,0,C22/$C$5)
A23: Хоз. расходы и материалы | C23: =-SUMIFS('Реестр операций'!$L$5:$L$442,'Реестр операций'!$P$5:$P$442,"Хоз. расходы и материалы") | D23: =IF($C$5=0,0,C23/$C$5)
A24: Страхование | C24: =-SUMIFS('Реестр операций'!$L$5:$L$442,'Реестр операций'!$P$5:$P$442,"Страхование") | D24: =IF($C$5=0,0,C24/$C$5)
A25: Налоги и отчисления | C25: =-SUMIFS('Реестр операций'!$L$5:$L$442,'Реестр операций'!$O$5:$O$442,"Налоги") | D25: =IF($C$5=0,0,C25/$C$5)
A26: ОПЕРАЦИОННАЯ ПРИБЫЛЬ (EBITDA-прокси) | C26: =C13+C15+C18+C25 | D26: =IF($C$5=0,0,C26/$C$5)
A27: ФИНАНСОВЫЕ РАСХОДЫ
A28: Проценты по кредиту | C28: =-SUMIFS('Реестр операций'!$L$5:$L$442,'Реестр операций'!$P$5:$P$442,"Проценты по кредиту") | D28: =IF($C$5=0,0,C28/$C$5)
A29: Финансовый лизинг | C29: =-SUMIFS('Реестр операций'!$L$5:$L$442,'Реестр операций'!$P$5:$P$442,"Финансовый лизинг") | D29: =IF($C$5=0,0,C29/$C$5)
A30: Банковские комиссии | C30: =-SUMIFS('Реестр операций'!$L$5:$L$442,'Реестр операций'!$P$5:$P$442,"Банковские комиссии") | D30: =IF($C$5=0,0,C30/$C$5)
A31: Проценты по депозиту (доход) | C31: =SUMIFS('Реестр операций'!$M$5:$M$442,'Реестр операций'!$P$5:$P$442,"Проценты по депозиту") | D31: =IF($C$5=0,0,C31/$C$5)
A32: ПРОЧИЕ / РАЗОВЫЕ (возвраты авансов, спонсорство) | C32: =-(SUMIFS('Реестр операций'!$L$5:$L$442,'Реестр операций'!$O$5:$O$442,"Прочее")-SUMIFS('Реестр операций'!$M$5:$M$442,'Реестр операций'!$O$5:$O$442,"Прочее")) | D32: =IF($C$5=0,0,C32/$C$5)
A33: ЧИСТЫЙ РЕЗУЛЬТАТ ПЕРИОДА (кассовый) | C33: =C26+C28+C29+C30+C31+C32 | D33: =IF($C$5=0,0,C33/$C$5)
A35: Кассовый метод по банковским выпискам. Тело кредита (66,7 млн ₸) и выданные займы (48,1 млн ₸) — движение денег, отражены в ОДДС, а не в ОПиУ; в прибыли учтены только проценты по кредиту. Не учитывает амортизацию, начисления и незакрытые взаиморасчёты. Все суммы — формулы SUMIFS по листу «Реестр операций».

Sheet ОДДС
A1: Отчёт о движении денежных средств (ОДДС)
A2: Прямой метод · тенге · ячейки связаны с реестром · сверка остатка
A4: Статья движения денежных средств | C4: Сумма, ₸
A5: Остаток денежных средств на начало периода | C5: 73255.65
A6: ОПЕРАЦИОННАЯ ДЕЯТЕЛЬНОСТЬ
A7: Поступления от клиентов за услуги | C7: =SUMIFS('Реестр операций'!$M$5:$M$442,'Реестр операций'!$O$5:$O$442,"Выручка")
A8: Оплата перевозчикам, КТЖ, аренда вагонов (себестоимость) | C8: =-SUMIFS('Реестр операций'!$L$5:$L$442,'Реестр операций'!$O$5:$O$442,"Себестоимость")
A9: Оплата труда и командировки | C9: =-SUMIFS('Реестр операций'!$L$5:$L$442,'Реестр операций'!$O$5:$O$442,"ФОТ")
A10: Административные и офисные расходы | C10: =-SUMIFS('Реестр операций'!$L$5:$L$442,'Реестр операций'!$O$5:$O$442,"Админ/офис")
A11: Налоги и отчисления | C11: =-SUMIFS('Реестр операций'!$L$5:$L$442,'Реестр операций'!$O$5:$O$442,"Налоги")
A12: Чистый поток от операционной деятельности | C12: =SUM(C7:C11)
A13: ИНВЕСТИЦИОННАЯ ДЕЯТЕЛЬНОСТЬ
A14: Выдача займов (связанным лицам) | C14: =-SUMIFS('Реестр операций'!$L$5:$L$442,'Реестр операций'!$P$5:$P$442,"Выданные займы (связ. лица)")
A15: Возврат ранее выданных займов | C15: =SUMIFS('Реестр операций'!$M$5:$M$442,'Реестр операций'!$P$5:$P$442,"Возврат выданных займов")
A16: Чистый поток от инвестиционной деятельности | C16: =C14+C15
A17: ФИНАНСОВАЯ ДЕЯТЕЛЬНОСТЬ
A18: Погашение тела кредита | C18: =-SUMIFS('Реестр операций'!$L$5:$L$442,'Реестр операций'!$P$5:$P$442,"Погашение кредита — тело")
A19: Проценты по кредиту | C19: =-SUMIFS('Реестр операций'!$L$5:$L$442,'Реестр операций'!$P$5:$P$442,"Проценты по кредиту")
A20: Финансовый лизинг | C20: =-SUMIFS('Реестр операций'!$L$5:$L$442,'Реестр операций'!$P$5:$P$442,"Финансовый лизинг")
A21: Банковские комиссии | C21: =-SUMIFS('Реестр операций'!$L$5:$L$442,'Реестр операций'!$P$5:$P$442,"Банковские комиссии")
A22: Проценты по депозиту (доход) | C22: =SUMIFS('Реестр операций'!$M$5:$M$442,'Реестр операций'!$P$5:$P$442,"Проценты по депозиту")
A23: Чистый поток от финансовой деятельности | C23: =SUM(C18:C22)
A24: ПРОЧИЕ / РАЗОВЫЕ ОПЕРАЦИИ
A25: Возврат средств контрагентам (авансы) | C25: =-SUMIFS('Реестр операций'!$L$5:$L$442,'Реестр операций'!$P$5:$P$442,"Возврат средств контрагенту")
A26: Спонсорство / благотворительность | C26: =-SUMIFS('Реестр операций'!$L$5:$L$442,'Реестр операций'!$P$5:$P$442,"Спонсорство / благотвор.")
A27: Прочие расходы | C27: =-SUMIFS('Реестр операций'!$L$5:$L$442,'Реестр операций'!$P$5:$P$442,"Прочие расходы")
A28: Прочие поступления | C28: =SUMIFS('Реестр операций'!$M$5:$M$442,'Реестр операций'!$P$5:$P$442,"Возврат средств")
A29: Чистый поток от прочих операций | C29: =SUM(C25:C28)
A30: Перемещения на прочие счета Группы + конвертация валют (нетто) | C30: =(SUMIFS('Реестр операций'!$M$5:$M$442,'Реестр операций'!$N$5:$N$442,"Внутренний перевод")-SUMIFS('Реестр операций'!$L$5:$L$442,'Реестр операций'!$N$5:$N$442,"Внутренний перевод"))+(SUMIFS('Реестр операций'!$M$5:$M$442,'Реестр операций'!$N$5:$N$442,"Конвертация валют")-SUMIFS('Реестр операций'!$L$5:$L$442,'Реестр операций'!$N$5:$N$442,"Конвертация валют"))
A31: ЧИСТОЕ ИЗМЕНЕНИЕ ДЕНЕЖНЫХ СРЕДСТВ | C31: =C12+C16+C23+C29+C30
A32: Остаток денежных средств на конец периода | C32: =C5+C31
A34: Сверка сходится: остаток на начало 73 256 ₸ + чистое изменение = остаток на конец ≈ 0 (см. лист «Денежные средства»). Строка «Перемещения на прочие счета Группы + конвертация» балансирует переводы на счета вне этих выписок и курсовые разницы. Все суммы — формулы по реестру.

Sheet Структура затрат
A1: Структура затрат по назначению
A2: Внешние платежи · формулы SUMIFS по реестру
A4: Группа / статья | C4: Сумма, ₸ | D4: % затрат | E4: % выручки
A5: Себестоимость | C5: =SUMIFS('Реестр операций'!$L$5:$L$442,'Реестр операций'!$O$5:$O$442,"Себестоимость") | D5: =C5/SUMIFS('Реестр операций'!$L$5:$L$442,'Реестр операций'!$N$5:$N$442,"Внешняя операция") | E5: =C5/SUMIFS('Реестр операций'!$M$5:$M$442,'Реестр операций'!$O$5:$O$442,"Выручка")
A6: Зарубежные перевозчики/экспедиторы | C6: =SUMIFS('Реестр операций'!$L$5:$L$442,'Реестр операций'!$P$5:$P$442,"Зарубежные перевозчики/экспедиторы") | D6: =C6/SUMIFS('Реестр операций'!$L$5:$L$442,'Реестр операций'!$N$5:$N$442,"Внешняя операция") | E6: =C6/SUMIFS('Реестр операций'!$M$5:$M$442,'Реестр операций'!$O$5:$O$442,"Выручка")
A7: Тариф КТЖ (ж/д перевозки) | C7: =SUMIFS('Реестр операций'!$L$5:$L$442,'Реестр операций'!$P$5:$P$442,"Тариф КТЖ (ж/д перевозки)") | D7: =C7/SUMIFS('Реестр операций'!$L$5:$L$442,'Реестр операций'!$N$5:$N$442,"Внешняя операция") | E7: =C7/SUMIFS('Реестр операций'!$M$5:$M$442,'Реестр операций'!$O$5:$O$442,"Выручка")
A8: Аренда/предоставление вагонов | C8: =SUMIFS('Реестр операций'!$L$5:$L$442,'Реестр операций'!$P$5:$P$442,"Аренда/предоставление вагонов") | D8: =C8/SUMIFS('Реестр операций'!$L$5:$L$442,'Реестр операций'!$N$5:$N$442,"Внешняя операция") | E8: =C8/SUMIFS('Реестр операций'!$M$5:$M$442,'Реестр операций'!$O$5:$O$442,"Выручка")
A9: Операторы вагонов (КТТ и др.) | C9: =SUMIFS('Реестр операций'!$L$5:$L$442,'Реестр операций'!$P$5:$P$442,"Операторы вагонов (КТТ и др.)") | D9: =C9/SUMIFS('Реестр операций'!$L$5:$L$442,'Реестр операций'!$N$5:$N$442,"Внешняя операция") | E9: =C9/SUMIFS('Реестр операций'!$M$5:$M$442,'Реестр операций'!$O$5:$O$442,"Выручка")
A10: Прочие ж/д и ТЭУ услуги | C10: =SUMIFS('Реестр операций'!$L$5:$L$442,'Реестр операций'!$P$5:$P$442,"Прочие ж/д и ТЭУ услуги") | D10: =C10/SUMIFS('Реестр операций'!$L$5:$L$442,'Реестр операций'!$N$5:$N$442,"Внешняя операция") | E10: =C10/SUMIFS('Реестр операций'!$M$5:$M$442,'Реестр операций'!$O$5:$O$442,"Выручка")
A11: Ремонт вагонов и узлов | C11: =SUMIFS('Реестр операций'!$L$5:$L$442,'Реестр операций'!$P$5:$P$442,"Ремонт вагонов и узлов") | D11: =C11/SUMIFS('Реестр операций'!$L$5:$L$442,'Реестр операций'!$N$5:$N$442,"Внешняя операция") | E11: =C11/SUMIFS('Реестр операций'!$M$5:$M$442,'Реестр операций'!$O$5:$O$442,"Выручка")
A12: ФОТ | C12: =SUMIFS('Реестр операций'!$L$5:$L$442,'Реестр операций'!$O$5:$O$442,"ФОТ") | D12: =C12/SUMIFS('Реестр операций'!$L$5:$L$442,'Реестр операций'!$N$5:$N$442,"Внешняя операция") | E12: =C12/SUMIFS('Реестр операций'!$M$5:$M$442,'Реестр операций'!$O$5:$O$442,"Выручка")
A13: Зарплата | C13: =SUMIFS('Реестр операций'!$L$5:$L$442,'Реестр операций'!$P$5:$P$442,"Зарплата") | D13: =C13/SUMIFS('Реестр операций'!$L$5:$L$442,'Реестр операций'!$N$5:$N$442,"Внешняя операция") | E13: =C13/SUMIFS('Реестр операций'!$M$5:$M$442,'Реестр операций'!$O$5:$O$442,"Выручка")
A14: Командировки и подотчёт | C14: =SUMIFS('Реестр операций'!$L$5:$L$442,'Реестр операций'!$P$5:$P$442,"Командировки и подотчёт") | D14: =C14/SUMIFS('Реестр операций'!$L$5:$L$442,'Реестр операций'!$N$5:$N$442,"Внешняя операция") | E14: =C14/SUMIFS('Реестр операций'!$M$5:$M$442,'Реестр операций'!$O$5:$O$442,"Выручка")
A15: Админ/офис | C15: =SUMIFS('Реестр операций'!$L$5:$L$442,'Реестр операций'!$O$5:$O$442,"Админ/офис") | D15: =C15/SUMIFS('Реестр операций'!$L$5:$L$442,'Реестр операций'!$N$5:$N$442,"Внешняя операция") | E15: =C15/SUMIFS('Реестр операций'!$M$5:$M$442,'Реестр операций'!$O$5:$O$442,"Выручка")
A16: Офис, аренда помещений, хоз. | C16: =SUMIFS('Реестр операций'!$L$5:$L$442,'Реестр операций'!$P$5:$P$442,"Офис, аренда помещений, хоз.") | D16: =C16/SUMIFS('Реестр операций'!$L$5:$L$442,'Реестр операций'!$N$5:$N$442,"Внешняя операция") | E16: =C16/SUMIFS('Реестр операций'!$M$5:$M$442,'Реестр операций'!$O$5:$O$442,"Выручка")
A17: Проф. услуги (бухг./юр./конс.) | C17: =SUMIFS('Реестр операций'!$L$5:$L$442,'Реестр операций'!$P$5:$P$442,"Проф. услуги (бухг./юр./конс.)") | D17: =C17/SUMIFS('Реестр операций'!$L$5:$L$442,'Реестр операций'!$N$5:$N$442,"Внешняя операция") | E17: =C17/SUMIFS('Реестр операций'!$M$5:$M$442,'Реестр операций'!$O$5:$O$442,"Выручка")
A18: Связь и ИТ | C18: =SUMIFS('Реестр операций'!$L$5:$L$442,'Реестр операций'!$P$5:$P$442,"Связь и ИТ") | D18: =C18/SUMIFS('Реестр операций'!$L$5:$L$442,'Реестр операций'!$N$5:$N$442,"Внешняя операция") | E18: =C18/SUMIFS('Реестр операций'!$M$5:$M$442,'Реестр операций'!$O$5:$O$442,"Выручка")
A19: Маркетинг и представит. | C19: =SUMIFS('Реестр операций'!$L$5:$L$442,'Реестр операций'!$P$5:$P$442,"Маркетинг и представит.") | D19: =C19/SUMIFS('Реестр операций'!$L$5:$L$442,'Реестр операций'!$N$5:$N$442,"Внешняя операция") | E19: =C19/SUMIFS('Реестр операций'!$M$5:$M$442,'Реестр операций'!$O$5:$O$442,"Выручка")
A20: Хоз. расходы и материалы | C20: =SUMIFS('Реестр операций'!$L$5:$L$442,'Реестр операций'!$P$5:$P$442,"Хоз. расходы и материалы") | D20: =C20/SUMIFS('Реестр операций'!$L$5:$L$442,'Реестр операций'!$N$5:$N$442,"Внешняя операция") | E20: =C20/SUMIFS('Реестр операций'!$M$5:$M$442,'Реестр операций'!$O$5:$O$442,"Выручка")
A21: Страхование | C21: =SUMIFS('Реестр операций'!$L$5:$L$442,'Реестр операций'!$P$5:$P$442,"Страхование") | D21: =C21/SUMIFS('Реестр операций'!$L$5:$L$442,'Реестр операций'!$N$5:$N$442,"Внешняя операция") | E21: =C21/SUMIFS('Реестр операций'!$M$5:$M$442,'Реестр операций'!$O$5:$O$442,"Выручка")
A22: Налоги | C22: =SUMIFS('Реестр операций'!$L$5:$L$442,'Реестр операций'!$O$5:$O$442,"Налоги") | D22: =C22/SUMIFS('Реестр операций'!$L$5:$L$442,'Реестр операций'!$N$5:$N$442,"Внешняя операция") | E22: =C22/SUMIFS('Реестр операций'!$M$5:$M$442,'Реестр операций'!$O$5:$O$442,"Выручка")
A23: Налоги и отчисления | C23: =SUMIFS('Реестр операций'!$L$5:$L$442,'Реестр операций'!$P$5:$P$442,"Налоги и отчисления") | D23: =C23/SUMIFS('Реестр операций'!$L$5:$L$442,'Реестр операций'!$N$5:$N$442,"Внешняя операция") | E23: =C23/SUMIFS('Реестр операций'!$M$5:$M$442,'Реестр операций'!$O$5:$O$442,"Выручка")
A24: Финансовые | C24: =SUMIFS('Реестр операций'!$L$5:$L$442,'Реестр операций'!$O$5:$O$442,"Финансовые") | D24: =C24/SUMIFS('Реестр операций'!$L$5:$L$442,'Реестр операций'!$N$5:$N$442,"Внешняя операция") | E24: =C24/SUMIFS('Реестр операций'!$M$5:$M$442,'Реестр операций'!$O$5:$O$442,"Выручка")
A25: Погашение кредита — тело | C25: =SUMIFS('Реестр операций'!$L$5:$L$442,'Реестр операций'!$P$5:$P$442,"Погашение кредита — тело") | D25: =C25/SUMIFS('Реестр операций'!$L$5:$L$442,'Реестр операций'!$N$5:$N$442,"Внешняя операция") | E25: =C25/SUMIFS('Реестр операций'!$M$5:$M$442,'Реестр операций'!$O$5:$O$442,"Выручка")
A26: Выданные займы (связ. лица) | C26: =SUMIFS('Реестр операций'!$L$5:$L$442,'Реестр операций'!$P$5:$P$442,"Выданные займы (связ. лица)") | D26: =C26/SUMIFS('Реестр операций'!$L$5:$L$442,'Реестр операций'!$N$5:$N$442,"Внешняя операция") | E26: =C26/SUMIFS('Реестр операций'!$M$5:$M$442,'Реестр операций'!$O$5:$O$442,"Выручка")
A27: Финансовый лизинг | C27: =SUMIFS('Реестр операций'!$L$5:$L$442,'Реестр операций'!$P$5:$P$442,"Финансовый лизинг") | D27: =C27/SUMIFS('Реестр операций'!$L$5:$L$442,'Реестр операций'!$N$5:$N$442,"Внешняя операция") | E27: =C27/SUMIFS('Реестр операций'!$M$5:$M$442,'Реестр операций'!$O$5:$O$442,"Выручка")
A28: Проценты по кредиту | C28: =SUMIFS('Реестр операций'!$L$5:$L$442,'Реестр операций'!$P$5:$P$442,"Проценты по кредиту") | D28: =C28/SUMIFS('Реестр операций'!$L$5:$L$442,'Реестр операций'!$N$5:$N$442,"Внешняя операция") | E28: =C28/SUMIFS('Реестр операций'!$M$5:$M$442,'Реестр операций'!$O$5:$O$442,"Выручка")
A29: Банковские комиссии | C29: =SUMIFS('Реестр операций'!$L$5:$L$442,'Реестр операций'!$P$5:$P$442,"Банковские комиссии") | D29: =C29/SUMIFS('Реестр операций'!$L$5:$L$442,'Реестр операций'!$N$5:$N$442,"Внешняя операция") | E29: =C29/SUMIFS('Реестр операций'!$M$5:$M$442,'Реестр операций'!$O$5:$O$442,"Выручка")
A30: Прочее | C30: =SUMIFS('Реестр операций'!$L$5:$L$442,'Реестр операций'!$O$5:$O$442,"Прочее") | D30: =C30/SUMIFS('Реестр операций'!$L$5:$L$442,'Реестр операций'!$N$5:$N$442,"Внешняя операция") | E30: =C30/SUMIFS('Реестр операций'!$M$5:$M$442,'Реестр операций'!$O$5:$O$442,"Выручка")
A31: Возврат средств контрагенту | C31: =SUMIFS('Реестр операций'!$L$5:$L$442,'Реестр операций'!$P$5:$P$442,"Возврат средств контрагенту") | D31: =C31/SUMIFS('Реестр операций'!$L$5:$L$442,'Реестр операций'!$N$5:$N$442,"Внешняя операция") | E31: =C31/SUMIFS('Реестр операций'!$M$5:$M$442,'Реестр операций'!$O$5:$O$442,"Выручка")
A32: Прочие расходы | C32: =SUMIFS('Реестр операций'!$L$5:$L$442,'Реестр операций'!$P$5:$P$442,"Прочие расходы") | D32: =C32/SUMIFS('Реестр операций'!$L$5:$L$442,'Реестр операций'!$N$5:$N$442,"Внешняя операция") | E32: =C32/SUMIFS('Реестр операций'!$M$5:$M$442,'Реестр операций'!$O$5:$O$442,"Выручка")
A33: Спонсорство / благотвор. | C33: =SUMIFS('Реестр операций'!$L$5:$L$442,'Реестр операций'!$P$5:$P$442,"Спонсорство / благотвор.") | D33: =C33/SUMIFS('Реестр операций'!$L$5:$L$442,'Реестр операций'!$N$5:$N$442,"Внешняя операция") | E33: =C33/SUMIFS('Реестр операций'!$M$5:$M$442,'Реестр операций'!$O$5:$O$442,"Выручка")
A34: ИТОГО расход (внешний) | C34: =SUMIFS('Реестр операций'!$L$5:$L$442,'Реестр операций'!$N$5:$N$442,"Внешняя операция") | D34: 1 | E34: =C34/SUMIFS('Реестр операций'!$M$5:$M$442,'Реестр операций'!$O$5:$O$442,"Выручка")

Sheet Клиенты
A1: Выручка по клиентам (все 25)
A2: Все контрагенты-плательщики за услуги · формулы SUMIFS по реестру
A4: # | B4: Контрагент | C4: Сумма, ₸ | D4: % выручки
A5: 1 | B5: ТОО «QAZAQ-ASTYQ GROUP» | C5: =SUMIFS('Реестр операций'!$M$5:$M$442,'Реестр операций'!$Q$5:$Q$442,"ТОО «QAZAQ-ASTYQ GROUP»",'Реестр операций'!$O$5:$O$442,"Выручка") | D5: =C5/SUMIFS('Реестр операций'!$M$5:$M$442,'Реестр операций'!$O$5:$O$442,"Выручка")
A6: 2 | B6: ALBATAREEQ TRADING LLC (ОАЭ) | C6: =SUMIFS('Реестр операций'!$M$5:$M$442,'Реестр операций'!$Q$5:$Q$442,"ALBATAREEQ TRADING LLC (ОАЭ)",'Реестр операций'!$O$5:$O$442,"Выручка") | D6: =C6/SUMIFS('Реестр операций'!$M$5:$M$442,'Реестр операций'!$O$5:$O$442,"Выручка")
A7: 3 | B7: ТОО «Altyn Shyghys» | C7: =SUMIFS('Реестр операций'!$M$5:$M$442,'Реестр операций'!$Q$5:$Q$442,"ТОО «Altyn Shyghys»",'Реестр операций'!$O$5:$O$442,"Выручка") | D7: =C7/SUMIFS('Реестр операций'!$M$5:$M$442,'Реестр операций'!$O$5:$O$442,"Выручка")
A8: 4 | B8: ТОО ROYAL EXPORT | C8: =SUMIFS('Реестр операций'!$M$5:$M$442,'Реестр операций'!$Q$5:$Q$442,"ТОО ROYAL EXPORT",'Реестр операций'!$O$5:$O$442,"Выручка") | D8: =C8/SUMIFS('Реестр операций'!$M$5:$M$442,'Реестр операций'!$O$5:$O$442,"Выручка")
A9: 5 | B9: ТОО "ШыгысАгроТорг" | C9: =SUMIFS('Реестр операций'!$M$5:$M$442,'Реестр операций'!$Q$5:$Q$442,"ТОО ""ШыгысАгроТорг""",'Реестр операций'!$O$5:$O$442,"Выручка") | D9: =C9/SUMIFS('Реестр операций'!$M$5:$M$442,'Реестр операций'!$O$5:$O$442,"Выручка")
A10: 6 | B10: ТОО "Экспорт-М" | C10: =SUMIFS('Реестр операций'!$M$5:$M$442,'Реестр операций'!$Q$5:$Q$442,"ТОО ""Экспорт-М""",'Реестр операций'!$O$5:$O$442,"Выручка") | D10: =C10/SUMIFS('Реестр операций'!$M$5:$M$442,'Реестр операций'!$O$5:$O$442,"Выручка")
A11: 7 | B11: ТОО REGAL EXPORT | C11: =SUMIFS('Реестр операций'!$M$5:$M$442,'Реестр операций'!$Q$5:$Q$442,"ТОО REGAL EXPORT",'Реестр операций'!$O$5:$O$442,"Выручка") | D11: =C11/SUMIFS('Реестр операций'!$M$5:$M$442,'Реестр операций'!$O$5:$O$442,"Выручка")
A12: 8 | B12: ТОО East Agro Company | C12: =SUMIFS('Реестр операций'!$M$5:$M$442,'Реестр операций'!$Q$5:$Q$442,"ТОО East Agro Company",'Реестр операций'!$O$5:$O$442,"Выручка") | D12: =C12/SUMIFS('Реестр операций'!$M$5:$M$442,'Реестр операций'!$O$5:$O$442,"Выручка")
A13: 9 | B13: ТОО "УСТЬ-КАМЕНОГОРСКИЙ МАСЛО-ЭКСТРАКЦИОННЫЙ | C13: =SUMIFS('Реестр операций'!$M$5:$M$442,'Реестр операций'!$Q$5:$Q$442,"ТОО ""УСТЬ-КАМЕНОГОРСКИЙ МАСЛО-ЭКСТРАКЦИОННЫЙ",'Реестр операций'!$O$5:$O$442,"Выручка") | D13: =C13/SUMIFS('Реестр операций'!$M$5:$M$442,'Реестр операций'!$O$5:$O$442,"Выручка")
A14: 10 | B14: ТОО Агро-Трейд-2030 | C14: =SUMIFS('Реестр операций'!$M$5:$M$442,'Реестр операций'!$Q$5:$Q$442,"ТОО Агро-Трейд-2030",'Реестр операций'!$O$5:$O$442,"Выручка") | D14: =C14/SUMIFS('Реестр операций'!$M$5:$M$442,'Реестр операций'!$O$5:$O$442,"Выручка")
A15: 11 | B15: ТОО Евразиан Каспиан Транс | C15: =SUMIFS('Реестр операций'!$M$5:$M$442,'Реестр операций'!$Q$5:$Q$442,"ТОО Евразиан Каспиан Транс",'Реестр операций'!$O$5:$O$442,"Выручка") | D15: =C15/SUMIFS('Реестр операций'!$M$5:$M$442,'Реестр операций'!$O$5:$O$442,"Выручка")
A16: 12 | B16: ТОО "GREENLIGHTS (ГРИНЛАЙТС)" | C16: =SUMIFS('Реестр операций'!$M$5:$M$442,'Реестр операций'!$Q$5:$Q$442,"ТОО ""GREENLIGHTS (ГРИНЛАЙТС)""",'Реестр операций'!$O$5:$O$442,"Выручка") | D16: =C16/SUMIFS('Реестр операций'!$M$5:$M$442,'Реестр операций'!$O$5:$O$442,"Выручка")
A17: 13 | B17: ТОО Темир Экспресс Логистик | C17: =SUMIFS('Реестр операций'!$M$5:$M$442,'Реестр операций'!$Q$5:$Q$442,"ТОО Темир Экспресс Логистик",'Реестр операций'!$O$5:$O$442,"Выручка") | D17: =C17/SUMIFS('Реестр операций'!$M$5:$M$442,'Реестр операций'!$O$5:$O$442,"Выручка")
A18: 14 | B18: ТОО "TimeAgro" | C18: =SUMIFS('Реестр операций'!$M$5:$M$442,'Реестр операций'!$Q$5:$Q$442,"ТОО ""TimeAgro""",'Реестр операций'!$O$5:$O$442,"Выручка") | D18: =C18/SUMIFS('Реестр операций'!$M$5:$M$442,'Реестр операций'!$O$5:$O$442,"Выручка")
A19: 15 | B19: ТОВАРИЩЕСТВО С ОГРАНИЧЕННОЙ ОТВЕТСТВЕННОСТЬЮ | C19: =SUMIFS('Реестр операций'!$M$5:$M$442,'Реестр операций'!$Q$5:$Q$442,"ТОВАРИЩЕСТВО С ОГРАНИЧЕННОЙ ОТВЕТСТВЕННОСТЬЮ",'Реестр операций'!$O$5:$O$442,"Выручка") | D19: =C19/SUMIFS('Реестр операций'!$M$5:$M$442,'Реестр операций'!$O$5:$O$442,"Выручка")
A20: 16 | B20: ТОО ALTAI MAI | C20: =SUMIFS('Реестр операций'!$M$5:$M$442,'Реестр операций'!$Q$5:$Q$442,"ТОО ALTAI MAI",'Реестр операций'!$O$5:$O$442,"Выручка") | D20: =C20/SUMIFS('Реестр операций'!$M$5:$M$442,'Реестр операций'!$O$5:$O$442,"Выручка")
A21: 17 | B21: ТОО «Atasu Global Trans» | C21: =SUMIFS('Реестр операций'!$M$5:$M$442,'Реестр операций'!$Q$5:$Q$442,"ТОО «Atasu Global Trans»",'Реестр операций'!$O$5:$O$442,"Выручка") | D21: =C21/SUMIFS('Реестр операций'!$M$5:$M$442,'Реестр операций'!$O$5:$O$442,"Выручка")
A22: 18 | B22: ТОО Kaz-Smart Logistics | C22: =SUMIFS('Реестр операций'!$M$5:$M$442,'Реестр операций'!$Q$5:$Q$442,"ТОО Kaz-Smart Logistics",'Реестр операций'!$O$5:$O$442,"Выручка") | D22: =C22/SUMIFS('Реестр операций'!$M$5:$M$442,'Реестр операций'!$O$5:$O$442,"Выручка")
A23: 19 | B23: ТОО EASY BOX | C23: =SUMIFS('Реестр операций'!$M$5:$M$442,'Реестр операций'!$Q$5:$Q$442,"ТОО EASY BOX",'Реестр операций'!$O$5:$O$442,"Выручка") | D23: =C23/SUMIFS('Реестр операций'!$M$5:$M$442,'Реестр операций'!$O$5:$O$442,"Выручка")
A24: 20 | B24: ТОО "AsstrА Almaty" (АсстрА Алматы) | C24: =SUMIFS('Реестр операций'!$M$5:$M$442,'Реестр операций'!$Q$5:$Q$442,"ТОО ""AsstrА Almaty"" (АсстрА Алматы)",'Реестр операций'!$O$5:$O$442,"Выручка") | D24: =C24/SUMIFS('Реестр операций'!$M$5:$M$442,'Реестр операций'!$O$5:$O$442,"Выручка")
A25: 21 | B25: ТОО Rhenus Intermodal Systems | C25: =SUMIFS('Реестр операций'!$M$5:$M$442,'Реестр операций'!$Q$5:$Q$442,"ТОО Rhenus Intermodal Systems",'Реестр операций'!$O$5:$O$442,"Выручка") | D25: =C25/SUMIFS('Реестр операций'!$M$5:$M$442,'Реестр операций'!$O$5:$O$442,"Выручка")
A26: 22 | B26: ТОО Каз Алтын Групп | C26: =SUMIFS('Реестр операций'!$M$5:$M$442,'Реестр операций'!$Q$5:$Q$442,"ТОО Каз Алтын Групп",'Реестр операций'!$O$5:$O$442,"Выручка") | D26: =C26/SUMIFS('Реестр операций'!$M$5:$M$442,'Реестр операций'!$O$5:$O$442,"Выручка")
A27: 23 | B27: ТОО "Максат-2030" | C27: =SUMIFS('Реестр операций'!$M$5:$M$442,'Реестр операций'!$Q$5:$Q$442,"ТОО ""Максат-2030""",'Реестр операций'!$O$5:$O$442,"Выручка") | D27: =C27/SUMIFS('Реестр операций'!$M$5:$M$442,'Реестр операций'!$O$5:$O$442,"Выручка")
A28: 24 | B28: ТОО "FRS logistics" | C28: =SUMIFS('Реестр операций'!$M$5:$M$442,'Реестр операций'!$Q$5:$Q$442,"ТОО ""FRS logistics""",'Реестр операций'!$O$5:$O$442,"Выручка") | D28: =C28/SUMIFS('Реестр операций'!$M$5:$M$442,'Реестр операций'!$O$5:$O$442,"Выручка")
A29: 25 | B29: Данияр Алим | C29: =SUMIFS('Реестр операций'!$M$5:$M$442,'Реестр операций'!$Q$5:$Q$442,"Данияр Алим",'Реестр операций'!$O$5:$O$442,"Выручка") | D29: =C29/SUMIFS('Реестр операций'!$M$5:$M$442,'Реестр операций'!$O$5:$O$442,"Выручка")
B30: ИТОГО (25 контрагентов) | C30: =SUM(C5:C29) | D30: =C30/SUMIFS('Реестр операций'!$M$5:$M$442,'Реестр операций'!$O$5:$O$442,"Выручка")

Sheet Поставщики
A1: Затраты по поставщикам (все 24)
A2: Все поставщики услуг (себестоимость) · формулы SUMIFS по реестру
A4: # | B4: Контрагент | C4: Сумма, ₸ | D4: % себест.
A5: 1 | B5: ТОО «КТЖ-Грузовые перевозки» | C5: =SUMIFS('Реестр операций'!$L$5:$L$442,'Реестр операций'!$Q$5:$Q$442,"ТОО «КТЖ-Грузовые перевозки»",'Реестр операций'!$O$5:$O$442,"Себестоимость") | D5: =C5/SUMIFS('Реестр операций'!$L$5:$L$442,'Реестр операций'!$O$5:$O$442,"Себестоимость")
A6: 2 | B6: MEGA STOCK CO. LTD (Таиланд) | C6: =SUMIFS('Реестр операций'!$L$5:$L$442,'Реестр операций'!$Q$5:$Q$442,"MEGA STOCK CO. LTD (Таиланд)",'Реестр операций'!$O$5:$O$442,"Себестоимость") | D6: =C6/SUMIFS('Реестр операций'!$L$5:$L$442,'Реестр операций'!$O$5:$O$442,"Себестоимость")
A7: 3 | B7: ООО «ТрансАльянс Запад» (РФ) | C7: =SUMIFS('Реестр операций'!$L$5:$L$442,'Реестр операций'!$Q$5:$Q$442,"ООО «ТрансАльянс Запад» (РФ)",'Реестр операций'!$O$5:$O$442,"Себестоимость") | D7: =C7/SUMIFS('Реестр операций'!$L$5:$L$442,'Реестр операций'!$O$5:$O$442,"Себестоимость")
A8: 4 | B8: АО «КазТемирТранс» (КТТ) | C8: =SUMIFS('Реестр операций'!$L$5:$L$442,'Реестр операций'!$Q$5:$Q$442,"АО «КазТемирТранс» (КТТ)",'Реестр операций'!$O$5:$O$442,"Себестоимость") | D8: =C8/SUMIFS('Реестр операций'!$L$5:$L$442,'Реестр операций'!$O$5:$O$442,"Себестоимость")
A9: 5 | B9: ТОО "АРНА" | C9: =SUMIFS('Реестр операций'!$L$5:$L$442,'Реестр операций'!$Q$5:$Q$442,"ТОО ""АРНА""",'Реестр операций'!$O$5:$O$442,"Себестоимость") | D9: =C9/SUMIFS('Реестр операций'!$L$5:$L$442,'Реестр операций'!$O$5:$O$442,"Себестоимость")
A10: 6 | B10: ТОО «InterLog Co» | C10: =SUMIFS('Реестр операций'!$L$5:$L$442,'Реестр операций'!$Q$5:$Q$442,"ТОО «InterLog Co»",'Реестр операций'!$O$5:$O$442,"Себестоимость") | D10: =C10/SUMIFS('Реестр операций'!$L$5:$L$442,'Реестр операций'!$O$5:$O$442,"Себестоимость")
A11: 7 | B11: ТОО "PRATA" | C11: =SUMIFS('Реестр операций'!$L$5:$L$442,'Реестр операций'!$Q$5:$Q$442,"ТОО ""PRATA""",'Реестр операций'!$O$5:$O$442,"Себестоимость") | D11: =C11/SUMIFS('Реестр операций'!$L$5:$L$442,'Реестр операций'!$O$5:$O$442,"Себестоимость")
A12: 8 | B12: LLC Altyn Trans (Узб.) | C12: =SUMIFS('Реестр операций'!$L$5:$L$442,'Реестр операций'!$Q$5:$Q$442,"LLC Altyn Trans (Узб.)",'Реестр операций'!$O$5:$O$442,"Себестоимость") | D12: =C12/SUMIFS('Реестр операций'!$L$5:$L$442,'Реестр операций'!$O$5:$O$442,"Себестоимость")
A13: 9 | B13: ТОО "ЭДЕМ ТРАНС" | C13: =SUMIFS('Реестр операций'!$L$5:$L$442,'Реестр операций'!$Q$5:$Q$442,"ТОО ""ЭДЕМ ТРАНС""",'Реестр операций'!$O$5:$O$442,"Себестоимость") | D13: =C13/SUMIFS('Реестр операций'!$L$5:$L$442,'Реестр операций'!$O$5:$O$442,"Себестоимость")
A14: 10 | B14: ТОО "PetroComLogistics" | C14: =SUMIFS('Реестр операций'!$L$5:$L$442,'Реестр операций'!$Q$5:$Q$442,"ТОО ""PetroComLogistics""",'Реестр операций'!$O$5:$O$442,"Себестоимость") | D14: =C14/SUMIFS('Реестр операций'!$L$5:$L$442,'Реестр операций'!$O$5:$O$442,"Себестоимость")
A15: 11 | B15: ТОО "ЭРСАЛТ РЭЙЛ" | C15: =SUMIFS('Реестр операций'!$L$5:$L$442,'Реестр операций'!$Q$5:$Q$442,"ТОО ""ЭРСАЛТ РЭЙЛ""",'Реестр операций'!$O$5:$O$442,"Себестоимость") | D15: =C15/SUMIFS('Реестр операций'!$L$5:$L$442,'Реестр операций'!$O$5:$O$442,"Себестоимость")
A16: 12 | B16: ТОО "USM-Logistics" | C16: =SUMIFS('Реестр операций'!$L$5:$L$442,'Реестр операций'!$Q$5:$Q$442,"ТОО ""USM-Logistics""",'Реестр операций'!$O$5:$O$442,"Себестоимость") | D16: =C16/SUMIFS('Реестр операций'!$L$5:$L$442,'Реестр операций'!$O$5:$O$442,"Себестоимость")
A17: 13 | B17: ТОО "ResursLogistiс (РесурсЛогистик)" | C17: =SUMIFS('Реестр операций'!$L$5:$L$442,'Реестр операций'!$Q$5:$Q$442,"ТОО ""ResursLogistiс (РесурсЛогистик)""",'Реестр операций'!$O$5:$O$442,"Себестоимость") | D17: =C17/SUMIFS('Реестр операций'!$L$5:$L$442,'Реестр операций'!$O$5:$O$442,"Себестоимость")
A18: 14 | B18: ТОО "Нұр-Альфинур" | C18: =SUMIFS('Реестр операций'!$L$5:$L$442,'Реестр операций'!$Q$5:$Q$442,"ТОО ""Нұр-Альфинур""",'Реестр операций'!$O$5:$O$442,"Себестоимость") | D18: =C18/SUMIFS('Реестр операций'!$L$5:$L$442,'Реестр операций'!$O$5:$O$442,"Себестоимость")
A19: 15 | B19: ТОО "Asia Railways Tracking Service (Азия Рэ | C19: =SUMIFS('Реестр операций'!$L$5:$L$442,'Реестр операций'!$Q$5:$Q$442,"ТОО ""Asia Railways Tracking Service (Азия Рэ",'Реестр операций'!$O$5:$O$442,"Себестоимость") | D19: =C19/SUMIFS('Реестр операций'!$L$5:$L$442,'Реестр операций'!$O$5:$O$442,"Себестоимость")
A20: 16 | B20: Turkmen Demiryol Express (Туркм.) | C20: =SUMIFS('Реестр операций'!$L$5:$L$442,'Реестр операций'!$Q$5:$Q$442,"Turkmen Demiryol Express (Туркм.)",'Реестр операций'!$O$5:$O$442,"Себестоимость") | D20: =C20/SUMIFS('Реестр операций'!$L$5:$L$442,'Реестр операций'!$O$5:$O$442,"Себестоимость")
A21: 17 | B21: ТОО ""SK RAILWAY Service"" | C21: =SUMIFS('Реестр операций'!$L$5:$L$442,'Реестр операций'!$Q$5:$Q$442,"ТОО """"SK RAILWAY Service""""",'Реестр операций'!$O$5:$O$442,"Себестоимость") | D21: =C21/SUMIFS('Реестр операций'!$L$5:$L$442,'Реестр операций'!$O$5:$O$442,"Себестоимость")
A22: 18 | B22: филиал акционерного общества "Национальная к | C22: =SUMIFS('Реестр операций'!$L$5:$L$442,'Реестр операций'!$Q$5:$Q$442,"филиал акционерного общества ""Национальная к",'Реестр операций'!$O$5:$O$442,"Себестоимость") | D22: =C22/SUMIFS('Реестр операций'!$L$5:$L$442,'Реестр операций'!$O$5:$O$442,"Себестоимость")
A23: 19 | B23: ТОО "ТОР Арыс" | C23: =SUMIFS('Реестр операций'!$L$5:$L$442,'Реестр операций'!$Q$5:$Q$442,"ТОО ""ТОР Арыс""",'Реестр операций'!$O$5:$O$442,"Себестоимость") | D23: =C23/SUMIFS('Реестр операций'!$L$5:$L$442,'Реестр операций'!$O$5:$O$442,"Себестоимость")
A24: 20 | B24: ТОО "Olivin.kz (Оливин.кз)" | C24: =SUMIFS('Реестр операций'!$L$5:$L$442,'Реестр операций'!$Q$5:$Q$442,"ТОО ""Olivin.kz (Оливин.кз)""",'Реестр операций'!$O$5:$O$442,"Себестоимость") | D24: =C24/SUMIFS('Реестр операций'!$L$5:$L$442,'Реестр операций'!$O$5:$O$442,"Себестоимость")
A25: 21 | B25: Производственный кооператив "ИБРАЕВ+К" | C25: =SUMIFS('Реестр операций'!$L$5:$L$442,'Реестр операций'!$Q$5:$Q$442,"Производственный кооператив ""ИБРАЕВ+К""",'Реестр операций'!$O$5:$O$442,"Себестоимость") | D25: =C25/SUMIFS('Реестр операций'!$L$5:$L$442,'Реестр операций'!$O$5:$O$442,"Себестоимость")
A26: 22 | B26: ТОО "Объединенное железнодорожное хозяйство" | C26: =SUMIFS('Реестр операций'!$L$5:$L$442,'Реестр операций'!$Q$5:$Q$442,"ТОО ""Объединенное железнодорожное хозяйство""",'Реестр операций'!$O$5:$O$442,"Себестоимость") | D26: =C26/SUMIFS('Реестр операций'!$L$5:$L$442,'Реестр операций'!$O$5:$O$442,"Себестоимость")
A27: 23 | B27: ТОО "АФ АГМ-Табыс" | C27: =SUMIFS('Реестр операций'!$L$5:$L$442,'Реестр операций'!$Q$5:$Q$442,"ТОО ""АФ АГМ-Табыс""",'Реестр операций'!$O$5:$O$442,"Себестоимость") | D27: =C27/SUMIFS('Реестр операций'!$L$5:$L$442,'Реестр операций'!$O$5:$O$442,"Себестоимость")
A28: 24 | B28: Филиал акционерного общества «Национальная к | C28: =SUMIFS('Реестр операций'!$L$5:$L$442,'Реестр операций'!$Q$5:$Q$442,"Филиал акционерного общества «Национальная к",'Реестр операций'!$O$5:$O$442,"Себестоимость") | D28: =C28/SUMIFS('Реестр операций'!$L$5:$L$442,'Реестр операций'!$O$5:$O$442,"Себестоимость")
B29: ИТОГО (24 контрагентов) | C29: =SUM(C5:C28) | D29: =C29/SUMIFS('Реестр операций'!$L$5:$L$442,'Реестр операций'!$O$5:$O$442,"Себестоимость")

Sheet Денежные средства
A1: Денежные средства по счетам
A2: Сверка: остаток на начало + приток − отток = остаток на конец · притоки/оттоки — формулы по реестру
A4: Банк · валюта | B4: ИИК | C4: Ост. на начало | D4: Приток | E4: Отток | F4: Опер. | G4: Ост. на конец
A5: ЦентрКредит · KZT | B5: KZ76...2401 | C5: 67511.82 | D5: =SUMIFS('Реестр операций'!$M$5:$M$442,'Реестр операций'!$B$5:$B$442,"ЦентрКредит",'Реестр операций'!$C$5:$C$442,"KZT") | E5: =SUMIFS('Реестр операций'!$L$5:$L$442,'Реестр операций'!$B$5:$B$442,"ЦентрКредит",'Реестр операций'!$C$5:$C$442,"KZT") | F5: =COUNTIFS('Реестр операций'!$B$5:$B$442,"ЦентрКредит",'Реестр операций'!$C$5:$C$442,"KZT") | G5: =C5+D5-E5
A6: ЦентрКредит · USD | B6: KZ58...6935 | C6: 0 | D6: =SUMIFS('Реестр операций'!$M$5:$M$442,'Реестр операций'!$B$5:$B$442,"ЦентрКредит",'Реестр операций'!$C$5:$C$442,"USD") | E6: =SUMIFS('Реестр операций'!$L$5:$L$442,'Реестр операций'!$B$5:$B$442,"ЦентрКредит",'Реестр операций'!$C$5:$C$442,"USD") | F6: =COUNTIFS('Реестр операций'!$B$5:$B$442,"ЦентрКредит",'Реестр операций'!$C$5:$C$442,"USD") | G6: =C6+D6-E6
A7: ЦентрКредит · RUB | B7: KZ03...8368 | C7: 0 | D7: =SUMIFS('Реестр операций'!$M$5:$M$442,'Реестр операций'!$B$5:$B$442,"ЦентрКредит",'Реестр операций'!$C$5:$C$442,"RUB") | E7: =SUMIFS('Реестр операций'!$L$5:$L$442,'Реестр операций'!$B$5:$B$442,"ЦентрКредит",'Реестр операций'!$C$5:$C$442,"RUB") | F7: =COUNTIFS('Реестр операций'!$B$5:$B$442,"ЦентрКредит",'Реестр операций'!$C$5:$C$442,"RUB") | G7: =C7+D7-E7
A8: Bank RBK · KZT | B8: KZ45...0001 | C8: 5743.83 | D8: =SUMIFS('Реестр операций'!$M$5:$M$442,'Реестр операций'!$B$5:$B$442,"Bank RBK",'Реестр операций'!$C$5:$C$442,"KZT") | E8: =SUMIFS('Реестр операций'!$L$5:$L$442,'Реестр операций'!$B$5:$B$442,"Bank RBK",'Реестр операций'!$C$5:$C$442,"KZT") | F8: =COUNTIFS('Реестр операций'!$B$5:$B$442,"Bank RBK",'Реестр операций'!$C$5:$C$442,"KZT") | G8: =C8+D8-E8
A9: Bank RBK · USD | B9: KZ20...0063 | C9: 0 | D9: =SUMIFS('Реестр операций'!$M$5:$M$442,'Реестр операций'!$B$5:$B$442,"Bank RBK",'Реестр операций'!$C$5:$C$442,"USD") | E9: =SUMIFS('Реестр операций'!$L$5:$L$442,'Реестр операций'!$B$5:$B$442,"Bank RBK",'Реестр операций'!$C$5:$C$442,"USD") | F9: =COUNTIFS('Реестр операций'!$B$5:$B$442,"Bank RBK",'Реестр операций'!$C$5:$C$442,"USD") | G9: =C9+D9-E9
A10: ИТОГО по 5 счетам | C10: =SUM(C5:C9) | D10: =SUM(D5:D9) | E10: =SUM(E5:E9) | F10: =SUM(F5:F9) | G10: =SUM(G5:G9)
A12: СПРАВОЧНО, ₸
A13: Валовой оборот по 5 счетам (приток+отток) | C13: =SUM('Реестр операций'!$L$5:$L$442)+SUM('Реестр операций'!$M$5:$M$442)
A14: Реальный внешний приток | C14: =SUMIFS('Реестр операций'!$M$5:$M$442,'Реестр операций'!$N$5:$N$442,"Внешняя операция")
A15: Реальный внешний расход | C15: =SUMIFS('Реестр операций'!$L$5:$L$442,'Реестр операций'!$N$5:$N$442,"Внешняя операция")
A16: «Шум» (внутр. переводы + конвертация) | C16: =SUM('Реестр операций'!$L$5:$L$442)+SUM('Реестр операций'!$M$5:$M$442)-SUMIFS('Реестр операций'!$M$5:$M$442,'Реестр операций'!$N$5:$N$442,"Внешняя операция")-SUMIFS('Реестр операций'!$L$5:$L$442,'Реестр операций'!$N$5:$N$442,"Внешняя операция")

Sheet Реестр операций
A1: Реестр операций (первичные данные)
A2: Все 438 операций из выписок с классификацией · источник для всех формул · фильтруется
A4: Дата | B4: Банк | C4: Вал | D4: Счёт | E4: Контрагент | F4: БИН | G4: КНП | H4: Назначение платежа | I4: Расход (вал) | J4: Приход (вал) | K4: Курс | L4: Расход, ₸ | M4: Приход, ₸ | N4: Тип | O4: Группа | P4: Статья | Q4: Контрагент (норм.)
A5: 01.07.2026 | B5: ЦентрКредит | C5: KZT | D5: 2401 | E5: Товарищество с ограниченной ответственностью "Shiny river" | F5: 251240008624 | G5: 872 | H5: Счет на оплату № 717 от 01.07.2026 г. Проживание в гостинице Унбетпаев / Доолоткулов с 01.07.2026 по 02.07.2026 | I5: 39000 | K5: 1 | L5: 39000 | N5: Внешняя операция | O5: ФОТ | P5: Командировки и подотчёт | Q5: ТОО "Shiny river"
A6: 01.07.2026 | B6: ЦентрКредит | C6: KZT | D6: 2401 | E6: Доолоткулов Данияр Дулатбекович | F6: 940502350175 | G6: 871 | H6: Суточные расходы на проезд в Астана-Усть-Каменогорск- Семей 30.06-04.07.2026 5 кд *15МРП (4325тг МРП) Приказ №51 от 29.06.2026. Без НДС. Платежи по поездкам | I6: 64875 | K6: 1 | L6: 64875 | N6: Внешняя операция | O6: ФОТ | P6: Командировки и подотчёт | Q6: Доолоткулов Данияр Дулатбекович
A7: 01.07.2026 | B7: ЦентрКредит | C7: KZT | D7: 2401 | E7: Унбетпаев Ернар Байтасович | F7: 840808300582 | G7: 871 | H7: Суточные расходы на проезд в Астана-Усть-Каменогорск- Семей 30.06-04.07.2026 5 кд *20МРП (4325тг МРП) Приказ №51 от 29.06.2026. Без НДС. Платежи по поездкам | I7: 86500 | K7: 1 | L7: 86500 | N7: Внешняя операция | O7: ФОТ | P7: Командировки и подотчёт | Q7: Унбетпаев Ернар Байтасович
A8: 01.07.2026 | B8: ЦентрКредит | C8: KZT | D8: 2401 | E8: Товарищество с ограниченной ответственностью "Olivin.kz (Оливин.кз)" | F8: 210240014486 | G8: 710 | H8: Счет на оплату № 177 от 25.06.2026 г. Магнитный внешний аккумулятор 30 шт | I8: 287400 | K8: 1 | L8: 287400 | N8: Внешняя операция | O8: Себестоимость | P8: Ремонт вагонов и узлов | Q8: ТОО "Olivin.kz (Оливин.кз)"
A9: 01.07.2026 | B9: ЦентрКредит | C9: KZT | D9: 2401 | E9: Товарищество с ограниченной ответственностью "Asia Railways Tracking Service (Азия Рэилвейс Трекинг Сервис)" | F9: 130540005778 | G9: 813 | H9: Счет на оплату № И-1792 от 01.07.2026 г. Договор № D-0071124 от 07.11.2024 г.Авансовая оплата за дислокацию подвижного состава | I9: 500000 | K9: 1 | L9: 500000 | N9: Внешняя операция | O9: Себестоимость | P9: Аренда/предоставление вагонов | Q9: ТОО "Asia Railways Tracking Service (Азия Рэ
A10: 01.07.2026 | B10: ЦентрКредит | C10: KZT | D10: 2401 | E10: Товарищество с ограниченной ответственностью "Нұр-Альфинур" | F10: 111240015961 | G10: 822 | H10: Оплата согласно акт сверки Сумма 2 505 840-78 тенге без налога | I10: 2505840.8 | K10: 1 | L10: 2505840.8 | N10: Внешняя операция | O10: Себестоимость | P10: Ремонт вагонов и узлов | Q10: ТОО "Нұр-Альфинур"
A11: 01.07.2026 | B11: ЦентрКредит | C11: KZT | D11: 2401 | E11: Банк ЦентрКредит для ЗП | F11: 980640000093 | G11: 332 | H11: Для зачисления на картсчета сотрудникам согласно спискам 5 500 000-00 тенге. | I11: 5500000 | K11: 1 | L11: 5500000 | N11: Внешняя операция | O11: ФОТ | P11: Зарплата | Q11: Банк ЦентрКредит для ЗП
A12: 01.07.2026 | B12: ЦентрКредит | C12: KZT | D12: 2401 | E12: Товарищество с ограниченной ответственностью "ResursLogistiс (РесурсЛогистик)" | F12: 230940036377 | G12: 813 | H12: Счет на оплату №124 от 22.06.2026 г. Счет на оплату №124 от 22.06.2026 г. Оплата за аренду вагонов ТОО «WayStar Group» по договору оказания услуг № 17-РЛ/25 от 13.05.2025г. Аренда ЦС за июль | I12: 6724520 | K12: 1 | L12: 6724520 | N12: Внешняя операция | O12: Себестоимость | P12: Аренда/предоставление вагонов | Q12: ТОО "ResursLogistiс (РесурсЛогистик)"
A13: 01.07.2026 | B13: ЦентрКредит | C13: KZT | D13: 2401 | E13: Товарищество с ограниченной ответственностью "WayStar Group" | F13: 240340014287 | G13: 312 | H13: Размещение вклада | I13: 9371424.2 | K13: 1 | L13: 9371424.2 | N13: Внутренний перевод | O13: Технические | P13: Перевод между своими счетами
A14: 01.07.2026 | B14: ЦентрКредит | C14: KZT | D14: 2401 | E14: Товарищество с ограниченной ответственностью "ResursLogistiс (РесурсЛогистик)" | F14: 230940036377 | G14: 880 | H14: Возврат денежных средств Договор №2026/03-14 от 05.03.2026 г. | I14: 10000000 | K14: 1 | L14: 10000000 | N14: Внешняя операция | O14: Прочее | P14: Возврат средств контрагенту | Q14: ТОО "ResursLogistiс (РесурсЛогистик)"
A15: 01.07.2026 | B15: ЦентрКредит | C15: KZT | D15: 2401 | E15: Товарищество с ограниченной ответственностью "WayStar Group" | F15: 240340014287 | G15: 312 | H15: на депозит. Без НДС. Размещение краткосрочных вкладов (не более одного года) | I15: 101543680 | K15: 1 | L15: 101543680 | N15: Внутренний перевод | O15: Технические | P15: Перевод между своими счетами
A16: 01.07.2026 | B16: ЦентрКредит | C16: KZT | D16: 2401 | E16: Товарищество с ограниченной ответственностью "WayStar Group" | F16: 240340014287 | G16: 316 | H16: Выплата начисленного вознаграждения по депозитному договору № 01607034 от 24.07.2025 за период с 29.06.26 по 30.06.26. Вкладчик Товарищество с ограниченной ответственностью "WayStar Group". | J16: 1328.33 | K16: 1 | M16: 1328.33 | N16: Внутренний перевод | O16: Технические | P16: Перевод между своими счетами
A17: 01.07.2026 | B17: ЦентрКредит | C17: KZT | D17: 2401 | E17: Товарищество с ограниченной ответственностью "WayStar Group" | F17: 240340014287 | G17: 322 | H17: Без НДС. Снятие с краткосрочного вклада (не более одного года) | J17: 500000 | K17: 1 | M17: 500000 | N17: Внутренний перевод | O17: Технические | P17: Перевод между своими счетами
A18: 01.07.2026 | B18: ЦентрКредит | C18: KZT | D18: 2401 | E18: Товарищество с ограниченной ответственностью "WayStar Group" | F18: 240340014287 | G18: 322 | H18: Без НДС. Снятие с краткосрочного вклада (не более одного года) | J18: 500000 | K18: 1 | M18: 500000 | N18: Внутренний перевод | O18: Технические | P18: Перевод между своими счетами
A19: 01.07.2026 | B19: ЦентрКредит | C19: KZT | D19: 2401 | E19: ТОО "WayStar Group" | F19: 240340014287 | G19: 343 | H19: перевод на другой счет Переводы клиентом денег со своего текущего счета в одном банке, филиале банка-нерезидента Республики Казахстан на свой текущий счет в другом банке, филиале другого банка-нерезидента Республики Казахстан | J19: 2626000 | K19: 1 | M19: 2626000 | N19: Внутренний перевод | O19: Технические | P19: Перевод между своими счетами
A20: 01.07.2026 | B20: ЦентрКредит | C20: KZT | D20: 2401 | E20: Товарищество с ограниченной ответственностью "WayStar Group" | F20: 240340014287 | G20: 322 | H20: Частичная выплата вклада по депозитному договору № 01607034 от 01.07.2026 в размере 3933799.78 согласно ДП. Вкладчик: Товарищество с ограниченной ответственностью "WayStar Group". | J20: 3933799.8 | K20: 1 | M20: 3933799.8 | N20: Внутренний перевод | O20: Технические | P20: Перевод между своими счетами
A21: 01.07.2026 | B21: ЦентрКредит | C21: KZT | D21: 2401 | E21: ТОО WayStar Group | F21: 240340014287 | G21: 343 | H21: перевод на другой счет Переводы клиентом денег со своего текущего счета в одном банке филиале банка-нерезидента Республики Казахстан на свой текущий счет в другом банке, филиале другого банка-нерезидента Республики Казахстан | J21: 8448600 | K21: 1 | M21: 8448600 | N21: Внутренний перевод | O21: Технические | P21: Перевод между своими счетами
A22: 01.07.2026 | B22: ЦентрКредит | C22: KZT | D22: 2401 | E22: ТОО "WayStar Group" | F22: 240340014287 | G22: 343 | H22: перевод на другой счет Переводы клиентом денег со своего текущего счета в одном банке, филиале банка-нерезидента Республики Казахстан на свой текущий счет в другом банке, филиале другого банка-нерезидента Республики Казахстан | J22: 10900000 | K22: 1 | M22: 10900000 | N22: Внутренний перевод | O22: Технические | P22: Перевод между своими счетами
A23: 01.07.2026 | B23: ЦентрКредит | C23: KZT | D23: 2401 | E23: ТОО "WayStar Group" | F23: 240340014287 | G23: 343 | H23: перевод на другой счет Переводы клиентом денег со своего текущего счета в одном банке, филиале банка-нерезидента Республики Казахстан на свой текущий счет в другом банке, филиале другого банка-нерезидента Республики Казахстан | J23: 109646000 | K23: 1 | M23: 109646000 | N23: Внутренний перевод | O23: Технические | P23: Перевод между своими счетами
A24: 02.07.2026 | B24: ЦентрКредит | C24: KZT | D24: 2401 | E24: РГУ УГД по Алмалинскому району ДГД по городу Алматы КГД МФ РК | F24: 910740000153 | G24: 911 | H24: гос пошлина. Начисленные (исчисленные) и иные обязательства в бюджет | I24: 27641.25 | K24: 1 | L24: 27641.25 | N24: Внешняя операция | O24: Налоги | P24: Налоги и отчисления | Q24: РГУ УГД по Алмалинскому району ДГД по город
A25: 02.07.2026 | B25: ЦентрКредит | C25: KZT | D25: 2401 | E25: Индивидуальный предприниматель "Саметханов Алихан Дарханұлы" | F25: 970527350974 | G25: 872 | H25: Без НДС. Платежи за услуги по проживанию и питанию | I25: 30000 | K25: 1 | L25: 30000 | N25: Внешняя операция | O25: ФОТ | P25: Командировки и подотчёт | Q25: Индивидуальный предприниматель "Саметханов А
A26: 02.07.2026 | B26: ЦентрКредит | C26: KZT | D26: 2401 | E26: Индивидуальный предприниматель "Капизова" | F26: 770127402766 | G26: 859 | H26: Без НДС. Платежи за профессиональные, научные и технические услуги | I26: 50000 | K26: 1 | L26: 50000 | N26: Внешняя операция | O26: Админ/офис | P26: Проф. услуги (бухг./юр./конс.) | Q26: Индивидуальный предприниматель "Капизова"
A27: 02.07.2026 | B27: ЦентрКредит | C27: KZT | D27: 2401 | E27: Акционерное Общество "Банк ЦентрКредит" | F27: 980640000093 | G27: 841 | H27: Интернет-банкинг. MIP. Международные платежи. Перевод OUR, кроме валют стран СНГ с 13:00 по 16:00. Расчетный документ № 1 от 02.07.26 на сумму 100 000.00 USD, в т.ч. НДС 16% | I27: 95852 | K27: 1 | L27: 95852 | N27: Внешняя операция | O27: Финансовые | P27: Банковские комиссии | Q27: Акционерное Общество "Банк ЦентрКредит"
A28: 02.07.2026 | B28: ЦентрКредит | C28: KZT | D28: 2401 | E28: Алим | F28: 020420550046 | G28: 871 | H28: Данияр Алим подотчет. Без НДС. Платежи по поездкам | I28: 986100 | K28: 1 | L28: 986100 | N28: Внешняя операция | O28: ФОТ | P28: Командировки и подотчёт | Q28: Алим
A29: 02.07.2026 | B29: ЦентрКредит | C29: KZT | D29: 2401 | E29: Товарищество с ограниченной ответственностью «InterLog Co» | F29: 061040010307 | G29: 813 | H29: Договор №017 от 30.12.2025 г. Оплата долга по акту сверки. Без НДС. Платежи за услуги железнодорожного транспорта | I29: 1648080 | K29: 1 | L29: 1648080 | N29: Внешняя операция | O29: Себестоимость | P29: Прочие ж/д и ТЭУ услуги | Q29: ТОО «InterLog Co»
A30: 02.07.2026 | B30: ЦентрКредит | C30: KZT | D30: 2401 | E30: ТОО КТЖ-Грузовые перевозки | F30: 031040001799 | G30: 813 | H30: Без НДС, 4185494, Платежи за услуги железнодорожного транспорта | I30: 10000000 | K30: 1 | L30: 10000000 | N30: Внешняя операция | O30: Себестоимость | P30: Тариф КТЖ (ж/д перевозки) | Q30: ТОО «КТЖ-Грузовые перевозки»
A31: 02.07.2026 | B31: ЦентрКредит | C31: KZT | D31: 2401 | E31: Акционерное Общество "Банк ЦентрКредит" | F31: 980640000093 | G31: 213 | H31: Покупка иностранной валюты TOD (день в день), Товарищество с ограниченной ответственностью "WayStar Group", БИН 240340014287. Заявка №615800. Дата вал. 02.07.2026. Покупка USD, продажа KZT. Курс сделки 473.73. Учетный курс 479.26. Получение услуг | I31: 47373000 | K31: 1 | L31: 47373000 | N31: Конвертация валют | O31: Технические | P31: Покупка/продажа валюты
A32: 02.07.2026 | B32: ЦентрКредит | C32: KZT | D32: 2401 | E32: ТОО "WayStar Group" | F32: 240340014287 | G32: 312 | H32: Без НДС. Размещение краткосрочных вкладов (не более одного года) | I32: 1.5574155e+08 | K32: 1 | L32: 1.5574155e+08 | N32: Внутренний перевод | O32: Технические | P32: Перевод между своими счетами
A33: 02.07.2026 | B33: ЦентрКредит | C33: KZT | D33: 2401 | E33: Товарищество с ограниченной ответственностью "WayStar Group" | F33: 240340014287 | G33: 316 | H33: Выплата начисленного вознаграждения по депозитному договору № 01607034 от 24.07.2025 за период с 01.07.26 по 01.07.26. Вкладчик Товарищество с ограниченной ответственностью "WayStar Group". | J33: 37115.17 | K33: 1 | M33: 37115.17 | N33: Внутренний перевод | O33: Технические | P33: Перевод между своими счетами
A34: 02.07.2026 | B34: ЦентрКредит | C34: KZT | D34: 2401 | E34: ТОО "WayStar Group" | F34: 240340014287 | G34: 343 | H34: перевод на другой счет Переводы клиентом денег со своего текущего счета в одном банке, филиале банка-нерезидента Республики Казахстан на свой текущий счет в другом банке, филиале другого банка-нерезидента Республики Казахстан | J34: 24000000 | K34: 1 | M34: 24000000 | N34: Внутренний перевод | O34: Технические | P34: Перевод между своими счетами
A35: 02.07.2026 | B35: ЦентрКредит | C35: KZT | D35: 2401 | E35: ТОО "WayStar Group" | F35: 240340014287 | G35: 343 | H35: перевод на другой счет Переводы клиентом денег со своего текущего счета в одном банке, филиале банка-нерезидента Республики Казахстан на свой текущий счет в другом банке, филиале другого банка-нерезидента Республики Казахстан | J35: 82000000 | K35: 1 | M35: 82000000 | N35: Внутренний перевод | O35: Технические | P35: Перевод между своими счетами
A36: 02.07.2026 | B36: ЦентрКредит | C36: KZT | D36: 2401 | E36: Товарищество с ограниченной ответственностью "WayStar Group" | F36: 240340014287 | G36: 322 | H36: Частичная выплата вклада по депозитному договору № 01607034 от 02.07.2026 в размере 109915104.15 согласно ДП. Вкладчик: Товарищество с ограниченной ответственностью "WayStar Group". | J36: 1.099151e+08 | K36: 1 | M36: 1.099151e+08 | N36: Внутренний перевод | O36: Технические | P36: Перевод между своими счетами
A37: 03.07.2026 | B37: ЦентрКредит | C37: KZT | D37: 2401 | E37: УГД по Есильскому району ДГД по городу Астане КГД МФ РК | F37: 081240013779 | G37: 911 | H37: КПН за нерезидента (доплата). Начисленные (исчисленные) и иные обязательства в бюджет | I37: 15843.69 | K37: 1 | L37: 15843.69 | N37: Внешняя операция | O37: Налоги | P37: Налоги и отчисления | Q37: УГД по Есильскому району ДГД по городу Астан
A38: 03.07.2026 | B38: ЦентрКредит | C38: KZT | D38: 2401 | E38: Товарищество с ограниченной ответственностью "WayStar Group" | F38: 240340014287 | G38: 423 | H38: Погашение вознаграждения по договору № AQ5/2024/U/S/120240/0001L от 06.01.25. Заемщик: Товарищество с ограниченной ответственностью "WayStar Group" | I38: 52589.43 | K38: 1 | L38: 52589.43 | N38: Внутренний перевод | O38: Технические | P38: Перевод между своими счетами
A39: 03.07.2026 | B39: ЦентрКредит | C39: KZT | D39: 2401 | E39: Товарищество с ограниченной ответственностью "WayStar Group" | F39: 240340014287 | G39: 423 | H39: Погашение вознаграждения по договору № AQ5/2024/U/S/120240/0001L от 06.01.25. Заемщик: Товарищество с ограниченной ответственностью "WayStar Group" | I39: 113114.11 | K39: 1 | L39: 113114.11 | N39: Внутренний перевод | O39: Технические | P39: Перевод между своими счетами
A40: 03.07.2026 | B40: ЦентрКредит | C40: KZT | D40: 2401 | E40: Товарищество с ограниченной ответственностью "WayStar Group" | F40: 240340014287 | G40: 423 | H40: Погашение вознаграждения по договору № AQ5/2024/U/S/120240/0001L от 06.01.25. Заемщик: Товарищество с ограниченной ответственностью "WayStar Group" | I40: 117081.71 | K40: 1 | L40: 117081.71 | N40: Внутренний перевод | O40: Технические | P40: Перевод между своими счетами
A41: 03.07.2026 | B41: ЦентрКредит | C41: KZT | D41: 2401 | E41: УГД по Есильскому району ДГД по городу Астане КГД МФ РК | F41: 081240013779 | G41: 911 | H41: ндс за нерезидента июнь 2026. Начисленные (исчисленные) и иные обязательства в бюджет | I41: 2000000 | K41: 1 | L41: 2000000 | N41: Внешняя операция | O41: Налоги | P41: Налоги и отчисления | Q41: УГД по Есильскому району ДГД по городу Астан
...
