Workbook

Sheet Справочник
A1: Справочник технических порогов и амортизации
A2: Параметр | B2: Значение | C2: Ед. | D2: Как используется
A3: Мин. обод после обточки при ДР | B3: 35 | C3: мм | D3: После обточки колесо должно иметь не менее 35 мм
A4: Съем металла при обточке | B4: 15 | C4: мм | D4: По условию расчета при обточке снимается 15 мм
A5: Порог до ДР | B5: =B3+B4 | C5: мм | D5: 35 мм + 15 мм = 50 мм: ниже порога колесная пара не проходит условие после обточки
A6: Текущий эксплуатационный предел | B6: 27 | C6: мм | D6: Предельное текущее значение; не заменяет требование 35 мм после обточки
A7: Макс. поправка на близость ДР | B7: 10 | C7: п.п. | D7: Модельное допущение: дополнительная амортизация при наступившем ДР; изменить при наличии фактической стоимости ДР
A8: Цена новой цистерны | B8: 4650000 | C8: ₽ / вагон | D8: Рыночная база пользователя; 100% стоимости нового вагона

Sheet Параметры
A1: Параметры методики v2 (компонентный затратный подход)
A2: Дата оценки | B2: 46239 | D2: Фиксированная дата расчёта
A3: Цена новой цистерны | B3: =Справочник!B8 | C3: ₽/вагон | D3: Ссылка на Справочник (100% нового вагона)
A4: — Доли компонентов в стоимости нового вагона (Σ = 100%) —
A5: Доля: котёл + рама | B5: 0.55 | D5: ДОПУЩЕНИЕ — уточнить по калькуляции завода
A6: Доля: тележки (литьё: боковые рамы + надрессорные балки) | B6: 0.18 | D6: ДОПУЩЕНИЕ — уточнить
A7: Доля: колёсные пары (4 шт) | B7: 0.2 | D7: ДОПУЩЕНИЕ — уточнить
A8: Доля: прочее (автосцепка, тормоз, арматура) | B8: 0.07 | D8: ДОПУЩЕНИЕ — уточнить
A9: Контроль суммы долей (должно быть 1,00) | B9: =SUM(B5:B8) | D9: Если ≠ 1,00 — исправьте доли
A10: — Ресурсы и пределы —
A11: Нормативный срок службы (fallback), лет | B11: 32 | C11: лет | D11: Используется, если нет даты СС в данных
A12: Срок службы литья тележек, лет | B12: 30 | C12: лет | D12: ДОПУЩЕНИЕ — нормативный срок рам/балок
A13: Толщина обода новой КП | B13: 70 | C13: мм | D13: ДОПУЩЕНИЕ — полный диапазон износа обода
A14: Предельная толщина обода | B14: =Справочник!B6 | C14: мм | D14: Ссылка на Справочник (эксплуатационный предел)
A15: Съём металла при обточке | B15: =Справочник!B4 | C15: мм | D15: Ссылка на Справочник
A16: Мин. обод после обточки (порог годности) | B16: =Справочник!B3 | C16: мм | D16: Ссылка на Справочник
A17: — Стоимости ремонтов, ₽ —
A18: Стоимость предстоящего планового ремонта (ДР) | B18: 300000 | C18: ₽ | D18: ДОПУЩЕНИЕ — заменить фактической сметой ДР
A19: Стоимость замены одной колёсной пары | B19: 220000 | C19: ₽/шт | D19: ДОПУЩЕНИЕ — цена новой/годной КП

Sheet Прайс
A1: Цены собственника (без НДС), по модели и году постройки
A2: Модель вагона | B2: Год постройки | C2: Кол-во | D2: Цена за ед. без НДС, ₽ | E2: Итого без НДС, ₽
A3: 15-1219-1П | B3: 2020 | C3: 60 | D3: 4125000 | E3: =C3*D3
A4: 15-150-04П | B4: 2011 | C4: 21 | D4: 2461000 | E4: =C4*D4
A5: 15-150-04П | B5: 2012 | C5: 7 | D5: 2621500 | E5: =C5*D5
A6: 15-150-04П | B6: 2015 | C6: 14 | D6: 3103000 | E6: =C6*D6
A7: 15-1755П | B7: 2013 | C7: 24 | D7: 2782000 | E7: =C7*D7
A8: 15-1755П | B8: 2014 | C8: 5 | D8: 2942500 | E8: =C8*D8
A9: 15-5103-7П | B9: 2011 | C9: 23 | D9: 2461000 | E9: =C9*D9
A10: 15-5103-7П | B10: 2012 | C10: 3 | D10: 2621500 | E10: =C10*D10
A11: 15-5103-7П | B11: 2015 | C11: 9 | D11: 3103000 | E11: =C11*D11
A12: ИТОГО | C12: =SUM(C3:C11) | E12: =SUM(E3:E11)

Sheet Оценка
A1: Оценка остаточной стоимости 166 цистерн — методика v2 (компонентный затратный подход). Синие/жёлтые ячейки-допущения — на листе «Параметры».
A2: № вагона | B2: Модель | C2: Год постройки | D2: Год оконч. срока службы | E2: Полный срок службы, лет | F2: Возраст вагона, лет | G2: Износ котла+рамы, % | H2: Остаточная котла+рамы, % | I2: Средний год литья тележек | J2: Возраст литья, лет | K2: Износ литья, % | L2: Остаточная литья, % | M2: Мин. обод по КП, мм | N2: Остаточная колёсных пар, % | O2: Остаточная прочего, % | P2: Компонентная стоимость, ₽ | Q2: Последний ремонт | R2: Следующий плановый ремонт | S2: Использовано цикла ДР, % | T2: Остаточный пробег, км | U2: Норма пробега, км | V2: Использовано цикла пробега, % | W2: Позиция обслуживания, % | X2: Обязательство ремонта (ДР), ₽ | Y2: КП не проходят обточку, шт | Z2: Обязательство замены КП, ₽ | AA2: ИТОГОВАЯ стоимость v2, ₽ | AB2: Цена продавца, ₽ (ввод) | AC2: Отклонение рынок−модель, ₽ | AD2: Оценка v1 (справочно), ₽
A3: =Комплектация!A5 | B3: =Комплектация!C5 | C3: =Комплектация!E5 | D3: 2043 | E3: =IF(D3="",Параметры!$B$11,MAX(1,D3-C3)) | F3: =MAX(0,YEAR(Параметры!$B$2)-C3) | G3: =MIN(100,F3/E3*100) | H3: =100-G3 | I3: =AVERAGE(Комплектация!BJ5,Комплектация!BP5,Комплектация!BV5,Комплектация!CB5,Комплектация!CH5,Комплектация!CN5) | J3: =MAX(0,YEAR(Параметры!$B$2)-I3) | K3: =MIN(100,J3/Параметры!$B$12*100) | L3: =100-K3 | M3: =MIN(Комплектация!AA5,Комплектация!AB5,Комплектация!AK5,Комплектация!AL5,Комплектация!AU5,Комплектация!AV5,Комплектация!BE5,Комплектация!BF5) | N3: =AVERAGE((100-MAX(0,MIN(100,(Параметры!$B$13-MIN(Комплектация!AA5,Комплектация!AB5))/(Параметры!$B$13-Параметры!$B$14)*100))),(100-MAX(0,MIN(100,(Параметры!$B$13-MIN(Комплектация!AK5,Комплектация!AL5))/(Параметры!$B$13-Параметры!$B$14)*100))),(100-MAX(0,MIN(100,(Параметры!$B$13-MIN(Комплектация!AU5,Комплектация!AV5))/(Параметры!$B$13-Параметры!$B$14)*100))),(100-MAX(0,MIN(100,(Параметры!$B$13-MIN(Комплектация!BE5,Комплектация!BF5))/(Параметры!$B$13-Параметры!$B$14)*100)))) | O3: =AVERAGE(H3,L3) | P3: =Параметры!$B$3*(Параметры!$B$5*H3+Параметры!$B$6*L3+Параметры!$B$7*N3+Параметры!$B$8*O3)/100 | Q3: 46099 | R3: 47195 | S3: =IF(OR(Q3="",R3="",R3=Q3),"",MAX(0,MIN(100,(Параметры!$B$2-Q3)/(R3-Q3)*100))) | T3: =IF(ISNUMBER(Комплектация!P5),Комплектация!P5,"") | U3: =IF(ISNUMBER(Комплектация!N5),Комплектация!N5,"") | V3: =IF(OR(U3="",T3="",U3=0),"",MAX(0,MIN(100,(U3-T3)/U3*100))) | W3: =MAX(IF(S3="",0,S3),IF(V3="",0,V3)) | X3: =Параметры!$B$18*W3/100 | Y3: =IF(MIN(Комплектация!AA5,Комплектация!AB5)-Параметры!$B$15<Параметры!$B$16,1,0)+IF(MIN(Комплектация!AK5,Комплектация!AL5)-Параметры!$B$15<Параметры!$B$16,1,0)+IF(MIN(Комплектация!AU5,Комплектация!AV5)-Параметры!$B$15<Параметры!$B$16,1,0)+IF(MIN(Комплектация!BE5,Комплектация!BF5)-Параметры!$B$15<Параметры!$B$16,1,0) | Z3: =Y3*Параметры!$B$19 | AA3: =MAX(0,P3-X3-Z3) | AB3: =SUMIFS(Прайс!$D$3:$D$11,Прайс!$A$3:$A$11,B3,Прайс!$B$3:$B$11,C3) | AC3: =IF(AB3="","",AB3-AA3) | AD3: 3198508.4
A4: =Комплектация!A6 | B4: =Комплектация!C6 | C4: =Комплектация!E6 | D4: 2043 | E4: =IF(D4="",Параметры!$B$11,MAX(1,D4-C4)) | F4: =MAX(0,YEAR(Параметры!$B$2)-C4) | G4: =MIN(100,F4/E4*100) | H4: =100-G4 | I4: =AVERAGE(Комплектация!BJ6,Комплектация!BP6,Комплектация!BV6,Комплектация!CB6,Комплектация!CH6,Комплектация!CN6) | J4: =MAX(0,YEAR(Параметры!$B$2)-I4) | K4: =MIN(100,J4/Параметры!$B$12*100) | L4: =100-K4 | M4: =MIN(Комплектация!AA6,Комплектация!AB6,Комплектация!AK6,Комплектация!AL6,Комплектация!AU6,Комплектация!AV6,Комплектация!BE6,Комплектация!BF6) | N4: =AVERAGE((100-MAX(0,MIN(100,(Параметры!$B$13-MIN(Комплектация!AA6,Комплектация!AB6))/(Параметры!$B$13-Параметры!$B$14)*100))),(100-MAX(0,MIN(100,(Параметры!$B$13-MIN(Комплектация!AK6,Комплектация!AL6))/(Параметры!$B$13-Параметры!$B$14)*100))),(100-MAX(0,MIN(100,(Параметры!$B$13-MIN(Комплектация!AU6,Комплектация!AV6))/(Параметры!$B$13-Параметры!$B$14)*100))),(100-MAX(0,MIN(100,(Параметры!$B$13-MIN(Комплектация!BE6,Комплектация!BF6))/(Параметры!$B$13-Параметры!$B$14)*100)))) | O4: =AVERAGE(H4,L4) | P4: =Параметры!$B$3*(Параметры!$B$5*H4+Параметры!$B$6*L4+Параметры!$B$7*N4+Параметры!$B$8*O4)/100 | Q4: 46065 | R4: 46795 | S4: =IF(OR(Q4="",R4="",R4=Q4),"",MAX(0,MIN(100,(Параметры!$B$2-Q4)/(R4-Q4)*100))) | T4: =IF(ISNUMBER(Комплектация!P6),Комплектация!P6,"") | U4: =IF(ISNUMBER(Комплектация!N6),Комплектация!N6,"") | V4: =IF(OR(U4="",T4="",U4=0),"",MAX(0,MIN(100,(U4-T4)/U4*100))) | W4: =MAX(IF(S4="",0,S4),IF(V4="",0,V4)) | X4: =Параметры!$B$18*W4/100 | Y4: =IF(MIN(Комплектация!AA6,Комплектация!AB6)-Параметры!$B$15<Параметры!$B$16,1,0)+IF(MIN(Комплектация!AK6,Комплектация!AL6)-Параметры!$B$15<Параметры!$B$16,1,0)+IF(MIN(Комплектация!AU6,Комплектация!AV6)-Параметры!$B$15<Параметры!$B$16,1,0)+IF(MIN(Комплектация!BE6,Комплектация!BF6)-Параметры!$B$15<Параметры!$B$16,1,0) | Z4: =Y4*Параметры!$B$19 | AA4: =MAX(0,P4-X4-Z4) | AB4: =SUMIFS(Прайс!$D$3:$D$11,Прайс!$A$3:$A$11,B4,Прайс!$B$3:$B$11,C4) | AC4: =IF(AB4="","",AB4-AA4) | AD4: 3170320.6
A5: =Комплектация!A7 | B5: =Комплектация!C7 | C5: =Комплектация!E7 | D5: 2043 | E5: =IF(D5="",Параметры!$B$11,MAX(1,D5-C5)) | F5: =MAX(0,YEAR(Параметры!$B$2)-C5) | G5: =MIN(100,F5/E5*100) | H5: =100-G5 | I5: =AVERAGE(Комплектация!BJ7,Комплектация!BP7,Комплектация!BV7,Комплектация!CB7,Комплектация!CH7,Комплектация!CN7) | J5: =MAX(0,YEAR(Параметры!$B$2)-I5) | K5: =MIN(100,J5/Параметры!$B$12*100) | L5: =100-K5 | M5: =MIN(Комплектация!AA7,Комплектация!AB7,Комплектация!AK7,Комплектация!AL7,Комплектация!AU7,Комплектация!AV7,Комплектация!BE7,Комплектация!BF7) | N5: =AVERAGE((100-MAX(0,MIN(100,(Параметры!$B$13-MIN(Комплектация!AA7,Комплектация!AB7))/(Параметры!$B$13-Параметры!$B$14)*100))),(100-MAX(0,MIN(100,(Параметры!$B$13-MIN(Комплектация!AK7,Комплектация!AL7))/(Параметры!$B$13-Параметры!$B$14)*100))),(100-MAX(0,MIN(100,(Параметры!$B$13-MIN(Комплектация!AU7,Комплектация!AV7))/(Параметры!$B$13-Параметры!$B$14)*100))),(100-MAX(0,MIN(100,(Параметры!$B$13-MIN(Комплектация!BE7,Комплектация!BF7))/(Параметры!$B$13-Параметры!$B$14)*100)))) | O5: =AVERAGE(H5,L5) | P5: =Параметры!$B$3*(Параметры!$B$5*H5+Параметры!$B$6*L5+Параметры!$B$7*N5+Параметры!$B$8*O5)/100 | Q5: 46065 | R5: 46795 | S5: =IF(OR(Q5="",R5="",R5=Q5),"",MAX(0,MIN(100,(Параметры!$B$2-Q5)/(R5-Q5)*100))) | T5: =IF(ISNUMBER(Комплектация!P7),Комплектация!P7,"") | U5: =IF(ISNUMBER(Комплектация!N7),Комплектация!N7,"") | V5: =IF(OR(U5="",T5="",U5=0),"",MAX(0,MIN(100,(U5-T5)/U5*100))) | W5: =MAX(IF(S5="",0,S5),IF(V5="",0,V5)) | X5: =Параметры!$B$18*W5/100 | Y5: =IF(MIN(Комплектация!AA7,Комплектация!AB7)-Параметры!$B$15<Параметры!$B$16,1,0)+IF(MIN(Комплектация!AK7,Комплектация!AL7)-Параметры!$B$15<Параметры!$B$16,1,0)+IF(MIN(Комплектация!AU7,Комплектация!AV7)-Параметры!$B$15<Параметры!$B$16,1,0)+IF(MIN(Комплектация!BE7,Комплектация!BF7)-Параметры!$B$15<Параметры!$B$16,1,0) | Z5: =Y5*Параметры!$B$19 | AA5: =MAX(0,P5-X5-Z5) | AB5: =SUMIFS(Прайс!$D$3:$D$11,Прайс!$A$3:$A$11,B5,Прайс!$B$3:$B$11,C5) | AC5: =IF(AB5="","",AB5-AA5) | AD5: 1659070.6
A6: =Комплектация!A8 | B6: =Комплектация!C8 | C6: =Комплектация!E8 | D6: 2043 | E6: =IF(D6="",Параметры!$B$11,MAX(1,D6-C6)) | F6: =MAX(0,YEAR(Параметры!$B$2)-C6) | G6: =MIN(100,F6/E6*100) | H6: =100-G6 | I6: =AVERAGE(Комплектация!BJ8,Комплектация!BP8,Комплектация!BV8,Комплектация!CB8,Комплектация!CH8,Комплектация!CN8) | J6: =MAX(0,YEAR(Параметры!$B$2)-I6) | K6: =MIN(100,J6/Параметры!$B$12*100) | L6: =100-K6 | M6: =MIN(Комплектация!AA8,Комплектация!AB8,Комплектация!AK8,Комплектация!AL8,Комплектация!AU8,Комплектация!AV8,Комплектация!BE8,Комплектация!BF8) | N6: =AVERAGE((100-MAX(0,MIN(100,(Параметры!$B$13-MIN(Комплектация!AA8,Комплектация!AB8))/(Параметры!$B$13-Параметры!$B$14)*100))),(100-MAX(0,MIN(100,(Параметры!$B$13-MIN(Комплектация!AK8,Комплектация!AL8))/(Параметры!$B$13-Параметры!$B$14)*100))),(100-MAX(0,MIN(100,(Параметры!$B$13-MIN(Комплектация!AU8,Комплектация!AV8))/(Параметры!$B$13-Параметры!$B$14)*100))),(100-MAX(0,MIN(100,(Параметры!$B$13-MIN(Комплектация!BE8,Комплектация!BF8))/(Параметры!$B$13-Параметры!$B$14)*100)))) | O6: =AVERAGE(H6,L6) | P6: =Параметры!$B$3*(Параметры!$B$5*H6+Параметры!$B$6*L6+Параметры!$B$7*N6+Параметры!$B$8*O6)/100 | Q6: 46065 | R6: 46795 | S6: =IF(OR(Q6="",R6="",R6=Q6),"",MAX(0,MIN(100,(Параметры!$B$2-Q6)/(R6-Q6)*100))) | T6: =IF(ISNUMBER(Комплектация!P8),Комплектация!P8,"") | U6: =IF(ISNUMBER(Комплектация!N8),Комплектация!N8,"") | V6: =IF(OR(U6="",T6="",U6=0),"",MAX(0,MIN(100,(U6-T6)/U6*100))) | W6: =MAX(IF(S6="",0,S6),IF(V6="",0,V6)) | X6: =Параметры!$B$18*W6/100 | Y6: =IF(MIN(Комплектация!AA8,Комплектация!AB8)-Параметры!$B$15<Параметры!$B$16,1,0)+IF(MIN(Комплектация!AK8,Комплектация!AL8)-Параметры!$B$15<Параметры!$B$16,1,0)+IF(MIN(Комплектация!AU8,Комплектация!AV8)-Параметры!$B$15<Параметры!$B$16,1,0)+IF(MIN(Комплектация!BE8,Комплектация!BF8)-Параметры!$B$15<Параметры!$B$16,1,0) | Z6: =Y6*Параметры!$B$19 | AA6: =MAX(0,P6-X6-Z6) | AB6: =SUMIFS(Прайс!$D$3:$D$11,Прайс!$A$3:$A$11,B6,Прайс!$B$3:$B$11,C6) | AC6: =IF(AB6="","",AB6-AA6) | AD6: 3216820.6
A7: =Комплектация!A9 | B7: =Комплектация!C9 | C7: =Комплектация!E9 | D7: 2044 | E7: =IF(D7="",Параметры!$B$11,MAX(1,D7-C7)) | F7: =MAX(0,YEAR(Параметры!$B$2)-C7) | G7: =MIN(100,F7/E7*100) | H7: =100-G7 | I7: =AVERAGE(Комплектация!BJ9,Комплектация!BP9,Комплектация!BV9,Комплектация!CB9,Комплектация!CH9,Комплектация!CN9) | J7: =MAX(0,YEAR(Параметры!$B$2)-I7) | K7: =MIN(100,J7/Параметры!$B$12*100) | L7: =100-K7 | M7: =MIN(Комплектация!AA9,Комплектация!AB9,Комплектация!AK9,Комплектация!AL9,Комплектация!AU9,Комплектация!AV9,Комплектация!BE9,Комплектация!BF9) | N7: =AVERAGE((100-MAX(0,MIN(100,(Параметры!$B$13-MIN(Комплектация!AA9,Комплектация!AB9))/(Параметры!$B$13-Параметры!$B$14)*100))),(100-MAX(0,MIN(100,(Параметры!$B$13-MIN(Комплектация!AK9,Комплектация!AL9))/(Параметры!$B$13-Параметры!$B$14)*100))),(100-MAX(0,MIN(100,(Параметры!$B$13-MIN(Комплектация!AU9,Комплектация!AV9))/(Параметры!$B$13-Параметры!$B$14)*100))),(100-MAX(0,MIN(100,(Параметры!$B$13-MIN(Комплектация!BE9,Комплектация!BF9))/(Параметры!$B$13-Параметры!$B$14)*100)))) | O7: =AVERAGE(H7,L7) | P7: =Параметры!$B$3*(Параметры!$B$5*H7+Параметры!$B$6*L7+Параметры!$B$7*N7+Параметры!$B$8*O7)/100 | Q7: 45731 | R7: 46461 | S7: =IF(OR(Q7="",R7="",R7=Q7),"",MAX(0,MIN(100,(Параметры!$B$2-Q7)/(R7-Q7)*100))) | T7: =IF(ISNUMBER(Комплектация!P9),Комплектация!P9,"") | U7: =IF(ISNUMBER(Комплектация!N9),Комплектация!N9,"") | V7: =IF(OR(U7="",T7="",U7=0),"",MAX(0,MIN(100,(U7-T7)/U7*100))) | W7: =MAX(IF(S7="",0,S7),IF(V7="",0,V7)) | X7: =Параметры!$B$18*W7/100 | Y7: =IF(MIN(Комплектация!AA9,Комплектация!AB9)-Параметры!$B$15<Параметры!$B$16,1,0)+IF(MIN(Комплектация!AK9,Комплектация!AL9)-Параметры!$B$15<Параметры!$B$16,1,0)+IF(MIN(Комплектация!AU9,Комплектация!AV9)-Параметры!$B$15<Параметры!$B$16,1,0)+IF(MIN(Комплектация!BE9,Комплектация!BF9)-Параметры!$B$15<Параметры!$B$16,1,0) | Z7: =Y7*Параметры!$B$19 | AA7: =MAX(0,P7-X7-Z7) | AB7: =SUMIFS(Прайс!$D$3:$D$11,Прайс!$A$3:$A$11,B7,Прайс!$B$3:$B$11,C7) | AC7: =IF(AB7="","",AB7-AA7) | AD7: 3163911
A8: =Комплектация!A10 | B8: =Комплектация!C10 | C8: =Комплектация!E10 | D8: 2044 | E8: =IF(D8="",Параметры!$B$11,MAX(1,D8-C8)) | F8: =MAX(0,YEAR(Параметры!$B$2)-C8) | G8: =MIN(100,F8/E8*100) | H8: =100-G8 | I8: =AVERAGE(Комплектация!BJ10,Комплектация!BP10,Комплектация!BV10,Комплектация!CB10,Комплектация!CH10,Комплектация!CN10) | J8: =MAX(0,YEAR(Параметры!$B$2)-I8) | K8: =MIN(100,J8/Параметры!$B$12*100) | L8: =100-K8 | M8: =MIN(Комплектация!AA10,Комплектация!AB10,Комплектация!AK10,Комплектация!AL10,Комплектация!AU10,Комплектация!AV10,Комплектация!BE10,Комплектация!BF10) | N8: =AVERAGE((100-MAX(0,MIN(100,(Параметры!$B$13-MIN(Комплектация!AA10,Комплектация!AB10))/(Параметры!$B$13-Параметры!$B$14)*100))),(100-MAX(0,MIN(100,(Параметры!$B$13-MIN(Комплектация!AK10,Комплектация!AL10))/(Параметры!$B$13-Параметры!$B$14)*100))),(100-MAX(0,MIN(100,(Параметры!$B$13-MIN(Комплектация!AU10,Комплектация!AV10))/(Параметры!$B$13-Параметры!$B$14)*100))),(100-MAX(0,MIN(100,(Параметры!$B$13-MIN(Комплектация!BE10,Комплектация!BF10))/(Параметры!$B$13-Параметры!$B$14)*100)))) | O8: =AVERAGE(H8,L8) | P8: =Параметры!$B$3*(Параметры!$B$5*H8+Параметры!$B$6*L8+Параметры!$B$7*N8+Параметры!$B$8*O8)/100 | Q8: 45750 | R8: 46480 | S8: =IF(OR(Q8="",R8="",R8=Q8),"",MAX(0,MIN(100,(Параметры!$B$2-Q8)/(R8-Q8)*100))) | T8: =IF(ISNUMBER(Комплектация!P10),Комплектация!P10,"") | U8: =IF(ISNUMBER(Комплектация!N10),Комплектация!N10,"") | V8: =IF(OR(U8="",T8="",U8=0),"",MAX(0,MIN(100,(U8-T8)/U8*100))) | W8: =MAX(IF(S8="",0,S8),IF(V8="",0,V8)) | X8: =Параметры!$B$18*W8/100 | Y8: =IF(MIN(Комплектация!AA10,Комплектация!AB10)-Параметры!$B$15<Параметры!$B$16,1,0)+IF(MIN(Комплектация!AK10,Комплектация!AL10)-Параметры!$B$15<Параметры!$B$16,1,0)+IF(MIN(Комплектация!AU10,Комплектация!AV10)-Параметры!$B$15<Параметры!$B$16,1,0)+IF(MIN(Комплектация!BE10,Комплектация!BF10)-Параметры!$B$15<Параметры!$B$16,1,0) | Z8: =Y8*Параметры!$B$19 | AA8: =MAX(0,P8-X8-Z8) | AB8: =SUMIFS(Прайс!$D$3:$D$11,Прайс!$A$3:$A$11,B8,Прайс!$B$3:$B$11,C8) | AC8: =IF(AB8="","",AB8-AA8) | AD8: 3176013.7
A9: =Комплектация!A11 | B9: =Комплектация!C11 | C9: =Комплектация!E11 | D9: 2043 | E9: =IF(D9="",Параметры!$B$11,MAX(1,D9-C9)) | F9: =MAX(0,YEAR(Параметры!$B$2)-C9) | G9: =MIN(100,F9/E9*100) | H9: =100-G9 | I9: =AVERAGE(Комплектация!BJ11,Комплектация!BP11,Комплектация!BV11,Комплектация!CB11,Комплектация!CH11,Комплектация!CN11) | J9: =MAX(0,YEAR(Параметры!$B$2)-I9) | K9: =MIN(100,J9/Параметры!$B$12*100) | L9: =100-K9 | M9: =MIN(Комплектация!AA11,Комплектация!AB11,Комплектация!AK11,Комплектация!AL11,Комплектация!AU11,Комплектация!AV11,Комплектация!BE11,Комплектация!BF11) | N9: =AVERAGE((100-MAX(0,MIN(100,(Параметры!$B$13-MIN(Комплектация!AA11,Комплектация!AB11))/(Параметры!$B$13-Параметры!$B$14)*100))),(100-MAX(0,MIN(100,(Параметры!$B$13-MIN(Комплектация!AK11,Комплектация!AL11))/(Параметры!$B$13-Параметры!$B$14)*100))),(100-MAX(0,MIN(100,(Параметры!$B$13-MIN(Комплектация!AU11,Комплектация!AV11))/(Параметры!$B$13-Параметры!$B$14)*100))),(100-MAX(0,MIN(100,(Параметры!$B$13-MIN(Комплектация!BE11,Комплектация!BF11))/(Параметры!$B$13-Параметры!$B$14)*100)))) | O9: =AVERAGE(H9,L9) | P9: =Параметры!$B$3*(Параметры!$B$5*H9+Параметры!$B$6*L9+Параметры!$B$7*N9+Параметры!$B$8*O9)/100 | Q9: 46067 | R9: 46797 | S9: =IF(OR(Q9="",R9="",R9=Q9),"",MAX(0,MIN(100,(Параметры!$B$2-Q9)/(R9-Q9)*100))) | T9: =IF(ISNUMBER(Комплектация!P11),Комплектация!P11,"") | U9: =IF(ISNUMBER(Комплектация!N11),Комплектация!N11,"") | V9: =IF(OR(U9="",T9="",U9=0),"",MAX(0,MIN(100,(U9-T9)/U9*100))) | W9: =MAX(IF(S9="",0,S9),IF(V9="",0,V9)) | X9: =Параметры!$B$18*W9/100 | Y9: =IF(MIN(Комплектация!AA11,Комплектация!AB11)-Параметры!$B$15<Параметры!$B$16,1,0)+IF(MIN(Комплектация!AK11,Комплектация!AL11)-Параметры!$B$15<Параметры!$B$16,1,0)+IF(MIN(Комплектация!AU11,Комплектация!AV11)-Параметры!$B$15<Параметры!$B$16,1,0)+IF(MIN(Комплектация!BE11,Комплектация!BF11)-Параметры!$B$15<Параметры!$B$16,1,0) | Z9: =Y9*Параметры!$B$19 | AA9: =MAX(0,P9-X9-Z9) | AB9: =SUMIFS(Прайс!$D$3:$D$11,Прайс!$A$3:$A$11,B9,Прайс!$B$3:$B$11,C9) | AC9: =IF(AB9="","",AB9-AA9) | AD9: 3194844.6
A10: =Комплектация!A12 | B10: =Комплектация!C12 | C10: =Комплектация!E12 | D10: 2047 | E10: =IF(D10="",Параметры!$B$11,MAX(1,D10-C10)) | F10: =MAX(0,YEAR(Параметры!$B$2)-C10) | G10: =MIN(100,F10/E10*100) | H10: =100-G10 | I10: =AVERAGE(Комплектация!BJ12,Комплектация!BP12,Комплектация!BV12,Комплектация!CB12,Комплектация!CH12,Комплектация!CN12) | J10: =MAX(0,YEAR(Параметры!$B$2)-I10) | K10: =MIN(100,J10/Параметры!$B$12*100) | L10: =100-K10 | M10: =MIN(Комплектация!AA12,Комплектация!AB12,Комплектация!AK12,Комплектация!AL12,Комплектация!AU12,Комплектация!AV12,Комплектация!BE12,Комплектация!BF12) | N10: =AVERAGE((100-MAX(0,MIN(100,(Параметры!$B$13-MIN(Комплектация!AA12,Комплектация!AB12))/(Параметры!$B$13-Параметры!$B$14)*100))),(100-MAX(0,MIN(100,(Параметры!$B$13-MIN(Комплектация!AK12,Комплектация!AL12))/(Параметры!$B$13-Параметры!$B$14)*100))),(100-MAX(0,MIN(100,(Параметры!$B$13-MIN(Комплектация!AU12,Комплектация!AV12))/(Параметры!$B$13-Параметры!$B$14)*100))),(100-MAX(0,MIN(100,(Параметры!$B$13-MIN(Комплектация!BE12,Комплектация!BF12))/(Параметры!$B$13-Параметры!$B$14)*100)))) | O10: =AVERAGE(H10,L10) | P10: =Параметры!$B$3*(Параметры!$B$5*H10+Параметры!$B$6*L10+Параметры!$B$7*N10+Параметры!$B$8*O10)/100 | Q10: 45889 | R10: 46985 | S10: =IF(OR(Q10="",R10="",R10=Q10),"",MAX(0,MIN(100,(Параметры!$B$2-Q10)/(R10-Q10)*100))) | T10: =IF(ISNUMBER(Комплектация!P12),Комплектация!P12,"") | U10: =IF(ISNUMBER(Комплектация!N12),Комплектация!N12,"") | V10: =IF(OR(U10="",T10="",U10=0),"",MAX(0,MIN(100,(U10-T10)/U10*100))) | W10: =MAX(IF(S10="",0,S10),IF(V10="",0,V10)) | X10: =Параметры!$B$18*W10/100 | Y10: =IF(MIN(Комплектация!AA12,Комплектация!AB12)-Параметры!$B$15<Параметры!$B$16,1,0)+IF(MIN(Комплектация!AK12,Комплектация!AL12)-Параметры!$B$15<Параметры!$B$16,1,0)+IF(MIN(Комплектация!AU12,Комплектация!AV12)-Параметры!$B$15<Параметры!$B$16,1,0)+IF(MIN(Комплектация!BE12,Комплектация!BF12)-Параметры!$B$15<Параметры!$B$16,1,0) | Z10: =Y10*Параметры!$B$19 | AA10: =MAX(0,P10-X10-Z10) | AB10: =SUMIFS(Прайс!$D$3:$D$11,Прайс!$A$3:$A$11,B10,Прайс!$B$3:$B$11,C10) | AC10: =IF(AB10="","",AB10-AA10) | AD10: 3394224.2
A11: =Комплектация!A13 | B11: =Комплектация!C13 | C11: =Комплектация!E13 | D11: 2043 | E11: =IF(D11="",Параметры!$B$11,MAX(1,D11-C11)) | F11: =MAX(0,YEAR(Параметры!$B$2)-C11) | G11: =MIN(100,F11/E11*100) | H11: =100-G11 | I11: =AVERAGE(Комплектация!BJ13,Комплектация!BP13,Комплектация!BV13,Комплектация!CB13,Комплектация!CH13,Комплектация!CN13) | J11: =MAX(0,YEAR(Параметры!$B$2)-I11) | K11: =MIN(100,J11/Параметры!$B$12*100) | L11: =100-K11 | M11: =MIN(Комплектация!AA13,Комплектация!AB13,Комплектация!AK13,Комплектация!AL13,Комплектация!AU13,Комплектация!AV13,Комплектация!BE13,Комплектация!BF13) | N11: =AVERAGE((100-MAX(0,MIN(100,(Параметры!$B$13-MIN(Комплектация!AA13,Комплектация!AB13))/(Параметры!$B$13-Параметры!$B$14)*100))),(100-MAX(0,MIN(100,(Параметры!$B$13-MIN(Комплектация!AK13,Комплектация!AL13))/(Параметры!$B$13-Параметры!$B$14)*100))),(100-MAX(0,MIN(100,(Параметры!$B$13-MIN(Комплектация!AU13,Комплектация!AV13))/(Параметры!$B$13-Параметры!$B$14)*100))),(100-MAX(0,MIN(100,(Параметры!$B$13-MIN(Комплектация!BE13,Комплектация!BF13))/(Параметры!$B$13-Параметры!$B$14)*100)))) | O11: =AVERAGE(H11,L11) | P11: =Параметры!$B$3*(Параметры!$B$5*H11+Параметры!$B$6*L11+Параметры!$B$7*N11+Параметры!$B$8*O11)/100 | Q11: 45890 | R11: 46986 | S11: =IF(OR(Q11="",R11="",R11=Q11),"",MAX(0,MIN(100,(Параметры!$B$2-Q11)/(R11-Q11)*100))) | T11: =IF(ISNUMBER(Комплектация!P13),Комплектация!P13,"") | U11: =IF(ISNUMBER(Комплектация!N13),Комплектация!N13,"") | V11: =IF(OR(U11="",T11="",U11=0),"",MAX(0,MIN(100,(U11-T11)/U11*100))) | W11: =MAX(IF(S11="",0,S11),IF(V11="",0,V11)) | X11: =Параметры!$B$18*W11/100 | Y11: =IF(MIN(Комплектация!AA13,Комплектация!AB13)-Параметры!$B$15<Параметры!$B$16,1,0)+IF(MIN(Комплектация!AK13,Комплектация!AL13)-Параметры!$B$15<Параметры!$B$16,1,0)+IF(MIN(Комплектация!AU13,Комплектация!AV13)-Параметры!$B$15<Параметры!$B$16,1,0)+IF(MIN(Комплектация!BE13,Комплектация!BF13)-Параметры!$B$15<Параметры!$B$16,1,0) | Z11: =Y11*Параметры!$B$19 | AA11: =MAX(0,P11-X11-Z11) | AB11: =SUMIFS(Прайс!$D$3:$D$11,Прайс!$A$3:$A$11,B11,Прайс!$B$3:$B$11,C11) | AC11: =IF(AB11="","",AB11-AA11) | AD11: 3092398.5
A12: =Комплектация!A14 | B12: =Комплектация!C14 | C12: =Комплектация!E14 | D12: 2047 | E12: =IF(D12="",Параметры!$B$11,MAX(1,D12-C12)) | F12: =MAX(0,YEAR(Параметры!$B$2)-C12) | G12: =MIN(100,F12/E12*100) | H12: =100-G12 | I12: =AVERAGE(Комплектация!BJ14,Комплектация!BP14,Комплектация!BV14,Комплектация!CB14,Комплектация!CH14,Комплектация!CN14) | J12: =MAX(0,YEAR(Параметры!$B$2)-I12) | K12: =MIN(100,J12/Параметры!$B$12*100) | L12: =100-K12 | M12: =MIN(Комплектация!AA14,Комплектация!AB14,Комплектация!AK14,Комплектация!AL14,Комплектация!AU14,Комплектация!AV14,Комплектация!BE14,Комплектация!BF14) | N12: =AVERAGE((100-MAX(0,MIN(100,(Параметры!$B$13-MIN(Комплектация!AA14,Комплектация!AB14))/(Параметры!$B$13-Параметры!$B$14)*100))),(100-MAX(0,MIN(100,(Параметры!$B$13-MIN(Комплектация!AK14,Комплектация!AL14))/(Параметры!$B$13-Параметры!$B$14)*100))),(100-MAX(0,MIN(100,(Параметры!$B$13-MIN(Комплектация!AU14,Комплектация!AV14))/(Параметры!$B$13-Параметры!$B$14)*100))),(100-MAX(0,MIN(100,(Параметры!$B$13-MIN(Комплектация!BE14,Комплектация!BF14))/(Параметры!$B$13-Параметры!$B$14)*100)))) | O12: =AVERAGE(H12,L12) | P12: =Параметры!$B$3*(Параметры!$B$5*H12+Параметры!$B$6*L12+Параметры!$B$7*N12+Параметры!$B$8*O12)/100 | Q12: 45889 | R12: 46985 | S12: =IF(OR(Q12="",R12="",R12=Q12),"",MAX(0,MIN(100,(Параметры!$B$2-Q12)/(R12-Q12)*100))) | T12: =IF(ISNUMBER(Комплектация!P14),Комплектация!P14,"") | U12: =IF(ISNUMBER(Комплектация!N14),Комплектация!N14,"") | V12: =IF(OR(U12="",T12="",U12=0),"",MAX(0,MIN(100,(U12-T12)/U12*100))) | W12: =MAX(IF(S12="",0,S12),IF(V12="",0,V12)) | X12: =Параметры!$B$18*W12/100 | Y12: =IF(MIN(Комплектация!AA14,Комплектация!AB14)-Параметры!$B$15<Параметры!$B$16,1,0)+IF(MIN(Комплектация!AK14,Комплектация!AL14)-Параметры!$B$15<Параметры!$B$16,1,0)+IF(MIN(Комплектация!AU14,Комплектация!AV14)-Параметры!$B$15<Параметры!$B$16,1,0)+IF(MIN(Комплектация!BE14,Комплектация!BF14)-Параметры!$B$15<Параметры!$B$16,1,0) | Z12: =Y12*Параметры!$B$19 | AA12: =MAX(0,P12-X12-Z12) | AB12: =SUMIFS(Прайс!$D$3:$D$11,Прайс!$A$3:$A$11,B12,Прайс!$B$3:$B$11,C12) | AC12: =IF(AB12="","",AB12-AA12) | AD12: 1813224.2
A13: =Комплектация!A15 | B13: =Комплектация!C15 | C13: =Комплектация!E15 | D13: 2043 | E13: =IF(D13="",Параметры!$B$11,MAX(1,D13-C13)) | F13: =MAX(0,YEAR(Параметры!$B$2)-C13) | G13: =MIN(100,F13/E13*100) | H13: =100-G13 | I13: =AVERAGE(Комплектация!BJ15,Комплектация!BP15,Комплектация!BV15,Комплектация!CB15,Комплектация!CH15,Комплектация!CN15) | J13: =MAX(0,YEAR(Параметры!$B$2)-I13) | K13: =MIN(100,J13/Параметры!$B$12*100) | L13: =100-K13 | M13: =MIN(Комплектация!AA15,Комплектация!AB15,Комплектация!AK15,Комплектация!AL15,Комплектация!AU15,Комплектация!AV15,Комплектация!BE15,Комплектация!BF15) | N13: =AVERAGE((100-MAX(0,MIN(100,(Параметры!$B$13-MIN(Комплектация!AA15,Комплектация!AB15))/(Параметры!$B$13-Параметры!$B$14)*100))),(100-MAX(0,MIN(100,(Параметры!$B$13-MIN(Комплектация!AK15,Комплектация!AL15))/(Параметры!$B$13-Параметры!$B$14)*100))),(100-MAX(0,MIN(100,(Параметры!$B$13-MIN(Комплектация!AU15,Комплектация!AV15))/(Параметры!$B$13-Параметры!$B$14)*100))),(100-MAX(0,MIN(100,(Параметры!$B$13-MIN(Комплектация!BE15,Комплектация!BF15))/(Параметры!$B$13-Параметры!$B$14)*100)))) | O13: =AVERAGE(H13,L13) | P13: =Параметры!$B$3*(Параметры!$B$5*H13+Параметры!$B$6*L13+Параметры!$B$7*N13+Параметры!$B$8*O13)/100 | Q13: 45891 | R13: 46987 | S13: =IF(OR(Q13="",R13="",R13=Q13),"",MAX(0,MIN(100,(Параметры!$B$2-Q13)/(R13-Q13)*100))) | T13: =IF(ISNUMBER(Комплектация!P15),Комплектация!P15,"") | U13: =IF(ISNUMBER(Комплектация!N15),Комплектация!N15,"") | V13: =IF(OR(U13="",T13="",U13=0),"",MAX(0,MIN(100,(U13-T13)/U13*100))) | W13: =MAX(IF(S13="",0,S13),IF(V13="",0,V13)) | X13: =Параметры!$B$18*W13/100 | Y13: =IF(MIN(Комплектация!AA15,Комплектация!AB15)-Параметры!$B$15<Параметры!$B$16,1,0)+IF(MIN(Комплектация!AK15,Комплектация!AL15)-Параметры!$B$15<Параметры!$B$16,1,0)+IF(MIN(Комплектация!AU15,Комплектация!AV15)-Параметры!$B$15<Параметры!$B$16,1,0)+IF(MIN(Комплектация!BE15,Комплектация!BF15)-Параметры!$B$15<Параметры!$B$16,1,0) | Z13: =Y13*Параметры!$B$19 | AA13: =MAX(0,P13-X13-Z13) | AB13: =SUMIFS(Прайс!$D$3:$D$11,Прайс!$A$3:$A$11,B13,Прайс!$B$3:$B$11,C13) | AC13: =IF(AB13="","",AB13-AA13) | AD13: 3104447.8
A14: =Комплектация!A16 | B14: =Комплектация!C16 | C14: =Комплектация!E16 | D14: 2044 | E14: =IF(D14="",Параметры!$B$11,MAX(1,D14-C14)) | F14: =MAX(0,YEAR(Параметры!$B$2)-C14) | G14: =MIN(100,F14/E14*100) | H14: =100-G14 | I14: =AVERAGE(Комплектация!BJ16,Комплектация!BP16,Комплектация!BV16,Комплектация!CB16,Комплектация!CH16,Комплектация!CN16) | J14: =MAX(0,YEAR(Параметры!$B$2)-I14) | K14: =MIN(100,J14/Параметры!$B$12*100) | L14: =100-K14 | M14: =MIN(Комплектация!AA16,Комплектация!AB16,Комплектация!AK16,Комплектация!AL16,Комплектация!AU16,Комплектация!AV16,Комплектация!BE16,Комплектация!BF16) | N14: =AVERAGE((100-MAX(0,MIN(100,(Параметры!$B$13-MIN(Комплектация!AA16,Комплектация!AB16))/(Параметры!$B$13-Параметры!$B$14)*100))),(100-MAX(0,MIN(100,(Параметры!$B$13-MIN(Комплектация!AK16,Комплектация!AL16))/(Параметры!$B$13-Параметры!$B$14)*100))),(100-MAX(0,MIN(100,(Параметры!$B$13-MIN(Комплектация!AU16,Комплектация!AV16))/(Параметры!$B$13-Параметры!$B$14)*100))),(100-MAX(0,MIN(100,(Параметры!$B$13-MIN(Комплектация!BE16,Комплектация!BF16))/(Параметры!$B$13-Параметры!$B$14)*100)))) | O14: =AVERAGE(H14,L14) | P14: =Параметры!$B$3*(Параметры!$B$5*H14+Параметры!$B$6*L14+Параметры!$B$7*N14+Параметры!$B$8*O14)/100 | Q14: 45923 | R14: 47019 | S14: =IF(OR(Q14="",R14="",R14=Q14),"",MAX(0,MIN(100,(Параметры!$B$2-Q14)/(R14-Q14)*100))) | T14: =IF(ISNUMBER(Комплектация!P16),Комплектация!P16,"") | U14: =IF(ISNUMBER(Комплектация!N16),Комплектация!N16,"") | V14: =IF(OR(U14="",T14="",U14=0),"",MAX(0,MIN(100,(U14-T14)/U14*100))) | W14: =MAX(IF(S14="",0,S14),IF(V14="",0,V14)) | X14: =Параметры!$B$18*W14/100 | Y14: =IF(MIN(Комплектация!AA16,Комплектация!AB16)-Параметры!$B$15<Параметры!$B$16,1,0)+IF(MIN(Комплектация!AK16,Комплектация!AL16)-Параметры!$B$15<Параметры!$B$16,1,0)+IF(MIN(Комплектация!AU16,Комплектация!AV16)-Параметры!$B$15<Параметры!$B$16,1,0)+IF(MIN(Комплектация!BE16,Комплектация!BF16)-Параметры!$B$15<Параметры!$B$16,1,0) | Z14: =Y14*Параметры!$B$19 | AA14: =MAX(0,P14-X14-Z14) | AB14: =SUMIFS(Прайс!$D$3:$D$11,Прайс!$A$3:$A$11,B14,Прайс!$B$3:$B$11,C14) | AC14: =IF(AB14="","",AB14-AA14) | AD14: 3161618.2
... A168: =Комплектация!A170 | B168: =Комплектация!C170 | C168: =Комплектация!E170 | D168: 2043 | E168: =IF(D168="",Параметры!$B$11,MAX(1,D168-C168)) | F168: =MAX(0,YEAR(Параметры!$B$2)-C168) | G168: =MIN(100,F168/E168*100) | H168: =100-G168 | I168: =AVERAGE(Комплектация!BJ170,Комплектация!BP170,Комплектация!BV170,Комплектация!CB170,Комплектация!CH170,Комплектация!CN170) | J168: =MAX(0,YEAR(Параметры!$B$2)-I168) | K168: =MIN(100,J168/Параметры!$B$12*100) | L168: =100-K168 | M168: =MIN(Комплектация!AA170,Комплектация!AB170,Комплектация!AK170,Комплектация!AL170,Комплектация!AU170,Комплектация!AV170,Комплектация!BE170,Комплектация!BF170) | N168: =AVERAGE((100-MAX(0,MIN(100,(Параметры!$B$13-MIN(Комплектация!AA170,Комплектация!AB170))/(Параметры!$B$13-Параметры!$B$14)*100))),(100-MAX(0,MIN(100,(Параметры!$B$13-MIN(Комплектация!AK170,Комплектация!AL170))/(Параметры!$B$13-Параметры!$B$14)*100))),(100-MAX(0,MIN(100,(Параметры!$B$13-MIN(Комплектация!AU170,Комплектация!AV170))/(Параметры!$B$13-Параметры!$B$14)*100))),(100-MAX(0,MIN(100,(Параметры!$B$13-MIN(Комплектация!BE170,Комплектация!BF170))/(Параметры!$B$13-Параметры!$B$14)*100)))) | O168: =AVERAGE(H168,L168) | P168: =Параметры!$B$3*(Параметры!$B$5*H168+Параметры!$B$6*L168+Параметры!$B$7*N168+Параметры!$B$8*O168)/100 | Q168: 45954 | R168: 46684 | S168: =IF(OR(Q168="",R168="",R168=Q168),"",MAX(0,MIN(100,(Параметры!$B$2-Q168)/(R168-Q168)*100))) | T168: =IF(ISNUMBER(Комплектация!P170),Комплектация!P170,"") | U168: =IF(ISNUMBER(Комплектация!N170),Комплектация!N170,"") | V168: =IF(OR(U168="",T168="",U168=0),"",MAX(0,MIN(100,(U168-T168)/U168*100))) | W168: =MAX(IF(S168="",0,S168),IF(V168="",0,V168)) | X168: =Параметры!$B$18*W168/100 | Y168: =IF(MIN(Комплектация!AA170,Комплектация!AB170)-Параметры!$B$15<Параметры!$B$16,1,0)+IF(MIN(Комплектация!AK170,Комплектация!AL170)-Параметры!$B$15<Параметры!$B$16,1,0)+IF(MIN(Комплектация!AU170,Комплектация!AV170)-Параметры!$B$15<Параметры!$B$16,1,0)+IF(MIN(Комплектация!BE170,Комплектация!BF170)-Параметры!$B$15<Параметры!$B$16,1,0) | Z168: =Y168*Параметры!$B$19 | AA168: =MAX(0,P168-X168-Z168) | AB168: =SUMIFS(Прайс!$D$3:$D$11,Прайс!$A$3:$A$11,B168,Прайс!$B$3:$B$11,C168) | AC168: =IF(AB168="","",AB168-AA168) | AD168: 3221677.7

Sheet Свод
A1: Свод оценки — методика v2
A2: Компонентный затратный подход: стоимость = Σ(доля компонента × остаточная %) − обязательства по ремонтам.
A4: Показатель | B4: Значение | C4: Комментарий
A5: Количество вагонов | B5: =COUNT(Оценка!$AA$3:$AA$168) | C5: Оценённых по модели v2
A6: Средняя стоимость v2, ₽ | B6: =AVERAGE(Оценка!$AA$3:$AA$168) | C6: Итоговая с учётом обязательств
A7: Минимальная стоимость v2, ₽ | B7: =MIN(Оценка!$AA$3:$AA$168)
A8: Максимальная стоимость v2, ₽ | B8: =MAX(Оценка!$AA$3:$AA$168)
A9: Суммарная стоимость парка v2, ₽ | B9: =SUM(Оценка!$AA$3:$AA$168) | C9: Итог по 166 вагонам
A11: Средняя оценка v1 (справочно), ₽ | B11: =AVERAGE(Оценка!$AD$3:$AD$168) | C11: Из исходной модели (возраст+обод, 50/50)
A12: Разница средних v2 − v1, ₽ | B12: =AVERAGE(Оценка!$AA$3:$AA$168)-AVERAGE(Оценка!$AD$3:$AD$168) | C12: Влияние новой методики
A13: Разница средних v2 − v1, % | B13: =(AVERAGE(Оценка!$AA$3:$AA$168)-AVERAGE(Оценка!$AD$3:$AD$168))/AVERAGE(Оценка!$AD$3:$AD$168)*100
A15: Сравнение с ценой собственника | B15: Значение | C15: Комментарий
A16: Итого прайс собственника, ₽ | B16: =SUM(Оценка!$AB$3:$AB$168) | C16: Сумма запрошенных цен (без НДС), лист «Прайс»
A17: Итого оценка v2 (износ), ₽ | B17: =SUM(Оценка!$AA$3:$AA$168) | C17: Компонентная стоимость − обязательства
A18: Переоценка прайса к v2, ₽ | B18: =SUM(Оценка!$AB$3:$AB$168)-SUM(Оценка!$AA$3:$AA$168) | C18: Насколько прайс выше стоимости по износу
A19: Переоценка прайса к v2, % | B19: =(SUM(Оценка!$AB$3:$AB$168)-SUM(Оценка!$AA$3:$AA$168))/SUM(Оценка!$AA$3:$AA$168)*100 | C19: Прайс дороже оценки на столько
A20: Итого оценка v1 (справочно), ₽ | B20: =SUM(Оценка!$AD$3:$AD$168) | C20: Почти равна прайсу — v1, как и прайс, ценит по возрасту
A21: Вагонов: прайс ВЫШЕ оценки v2 (переоценены) | B21: =COUNTIF(Оценка!$AC$3:$AC$168,">0") | C21: Есть основание торговаться вниз
A22: Вагонов: прайс НИЖЕ оценки v2 (привлекательны) | B22: =COUNTIF(Оценка!$AC$3:$AC$168,"<0") | C22: Прайс уже ниже стоимости по состоянию
A24: Что изменено в методике v2 против v1:
A25: 1. Компонентная декомпозиция | C25: Котёл+рама / тележки(литьё) / КП / прочее вместо 50-на-50
A26: 2. Индивидуальный срок службы | C26: Износ котла — по дате СС из данных, не общий 32 г.
A27: 3. Литьё тележек как компонент | C27: Использованы годы боковых рам и надрессорных балок
A28: 4. Обод по полному диапазону | C28: Износ обода от новой (70 мм) до предела, а не в полосе 50→27
A29: 5. Пробег как ресурс | C29: Остаточный пробег включён в позицию обслуживания
A30: 6. ДР как обязательство в ₽ | C30: Стоимость предстоящего ремонта вычитается в рублях
A31: 7. Замена негодных КП в ₽ | C31: Негодные к обточке КП — вычет стоимости замены
A32: 8. Рыночная сверка | C32: Колонка «Цена продавца» для сравнения (затратный↔рыночный)
A34: Ограничения — требуют данных/уточнения:
A35: • Толщина гребня | C35: В источнике = 0 (не собрана). Добавить в износ КП после замера.
A36: • Доли компонентов и цены ремонтов | C36: Заданы как допущения на листе «Параметры» — заменить фактикой.
A37: • Состояние котла (коррозия, толщина стенки) | C37: Нет в данных; износ тела аппроксимирован сроком службы.
A38: • Единая цена новой для всех моделей | C38: 2020 г. (15-1219-1П, 69 тн) — премиальная модель; при единой цене новой её оценка занижена, переоценка прайса по ней завышена.
A39: • Функциональный / внешний износ | C39: Не учтён (тип цистерны, ставка аренды, регуляторные лимиты).
A41: Модель / год | B41: Кол-во | C41: Прайс ед., ₽ | D41: Оценка v2 ед., ₽ | E41: Δ прайс−v2, ₽ | F41: Δ, %
A42: 15-1219-1П · 2020 | B42: =COUNTIFS(Оценка!$B$3:$B$168,"15-1219-1П",Оценка!$C$3:$C$168,2020) | C42: =AVERAGEIFS(Оценка!$AB$3:$AB$168,Оценка!$B$3:$B$168,"15-1219-1П",Оценка!$C$3:$C$168,2020) | D42: =AVERAGEIFS(Оценка!$AA$3:$AA$168,Оценка!$B$3:$B$168,"15-1219-1П",Оценка!$C$3:$C$168,2020) | E42: =C42-D42 | F42: =IF(C42=0,0,(C42-D42)/C42*100)
A43: 15-150-04П · 2011 | B43: =COUNTIFS(Оценка!$B$3:$B$168,"15-150-04П",Оценка!$C$3:$C$168,2011) | C43: =AVERAGEIFS(Оценка!$AB$3:$AB$168,Оценка!$B$3:$B$168,"15-150-04П",Оценка!$C$3:$C$168,2011) | D43: =AVERAGEIFS(Оценка!$AA$3:$AA$168,Оценка!$B$3:$B$168,"15-150-04П",Оценка!$C$3:$C$168,2011) | E43: =C43-D43 | F43: =IF(C43=0,0,(C43-D43)/C43*100)
A44: 15-150-04П · 2012 | B44: =COUNTIFS(Оценка!$B$3:$B$168,"15-150-04П",Оценка!$C$3:$C$168,2012) | C44: =AVERAGEIFS(Оценка!$AB$3:$AB$168,Оценка!$B$3:$B$168,"15-150-04П",Оценка!$C$3:$C$168,2012) | D44: =AVERAGEIFS(Оценка!$AA$3:$AA$168,Оценка!$B$3:$B$168,"15-150-04П",Оценка!$C$3:$C$168,2012) | E44: =C44-D44 | F44: =IF(C44=0,0,(C44-D44)/C44*100)
A45: 15-150-04П · 2015 | B45: =COUNTIFS(Оценка!$B$3:$B$168,"15-150-04П",Оценка!$C$3:$C$168,2015) | C45: =AVERAGEIFS(Оценка!$AB$3:$AB$168,Оценка!$B$3:$B$168,"15-150-04П",Оценка!$C$3:$C$168,2015) | D45: =AVERAGEIFS(Оценка!$AA$3:$AA$168,Оценка!$B$3:$B$168,"15-150-04П",Оценка!$C$3:$C$168,2015) | E45: =C45-D45 | F45: =IF(C45=0,0,(C45-D45)/C45*100)
A46: 15-1755П · 2013 | B46: =COUNTIFS(Оценка!$B$3:$B$168,"15-1755П",Оценка!$C$3:$C$168,2013) | C46: =AVERAGEIFS(Оценка!$AB$3:$AB$168,Оценка!$B$3:$B$168,"15-1755П",Оценка!$C$3:$C$168,2013) | D46: =AVERAGEIFS(Оценка!$AA$3:$AA$168,Оценка!$B$3:$B$168,"15-1755П",Оценка!$C$3:$C$168,2013) | E46: =C46-D46 | F46: =IF(C46=0,0,(C46-D46)/C46*100)
...

Sheet Комплектация
A1: Номер вагона / контейнера | B1: Род вагона | C1: Модель | D1: Дата постройки | E1: Год постройки | F1: Срок службы | G1: Дата последнего деповского ремонта | H1: Депопоследнего деповского ремонта | I1: Дата капитального | J1: Депо капитального | K1: Очередной вид ремонта | L1: Дата очередного плановго ремонта | M1: Собственник | N1: Норма пробега | O1: Пробег общий | P1: Остаточный пробег | Q1: Дата ремонта по пробегу | R1: Дата изменения комплектации | T1: Колесная пара 1 | AD1: Колесная пара 2 | AN1: Колесная пара 3 | AX1: Колесная пара 4 | BH1: Надрессорная балка 1 | BN1: Надрессорная балка 2 | BT1: Боковая рама 1 | BZ1: Боковая рама 2 | CF1: Боковая рама 3 | CL1: Боковая рама 4
T2: Номер детали | U2: Клеймо | V2: Год постр | W2: Депо | X2: Дата | Y2: Толщина гребня | AA2: Толщина обода | AD2: Номер детали | AE2: Клеймо | AF2: Год постр | AG2: Депо | AH2: Дата | AI2: Толщина гребня | AK2: Толщина обода | AN2: Номер детали | AO2: Клеймо | AP2: Год постр | AQ2: Депо | AR2: Дата | AS2: Толщина гребня | AU2: Толщина обода | AX2: Номер детали | AY2: Клеймо | AZ2: Год постр | BA2: Депо | BB2: Дата | BC2: Толщина гребня | BE2: Толщина обода | BH2: Номер детали | BI2: Клеймо | BJ2: Год постр | BK2: Депо | BL2: Дата | BN2: Номер детали | BO2: Клеймо | BP2: Год постр | BQ2: Депо | BR2: Дата | BT2: Номер детали | BU2: Клеймо | BV2: Год постр | BW2: Депо | BX2: Дата | BZ2: Номер детали | CA2: Клеймо | CB2: Год постр | CC2: Депо | CD2: Дата | CF2: Номер детали | CG2: Клеймо | CH2: Год постр | CI2: Депо | CJ2: Дата | CL2: Номер детали | CM2: Клеймо | CN2: Год постр | CO2: Депо | CP2: Дата
Y3: ЛЕВ. | Z3: ПРАВ. | AA3: ЛЕВ. | AB3: ПРАВ. | AI3: ЛЕВ. | AJ3: ПРАВ. | AK3: ЛЕВ. | AL3: ПРАВ. | AS3: ЛЕВ. | AT3: ПРАВ. | AU3: ЛЕВ. | AV3: ПРАВ. | BC3: ЛЕВ. | BD3: ПРАВ. | BE3: ЛЕВ. | BF3: ПРАВ.
A5: 77223766 | B5: Цистерна для перевозки продуктов | C5: 15-5103-7П | D5: 12.09.2011 | E5: 2011 | F5: 12.09.2043 | G5: 31.03.2023 | H5: ВРД Кочетовка – филиал ООО "НВК" | I5: 18.03.2026 | J5: Усть-Каменогорское ВРД | K5: Деповской | L5: 18.03.2029 | M5: ООО "ТрансАльянс Запад" | N5: 160000 | O5: 7663 | P5: 152337 | Q5: 11.07.2033 | R5: 18.03.2026 | T5: 107741 | U5: 0005 | V5: 2005 | W5: 745 | X5: мар.26 | Y5: 0 | Z5: 0 | AA5: 73 | AB5: 73 | AD5: 52282 | AE5: 1175 | AF5: 2012 | AG5: 745 | AH5: мар.26 | AI5: 0 | AJ5: 0 | AK5: 71 | AL5: 71 | AN5: 750688 | AO5: 0005 | AP5: 2017 | AQ5: 745 | AR5: мар.26 | AS5: 0 | AT5: 0 | AU5: 73 | AV5: 73 | AX5: 812280 | AY5: 0005 | AZ5: 2018 | BA5: 745 | BB5: мар.26 | BC5: 0 | BD5: 0 | BE5: 74 | BF5: 74 | BH5: 69894 | BI5: 0014 | BJ5: 2011 | BN5: 66505 | BO5: 0014 | BP5: 2011 | BT5: 117185 | BU5: 0014 | BV5: 2011 | BZ5: 117258 | CA5: 0014 | CB5: 2011 | CF5: 116917 | CG5: 0014 | CH5: 2011 | CL5: 117136 | CM5: 0014 | CN5: 2011
A6: 77206126 | B6: Цистерна для перевозки продуктов | C6: 15-1755П | D6: 20.06.2013 | E6: 2013 | F6: 20.06.2043 | G6: 12.02.2026 | H6: Усть-Каменогорское ВРД | I6: 02.02.2024 | J6: ВЧД Унеча-ООО "НВК" | K6: Деповской | L6: 12.02.2028 | M6: ООО "ТрансАльянс Запад" | N6: 160000 | O6: 20933 | P6: 139067 | Q6: 04.07.2029 | R6: 12.02.2026 | T6: 107656 | U6: 0005 | V6: 2014 | W6: 745 | X6: фев.26 | Y6: 0 | Z6: 0 | AA6: 72 | AB6: 72 | AD6: 227365 | AE6: 0005 | AF6: 2019 | AG6: 745 | AH6: фев.26 | AI6: 0 | AJ6: 0 | AK6: 72 | AL6: 72 | AN6: 16504 | AO6: 1175 | AP6: 2008 | AQ6: 745 | AR6: фев.26 | AS6: 0 | AT6: 0 | AU6: 74 | AV6: 74 | AX6: 844904 | AY6: 0029 | AZ6: 1990 | BA6: 745 | BB6: фев.26 | BC6: 0 | BD6: 0 | BE6: 72 | BF6: 72 | BH6: 15188 | BI6: 1291 | BJ6: 2013 | BN6: 15246 | BO6: 1291 | BP6: 2013 | BT6: 42930 | BU6: 1291 | BV6: 2013 | BZ6: 42424 | CA6: 1291 | CB6: 2013 | CF6: 38356 | CG6: 1291 | CH6: 2013 | CL6: 43316 | CM6: 1291 | CN6: 2013
A7: 77205912 | B7: Цистерна для перевозки продуктов | C7: 15-1755П | D7: 20.06.2013 | E7: 2013 | F7: 20.06.2043 | G7: 12.02.2026 | H7: Усть-Каменогорское ВРД | I7: 08.02.2024 | J7: ВРД Кочетовка – филиал ООО "НВК" | K7: Деповской | L7: 12.02.2028 | M7: ООО "ТрансАльянс Запад" | N7: 160000 | O7: 15958 | P7: 144042 | Q7: 25.07.2030 | R7: 15.06.2026 | T7: 392521 | U7: 0029 | V7: 2013 | W7: 4036 | X7: июнь.26 | Y7: 0 | Z7: 0 | AA7: 38 | AB7: 38 | AD7: 370222 | AE7: 0029 | AF7: 2012 | AG7: 4036 | AH7: июнь.26 | AI7: 0 | AJ7: 0 | AK7: 38 | AL7: 38 | AN7: 459384 | AO7: 0029 | AP7: 2013 | AQ7: 4036 | AR7: июнь.26 | AS7: 0 | AT7: 0 | AU7: 32 | AV7: 32 | AX7: 460013 | AY7: 0029 | AZ7: 2013 | BA7: 4036 | BB7: июнь.26 | BC7: 0 | BD7: 0 | BE7: 37 | BF7: 37 | BH7: 15648 | BI7: 1291 | BJ7: 2013 | BN7: 15896 | BO7: 1291 | BP7: 2013 | BT7: 46279 | BU7: 1291 | BV7: 2013 | BZ7: 45962 | CA7: 1291 | CB7: 2013 | CF7: 37854 | CG7: 1291 | CH7: 2013 | CL7: 45456 | CM7: 1291 | CN7: 2013
A8: 77206159 | B8: Цистерна для перевозки продуктов | C8: 15-1755П | D8: 20.06.2013 | E8: 2013 | F8: 20.06.2043 | G8: 12.02.2026 | H8: Усть-Каменогорское ВРД | I8: 05.02.2024 | J8: ТОО "Аждар и К" | K8: Деповской | L8: 12.02.2028 | M8: ООО "ТрансАльянс Запад" | N8: 160000 | O8: 15958 | P8: 144042 | Q8: 25.07.2030 | R8: 15.06.2026 | T8: 3029 | U8: 1175 | V8: 2011 | W8: 4036 | X8: июнь.26 | Y8: 0 | Z8: 0 | AA8: 75 | AB8: 75 | AD8: 884003 | AE8: 0029 | AF8: 2010 | AG8: 4036 | AH8: июнь.26 | AI8: 0 | AJ8: 0 | AK8: 75 | AL8: 75 | AN8: 134498 | AO8: 0005 | AP8: 2010 | AQ8: 4036 | AR8: июнь.26 | AS8: 0 | AT8: 0 | AU8: 66 | AV8: 66 | AX8: 696276 | AY8: 0029 | AZ8: 2008 | BA8: 4036 | BB8: июнь.26 | BC8: 0 | BD8: 0 | BE8: 75 | BF8: 75 | BH8: 15682 | BI8: 1291 | BJ8: 2013 | BN8: 52443 | BO8: 1291 | BP8: 2013 | BT8: 42733 | BU8: 1291 | BV8: 2013 | BZ8: 45183 | CA8: 1291 | CB8: 2013 | CF8: 42604 | CG8: 1291 | CH8: 2013 | CL8: 46047 | CM8: 1291 | CN8: 2013
A9: 77222149 | B9: Цистерна для перевозки продуктов | C9: 15-1755П | D9: 16.04.2014 | E9: 2014 | F9: 16.04.2044 | G9: 16.04.2023 | H9: ТОО "Аждар и К" | I9: 15.03.2025 | J9: ВРД Кочетовка – филиал ООО "НВК" | K9: Деповской | L9: 15.03.2027 | M9: ООО "ТрансАльянс Запад" | N9: 160000 | O9: 45837 | P9: 114163 | Q9: 10.12.2029 | R9: 15.03.2025 | T9: 444025 | U9: 0029 | V9: 2013 | W9: 301 | X9: мар.25 | Y9: 33 | Z9: 33 | AA9: 75 | AB9: 75 | AD9: 458607 | AE9: 0029 | AF9: 2013 | AG9: 301 | AH9: мар.25 | AI9: 33 | AJ9: 33 | AK9: 75 | AL9: 75 | AN9: 523344 | AO9: 0029 | AP9: 2014 | AQ9: 301 | AR9: мар.25 | AS9: 33 | AT9: 33 | AU9: 75 | AV9: 75 | AX9: 523382 | AY9: 0029 | AZ9: 2014 | BA9: 301 | BB9: мар.25 | BC9: 33 | BD9: 33 | BE9: 75 | BF9: 75 | BH9: 50753 | BI9: 1291 | BJ9: 2014 | BN9: 50876 | BO9: 1291 | BP9: 2014 | BT9: 3954 | BU9: 1291 | BV9: 2014 | BZ9: 3946 | CA9: 1291 | CB9: 2014 | CF9: 4551 | CG9: 1291 | CH9: 2014 | CL9: 3969 | CM9: 1291 | CN9: 2014
A10: 77222214 | B10: Цистерна для перевозки продуктов | C10: 15-1755П | D10: 16.04.2014 | E10: 2014 | F10: 16.04.2044 | G10: 22.03.2023 | H10: ВРД Кочетовка – филиал ООО "НВК" | I10: 03.04.2025 | J10: ВРД Кочетовка – филиал ООО "НВК" | K10: Деповской | L10: 03.04.2027 | M10: ООО "ТрансАльянс Запад" | N10: 160000 | O10: 48240 | P10: 111760 | Q10: 02.08.2029 | R10: 16.03.2026 | T10: 516474 | U10: 0029 | V10: 2013 | W10: 4046 | X10: мар.26 | Y10: 0 | Z10: 0 | AA10: 75 | AB10: 75 | AD10: 516476 | AE10: 0029 | AF10: 2013 | AG10: 4046 | AH10: мар.26 | AI10: 0 | AJ10: 0 | AK10: 75 | AL10: 75 | AN10: 523018 | AO10: 0029 | AP10: 2014 | AQ10: 4046 | AR10: мар.26 | AS10: 0 | AT10: 0 | AU10: 75 | AV10: 75 | AX10: 522934 | AY10: 0029 | AZ10: 2014 | BA10: 4046 | BB10: мар.26 | BC10: 0 | BD10: 0 | BE10: 75 | BF10: 75 | BH10: 51520 | BI10: 1291 | BJ10: 2014 | BN10: 51484 | BO10: 1291 | BP10: 2014 | BT10: 3898 | BU10: 1291 | BV10: 2014 | BZ10: 3949 | CA10: 1291 | CB10: 2014 | CF10: 403 | CG10: 1291 | CH10: 2014 | CL10: 2470 | CM10: 1291 | CN10: 2014
A11: 77206076 | B11: Цистерна для перевозки продуктов | C11: 15-1755П | D11: 20.06.2013 | E11: 2013 | F11: 20.06.2043 | G11: 14.02.2026 | H11: Усть-Каменогорское ВРД | I11: 04.02.2024 | J11: ТОО "Аждар и К" | K11: Деповской | L11: 14.02.2028 | M11: ООО "ТрансАльянс Запад" | N11: 160000 | O11: 15959 | P11: 144041 | Q11: 07.07.2030 | R11: 14.02.2026 | T11: 17411 | U11: 0039 | V11: 2005 | W11: 745 | X11: фев.26 | Y11: 0 | Z11: 0 | AA11: 75 | AB11: 75 | AD11: 61059 | AE11: 1175 | AF11: 2013 | AG11: 745 | AH11: фев.26 | AI11: 0 | AJ11: 0 | AK11: 72 | AL11: 72 | AN11: 27784 | AO11: 1175 | AP11: 2007 | AQ11: 745 | AR11: фев.26 | AS11: 0 | AT11: 0 | AU11: 71 | AV11: 71 | AX11: 61686 | AY11: 0039 | AZ11: 2010 | BA11: 745 | BB11: фев.26 | BC11: 0 | BD11: 0 | BE11: 70 | BF11: 70 | BH11: 14096 | BI11: 1291 | BJ11: 2013 | BN11: 13922 | BO11: 1291 | BP11: 2013 | BT11: 41746 | BU11: 1291 | BV11: 2013 | BZ11: 41214 | CA11: 1291 | CB11: 2013 | CF11: 42087 | CG11: 1291 | CH11: 2013 | CL11: 41710 | CM11: 1291 | CN11: 2013
A12: 77228781 | B12: Цистерна для перевозки продуктов | C12: 15-5103-7П | D12: 19.01.2015 | E12: 2015 | F12: 19.01.2047 | G12: 20.08.2025 | H12: Орский ВРЗ-филиал ООО "НВК" | K12: Капитальный | L12: 20.08.2028 | M12: ООО "ТрансАльянс Запад" | N12: 160000 | O12: 45251 | P12: 114749 | Q12: 27.11.2028 | R12: 20.08.2025 | T12: 881967 | U12: 0029 | V12: 2010 | W12: 2348 | X12: авг.25 | Y12: 30 | Z12: 30 | AA12: 60 | AB12: 60 | AD12: 133082 | AE12: 0005 | AF12: 2014 | AG12: 2348 | AH12: авг.25 | AI12: 30 | AJ12: 30 | AK12: 60 | AL12: 60 | AN12: 132197 | AO12: 0005 | AP12: 2014 | AQ12: 2348 | AR12: авг.25 | AS12: 30 | AT12: 30 | AU12: 58 | AV12: 58 | AX12: 389220 | AY12: 0005 | AZ12: 2013 | BA12: 2348 | BB12: авг.25 | BC12: 30 | BD12: 30 | BE12: 59 | BF12: 58 | BH12: 34861 | BI12: 0005 | BJ12: 2014 | BN12: 35626 | BO12: 0005 | BP12: 2014 | BT12: 920 | BU12: 0005 | BV12: 2015 | BZ12: 1398 | CA12: 0005 | CB12: 2015 | CF12: 1466 | CG12: 0005 | CH12: 2015 | CL12: 1898 | CM12: 0005 | CN12: 2015
A13: 77221810 | B13: Цистерна для перевозки продуктов | C13: 15-5103-7П | D13: 06.09.2011 | E13: 2011 | F13: 06.09.2043 | G13: 21.12.2022 | H13: ВЧДР Ульяновск – ОСП АО "ОМК Стальной путь" | I13: 21.08.2025 | J13: ВРЗ Челябинск – филиал ООО "НВК" | K13: Деповской | L13: 21.08.2028 | M13: ООО "ТрансАльянс Запад" | N13: 160000 | O13: 36954 | P13: 123046 | Q13: 19.08.2029 | R13: 21.08.2025 | T13: 387818 | U13: 0005 | V13: 2013 | W13: 600 | X13: авг.25 | Y13: 33 | Z13: 33 | AA13: 71 | AB13: 70 | AD13: 285936 | AE13: 0005 | AF13: 2011 | AG13: 600 | AH13: авг.25 | AI13: 33 | AJ13: 33 | AK13: 74 | AL13: 74 | AN13: 144857 | AO13: 0005 | AP13: 2014 | AQ13: 600 | AR13: авг.25 | AS13: 33 | AT13: 33 | AU13: 71 | AV13: 71 | AX13: 285133 | AY13: 0005 | AZ13: 2011 | BA13: 600 | BB13: авг.25 | BC13: 33 | BD13: 33 | BE13: 73 | BF13: 73 | BH13: 38533 | BI13: 0005 | BJ13: 2011 | BN13: 38400 | BO13: 0005 | BP13: 2011 | BT13: 64559 | BU13: 0005 | BV13: 2011 | BZ13: 67459 | CA13: 0005 | CB13: 2011 | CF13: 67635 | CG13: 0005 | CH13: 2011 | CL13: 66238 | CM13: 0005 | CN13: 2011
A14: 77228724 | B14: Цистерна для перевозки продуктов | C14: 15-5103-7П | D14: 19.01.2015 | E14: 2015 | F14: 19.01.2047 | G14: 20.08.2025 | H14: Орский ВРЗ-филиал ООО "НВК" | K14: Капитальный | L14: 20.08.2028 | M14: ООО "ТрансАльянс Запад" | N14: 160000 | O14: 36244 | P14: 123756 | Q14: 20.09.2029 | R14: 20.08.2025 | T14: 300837 | U14: 0005 | V14: 2015 | W14: 2348 | X14: авг.25 | Y14: 30 | Z14: 30 | AA14: 47 | AB14: 47 | AD14: 303165 | AE14: 0005 | AF14: 2015 | AG14: 2348 | AH14: авг.25 | AI14: 30 | AJ14: 30 | AK14: 43 | AL14: 43 | AN14: 301420 | AO14: 0005 | AP14: 2015 | AQ14: 2348 | AR14: авг.25 | AS14: 30 | AT14: 30 | AU14: 41 | AV14: 41 | AX14: 207759 | AY14: 0005 | AZ14: 2014 | BA14: 2348 | BB14: авг.25 | BC14: 30 | BD14: 30 | BE14: 42 | BF14: 42 | BH14: 35428 | BI14: 0005 | BJ14: 2014 | BN14: 35655 | BO14: 0005 | BP14: 2014 | BT14: 2572 | BU14: 0005 | BV14: 2015 | BZ14: 1213 | CA14: 0005 | CB14: 2015 | CF14: 1582 | CG14: 0005 | CH14: 2015 | CL14: 1625 | CM14: 0005 | CN14: 2015
A15: 77222040 | B15: Цистерна для перевозки продуктов | C15: 15-150-04П | D15: 31.08.2011 | E15: 2011 | F15: 31.08.2043 | G15: 19.01.2023 | H15: ВРД Кочетовка – филиал ООО "НВК" | I15: 22.08.2025 | J15: ВРЗ Челябинск – филиал ООО "НВК" | K15: Деповской | L15: 22.08.2028 | M15: ООО "ТрансАльянс Запад" | N15: 160000 | O15: 36020 | P15: 123980 | Q15: 23.09.2029 | R15: 22.08.2025 | T15: 361758 | U15: 0005 | V15: 2013 | W15: 600 | X15: авг.25 | Y15: 29 | Z15: 29 | AA15: 64 | AB15: 63 | AD15: 283089 | AE15: 0005 | AF15: 2011 | AG15: 600 | AH15: авг.25 | AI15: 29 | AJ15: 29 | AK15: 66 | AL15: 67 | AN15: 361783 | AO15: 0005 | AP15: 2013 | AQ15: 600 | AR15: авг.25 | AS15: 29 | AT15: 29 | AU15: 67 | AV15: 67 | AX15: 178288 | AY15: 0005 | AZ15: 2014 | BA15: 600 | BB15: авг.25 | BC15: 29 | BD15: 29 | BE15: 68 | BF15: 68 | BH15: 37526 | BI15: 0005 | BJ15: 2011 | BN15: 36840 | BO15: 0005 | BP15: 2011 | BT15: 65174 | BU15: 0005 | BV15: 2011 | BZ15: 64960 | CA15: 0005 | CB15: 2011 | CF15: 66375 | CG15: 0005 | CH15: 2011 | CL15: 66315 | CM15: 0005 | CN15: 2011
A16: 77227080 | B16: Цистерна для перевозки продуктов | C16: 15-5103-7П | D16: 19.01.2012 | E16: 2012 | F16: 19.01.2044 | G16: 29.09.2022 | H16: ВЧД Унеча-ООО "НВК" | I16: 23.09.2025 | J16: ВРЗ Челябинск – филиал ООО "НВК" | K16: Деповской | L16: 23.09.2028 | M16: ООО "ТрансАльянс Запад" | N16: 160000 | O16: 42876 | P16: 117124 | Q16: 31.10.2028 | R16: 23.09.2025 | T16: 122882 | U16: 0005 | V16: 2012 | W16: 600 | X16: сен.25 | Y16: 29 | Z16: 29 | AA16: 71 | AB16: 71 | AD16: 123143 | AE16: 0005 | AF16: 2012 | AG16: 600 | AH16: сен.25 | AI16: 29 | AJ16: 29 | AK16: 71 | AL16: 71 | AN16: 305740 | AO16: 0005 | AP16: 2011 | AQ16: 600 | AR16: сен.25 | AS16: 29 | AT16: 29 | AU16: 72 | AV16: 71 | AX16: 315082 | AY16: 0005 | AZ16: 2011 | BA16: 600 | BB16: сен.25 | BC16: 29 | BD16: 29 | BE16: 72 | BF16: 73 | BH16: 49779 | BI16: 0005 | BJ16: 2011 | BN16: 3063 | BO16: 0005 | BP16: 2012 | BT16: 88660 | BU16: 0005 | BV16: 2011 | BZ16: 86578 | CA16: 0005 | CB16: 2011 | CF16: 95277 | CG16: 0005 | CH16: 2012 | CL16: 5895 | CM16: 0005 | CN16: 2012
A17: 77228773 | B17: Цистерна для перевозки продуктов | C17: 15-5103-7П | D17: 19.01.2015 | E17: 2015 | F17: 19.01.2047 | G17: 24.08.2025 | H17: Орский ВРЗ-филиал ООО "НВК" | K17: Капитальный | L17: 24.08.2028 | M17: ООО "ТрансАльянс Запад" | N17: 160000 | O17: 39135 | P17: 120865 | Q17: 21.05.2029 | R17: 24.08.2025 | T17: 975384 | U17: 0029 | V17: 2011 | W17: 2348 | X17: авг.25 | Y17: 30 | Z17: 30 | AA17: 53 | AB17: 51 | AD17: 26652 | AE17: 0039 | AF17: 2006 | AG17: 2348 | AH17: авг.25 | AI17: 30 | AJ17: 30 | AK17: 56 | AL17: 55 | AN17: 861974 | AO17: 0029 | AP17: 1990 | AQ17: 2348 | AR17: авг.25 | AS17: 30 | AT17: 30 | AU17: 58 | AV17: 58 | AX17: 108425 | AY17: 0005 | AZ17: 2006 | BA17: 2348 | BB17: авг.25 | BC17: 30 | BD17: 30 | BE17: 58 | BF17: 57 | BH17: 35195 | BI17: 0005 | BJ17: 2014 | BN17: 34646 | BO17: 0005 | BP17: 2014 | BT17: 69675 | BU17: 0005 | BV17: 2014 | BZ17: 69237 | CA17: 0005 | CB17: 2014 | CF17: 69365 | CG17: 0005 | CH17: 2014 | CL17: 69725 | CM17: 0005 | CN17: 2014
A18: 77221950 | B18: Цистерна для перевозки продуктов | C18: 15-150-04П | D18: 28.02.2012 | E18: 2012 | F18: 28.02.2044 | G18: 19.09.2022 | H18: ВРД Кочетовка – филиал ООО "НВК" | I18: 21.08.2025 | J18: ВРЗ Челябинск – филиал ООО "НВК" | K18: Деповской | L18: 21.08.2028 | M18: ООО "ТрансАльянс Запад" | N18: 160000 | O18: 34259 | P18: 125741 | Q18: 12.12.2029 | R18: 21.08.2025 | T18: 170868 | U18: 0005 | V18: 2007 | W18: 600 | X18: авг.25 | Y18: 33 | Z18: 33 | AA18: 73 | AB18: 73 | AD18: 151700 | AE18: 0029 | AF18: 1992 | AG18: 600 | AH18: авг.25 | AI18: 33 | AJ18: 33 | AK18: 74 | AL18: 74 | AN18: 122486 | AO18: 0005 | AP18: 2012 | AQ18: 600 | AR18: авг.25 | AS18: 33 | AT18: 33 | AU18: 74 | AV18: 74 | AX18: 123286 | AY18: 0005 | AZ18: 2012 | BA18: 600 | BB18: авг.25 | BC18: 33 | BD18: 33 | BE18: 74 | BF18: 73 | BH18: 10219 | BI18: 0014 | BJ18: 2012 | BN18: 3246 | BO18: 0014 | BP18: 2012 | BT18: 10126 | BU18: 0014 | BV18: 2012 | BZ18: 504892 | CA18: 0014 | CB18: 2012 | CF18: 14196 | CG18: 0014 | CH18: 2012 | CL18: 306 | CM18: 0014 | CN18: 2012
A19: 77205664 | B19: Цистерна для перевозки продуктов | C19: 15-1755П | D19: 20.06.2013 | E19: 2013 | F19: 20.06.2043 | G19: 29.08.2025 | H19: Орский ВРЗ-филиал ООО "НВК" | I19: 27.01.2024 | J19: ВРЗ Челябинск – филиал ООО "НВК" | K19: Деповской | L19: 29.08.2027 | M19: ООО "ТрансАльянс Запад" | N19: 160000 | O19: 35111 | P19: 124889 | Q19: 06.10.2029 | R19: 29.08.2025 | T19: 442976 | U19: 0029 | V19: 2013 | W19: 2348 | X19: авг.25 | Y19: 33 | Z19: 33 | AA19: 74 | AB19: 74 | AD19: 459729 | AE19: 0029 | AF19: 2013 | AG19: 2348 | AH19: авг.25 | AI19: 33 | AJ19: 33 | AK19: 74 | AL19: 74 | AN19: 459998 | AO19: 0029 | AP19: 2013 | AQ19: 2348 | AR19: авг.25 | AS19: 33 | AT19: 33 | AU19: 74 | AV19: 74 | AX19: 459372 | AY19: 0029 | AZ19: 2013 | BA19: 2348 | BB19: авг.25 | BC19: 33 | BD19: 33 | BE19: 74 | BF19: 74 | BH19: 52104 | BI19: 1291 | BJ19: 2013 | BN19: 14349 | BO19: 1291 | BP19: 2013 | BT19: 37899 | BU19: 1291 | BV19: 2013 | BZ19: 38264 | CA19: 1291 | CB19: 2013 | CF19: 42407 | CG19: 1291 | CH19: 2013 | CL19: 42444 | CM19: 1291 | CN19: 2013
A20: 77205706 | B20: Цистерна для перевозки продуктов | C20: 15-1755П | D20: 20.06.2013 | E20: 2013 | F20: 20.06.2043 | G20: 06.09.2025 | H20: Орский ВРЗ-филиал ООО "НВК" | I20: 17.01.2024 | J20: ВЧД Унеча-ООО "НВК" | K20: Деповской | L20: 06.09.2027 | M20: ООО "ТрансАльянс Запад" | N20: 160000 | O20: 36116 | P20: 123884 | Q20: 29.07.2029 | R20: 06.09.2025 | T20: 369126 | U20: 0029 | V20: 2012 | W20: 2348 | X20: сен.25 | Y20: 30 | Z20: 30 | AA20: 55 | AB20: 55 | AD20: 51638 | AE20: 2412 | AF20: 2024 | AG20: 2348 | AH20: сен.25 | AI20: 30 | AJ20: 30 | AK20: 54 | AL20: 54 | AN20: 325321 | AO20: 0029 | AP20: 2012 | AQ20: 2348 | AR20: сен.25 | AS20: 30 | AT20: 30 | AU20: 48 | AV20: 48 | AX20: 308575 | AY20: 0029 | AZ20: 2012 | BA20: 2348 | BB20: сен.25 | BC20: 30 | BD20: 30 | BE20: 51 | BF20: 51 | BH20: 14317 | BI20: 1291 | BJ20: 2013 | BN20: 14674 | BO20: 1291 | BP20: 2013 | BT20: 42624 | BU20: 1291 | BV20: 2013 | BZ20: 40631 | CA20: 1291 | CB20: 2013 | CF20: 44747 | CG20: 1291 | CH20: 2013 | CL20: 44767 | CM20: 1291 | CN20: 2013
A21: 77205888 | B21: Цистерна для перевозки продуктов | C21: 15-1755П | D21: 20.06.2013 | E21: 2013 | F21: 20.06.2043 | G21: 24.08.2025 | H21: Орский ВРЗ-филиал ООО "НВК" | I21: 31.01.2024 | J21: ВРД Кочетовка – филиал ООО "НВК" | K21: Деповской | L21: 24.08.2027 | M21: ООО "ТрансАльянс Запад" | N21: 160000 | O21: 31425 | P21: 128575 | Q21: 21.04.2030 | R21: 24.08.2025 | T21: 444796 | U21: 0029 | V21: 2013 | W21: 2348 | X21: авг.25 | Y21: 30 | Z21: 30 | AA21: 62 | AB21: 61 | AD21: 443687 | AE21: 0029 | AF21: 2013 | AG21: 2348 | AH21: авг.25 | AI21: 30 | AJ21: 30 | AK21: 63 | AL21: 63 | AN21: 443345 | AO21: 0029 | AP21: 2013 | AQ21: 2348 | AR21: авг.25 | AS21: 30 | AT21: 30 | AU21: 59 | AV21: 59 | AX21: 455903 | AY21: 0029 | AZ21: 2013 | BA21: 2348 | BB21: авг.25 | BC21: 30 | BD21: 30 | BE21: 62 | BF21: 62 | BH21: 15045 | BI21: 1291 | BJ21: 2013 | BN21: 15233 | BO21: 1291 | BP21: 2013 | BT21: 44652 | BU21: 1291 | BV21: 2013 | BZ21: 44087 | CA21: 1291 | CB21: 2013 | CF21: 42795 | CG21: 1291 | CH21: 2013 | CL21: 42357 | CM21: 1291 | CN21: 2013
A22: 77221919 | B22: Цистерна для перевозки продуктов | C22: 15-5103-7П | D22: 06.09.2011 | E22: 2011 | F22: 06.09.2043 | G22: 20.02.2023 | H22: ВРД Кочетовка – филиал ООО "НВК" | I22: 02.02.2025 | J22: ВЧД Унеча-ООО "НВК" | K22: Деповской | L22: 02.02.2028 | M22: ООО "ТрансАльянс Запад" | N22: 160000 | O22: 45858 | P22: 114142 | Q22: 22.03.2030 | R22: 02.02.2025 | T22: 285774 | U22: 0005 | V22: 2011 | W22: 357 | X22: фев.25 | Y22: 33 | Z22: 33 | AA22: 74 | AB22: 74 | AD22: 285824 | AE22: 0005 | AF22: 2011 | AG22: 357 | AH22: фев.25 | AI22: 33 | AJ22: 33 | AK22: 73 | AL22: 73 | AN22: 180370 | AO22: 0005 | AP22: 2014 | AQ22: 357 | AR22: фев.25 | AS22: 33 | AT22: 33 | AU22: 73 | AV22: 73 | AX22: 286908 | AY22: 0005 | AZ22: 2011 | BA22: 357 | BB22: фев.25 | BC22: 33 | BD22: 33 | BE22: 73 | BF22: 73 | BH22: 38613 | BI22: 0005 | BJ22: 2011 | BN22: 38286 | BO22: 0005 | BP22: 2011 | BT22: 63621 | BU22: 0005 | BV22: 2011 | BZ22: 67432 | CA22: 0005 | CB22: 2011 | CF22: 67508 | CG22: 0005 | CH22: 2011 | CL22: 67584 | CM22: 0005 | CN22: 2011
A23: 77221844 | B23: Цистерна для перевозки продуктов | C23: 15-150-04П | D23: 31.08.2011 | E23: 2011 | F23: 31.08.2043 | G23: 18.02.2023 | H23: ВРД Кочетовка – филиал ООО "НВК" | I23: 26.03.2026 | J23: Усть-Каменогорское ВРД | K23: Деповской | L23: 26.03.2029 | M23: ООО "ТрансАльянс Запад" | N23: 160000 | O23: 8028 | P23: 151972 | Q23: 12.10.2032 | R23: 26.03.2026 | T23: 363178 | U23: 0005 | V23: 2013 | W23: 745 | X23: мар.26 | Y23: 0 | Z23: 0 | AA23: 73 | AB23: 73 | AD23: 285305 | AE23: 0005 | AF23: 2011 | AG23: 745 | AH23: мар.26 | AI23: 0 | AJ23: 0 | AK23: 73 | AL23: 73 | AN23: 282111 | AO23: 0005 | AP23: 2011 | AQ23: 745 | AR23: мар.26 | AS23: 0 | AT23: 0 | AU23: 72 | AV23: 72 | AX23: 285278 | AY23: 0005 | AZ23: 2011 | BA23: 745 | BB23: мар.26 | BC23: 0 | BD23: 0 | BE23: 73 | BF23: 73 | BH23: 37070 | BI23: 0005 | BJ23: 2011 | BN23: 37413 | BO23: 0005 | BP23: 2011 | BT23: 66136 | BU23: 0005 | BV23: 2011 | BZ23: 65255 | CA23: 0005 | CB23: 2011 | CF23: 66052 | CG23: 0005 | CH23: 2011 | CL23: 63648 | CM23: 0005 | CN23: 2011
A24: 75183491 | B24: Цистерна для перевозки продуктов | C24: 15-1219-1П | D24: 08.10.2020 | E24: 2020 | F24: 08.10.2050 | G24: 30.10.2025 | H24: ВРД Зелецино - филиал ООО "НВК" | K24: Деповской | L24: 30.10.2027 | M24: ООО "ТрансАльянс Запад" | N24: 160000 | O24: 25151 | P24: 134849 | Q24: 25.06.2030 | R24: 30.10.2025 | T24: 12278 | U24: 2002 | V24: 2020 | W24: 1173 | X24: окт.25 | Y24: 30 | Z24: 30 | AA24: 50 | AB24: 52 | AD24: 446185 | AE24: 0005 | AF24: 2020 | AG24: 1173 | AH24: окт.25 | AI24: 30 | AJ24: 30 | AK24: 43 | AL24: 45 | AN24: 446107 | AO24: 0005 | AP24: 2020 | AQ24: 1173 | AR24: окт.25 | AS24: 30 | AT24: 30 | AU24: 51 | AV24: 53 | AX24: 446117 | AY24: 0005 | AZ24: 2020 | BA24: 1173 | BB24: окт.25 | BC24: 30 | BD24: 29 | BE24: 53 | BF24: 55 | BH24: 27363 | BI24: 1275 | BJ24: 2020 | BN24: 27358 | BO24: 1275 | BP24: 2020 | BT24: 45585 | BU24: 1275 | BV24: 2020 | BZ24: 45569 | CA24: 1275 | CB24: 2020 | CF24: 41311 | CG24: 1275 | CH24: 2020 | CL24: 45586 | CM24: 1275 | CN24: 2020
A25: 75184093 | B25: Цистерна для перевозки продуктов | C25: 15-1219-1П | D25: 08.10.2020 | E25: 2020 | F25: 08.10.2050 | G25: 19.10.2025 | H25: ВРД Зелецино - филиал ООО "НВК" | K25: Деповской | L25: 19.10.2027 | M25: ООО "ТрансАльянс Запад" | N25: 160000 | O25: 26103 | P25: 133897 | Q25: 19.06.2030 | R25: 19.10.2025 | T25: 735030 | U25: 0029 | V25: 2020 | W25: 1173 | X25: окт.25 | Y25: 30 | Z25: 30 | AA25: 61 | AB25: 60 | AD25: 753604 | AE25: 0029 | AF25: 2020 | AG25: 1173 | AH25: окт.25 | AI25: 29 | AJ25: 29 | AK25: 59 | AL25: 61 | AN25: 448491 | AO25: 0005 | AP25: 2020 | AQ25: 1173 | AR25: окт.25 | AS25: 29 | AT25: 29 | AU25: 56 | AV25: 54 | AX25: 449053 | AY25: 0005 | AZ25: 2020 | BA25: 1173 | BB25: окт.25 | BC25: 29 | BD25: 30 | BE25: 61 | BF25: 62 | BH25: 27088 | BI25: 1275 | BJ25: 2020 | BN25: 27518 | BO25: 1275 | BP25: 2020 | BT25: 46122 | BU25: 1275 | BV25: 2020 | BZ25: 45988 | CA25: 1275 | CB25: 2020 | CF25: 44631 | CG25: 1275 | CH25: 2020 | CL25: 45967 | CM25: 1275 | CN25: 2020
