Workbook

Sheet Амортизация
A1: Оценка амортизации 166 цистерн
A2: Расчетная модель для предварительной оценки покупки. Желтые ячейки — изменяемые допущения.
A4: Параметр | B4: Значение | C4: Комментарий
A5: Дата оценки | B5: 46239 | C5: Фиксированная дата расчета
A6: Нормативный срок вагона, лет | B6: 32 | C6: Можно изменить
A7: Порог до ДР по ободу, мм | B7: =Справочник!B5 -> 50 | C7: 35 мм после обточки + 15 мм съем = 50 мм до деповского ремонта
A8: Текущий предел обода, мм | B8: =Справочник!B6 -> 27 | C8: Эксплуатационный предел — 27 мм
A9: Срок колесной пары, лет | B9: 30 | C9: Для возрастной составляющей
A10: Вес физического износа КП | B10: 0.7 | C10: Внутри оценки колесных пар
A11: Вес возраста КП | B11: 0.3 | C11: Внутри оценки колесных пар
A12: Вес износа вагона | B12: 0.5 | C12: В итоговой амортизации
A13: Вес износа колесных пар | B13: 0.5 | C13: В итоговой амортизации
A15: № вагона | B15: Модель | C15: Год вагона | D15: Возраст вагона, лет | E15: Износ вагона, % | F15: Годы КП 1–4 | G15: Средний год КП | H15: Средний возраст КП, лет | I15: Средняя толщина обода, мм | J15: Мин. толщина обода, мм | K15: Физический износ КП, % (50→27 мм) | L15: Возрастной износ КП, % | M15: Итоговый износ КП, % (с риском ДР) | N15: Общая амортизация, % (с ДР) | O15: Остаточная стоимость, % | P15: Цена продавца, ₸ | Q15: Расчетная стоимость, ₸ | R15: Последний плановый ремонт | S15: Следующий ДР | T15: Осталось до ДР, лет | U15: Использовано цикла ДР, % | V15: Доп. амортизация ДР, п.п. | W15: Мин. после обточки, мм | X15: КП не проходят ДР, шт | Y15: Цена новой, ₽ | Z15: Оценочная цена с учетом износа, ₽
A16: =Комплектация!A5 -> 77223766 | B16: =Комплектация!C5 -> 15-5103-7П | C16: =Комплектация!E5 -> 2011 | D16: =MAX(0,YEAR($B$5)-C16) -> 15 | E16: =MIN(100,D16/$B$6*100) -> 46.875 | F16: =TEXT(Комплектация!V5,"0")&"/"&TEXT(Комплектация!AF5,"0")&"/"&TEXT(Комплектация!AP5,"0")&"/"&TEXT(Комплектация!AZ5,"0") -> 2005/2012/2017/2018 | G16: =AVERAGE(Комплектация!V5,Комплектация!AF5,Комплектация!AP5,Комплектация!AZ5) -> 2013 | H16: =MAX(0,YEAR($B$5)-G16) -> 13 | I16: =AVERAGE(Комплектация!AA5:'Комплектация'!AB5,Комплектация!AK5:'Комплектация'!AL5,Комплектация!AU5:'Комплектация'!AV5,Комплектация!BE5:'Комплектация'!BF5) -> 72.75 | J16: =MIN(Комплектация!AA5:'Комплектация'!AB5,Комплектация!AK5:'Комплектация'!AL5,Комплектация!AU5:'Комплектация'!AV5,Комплектация!BE5:'Комплектация'!BF5) -> 71 | K16: =MAX(0,MIN(100,($B$7-J16)/($B$7-$B$8)*100)) -> 0 | L16: =MAX(0,MIN(100,H16/$B$9*100)) -> 43.333333 | M16: =MAX(K16,X16/4*100)*$B$10+L16*$B$11 -> 13 | N16: =MIN(100,E16*$B$12+M16*$B$13+V16) -> 31.214872 | O16: =100-N16 -> 68.785128 | Q16: =IF(P16="","",P16*O16/100) | R16: =IF(Комплектация!G5="",Комплектация!I5,IF(Комплектация!I5="",Комплектация!G5,IF(DATE(VALUE(RIGHT(Комплектация!G5,4)),VALUE(MID(Комплектация!G5,4,2)),VALUE(LEFT(Комплектация!G5,2)))>=DATE(VALUE(RIGHT(Комплектация!I5,4)),VALUE(MID(Комплектация!I5,4,2)),VALUE(LEFT(Комплектация!I5,2))),Комплектация!G5,Комплектация!I5))) -> 18.03.2026 | S16: =Комплектация!L5 -> 18.03.2029 | T16: =IF(S16="","",MAX(0,(DATE(VALUE(RIGHT(S16,4)),VALUE(MID(S16,4,2)),VALUE(LEFT(S16,2)))-$B$5)/365.25)) -> 2.6173854 | U16: =IF(OR(R16="",S16=""),"",MAX(0,MIN(100,($B$5-DATE(VALUE(RIGHT(R16,4)),VALUE(MID(R16,4,2)),VALUE(LEFT(R16,2))))/(DATE(VALUE(RIGHT(S16,4)),VALUE(MID(S16,4,2)),VALUE(LEFT(S16,2)))-DATE(VALUE(RIGHT(R16,4)),VALUE(MID(R16,4,2)),VALUE(LEFT(R16,2))))*100))) -> 12.773723 | V16: =IF(U16="","",U16*Справочник!$B$7/100) -> 1.2773723 | W16: =J16-Справочник!$B$4 -> 56 | X16: =IF(MIN(Комплектация!AA5:'Комплектация'!AB5)-Справочник!$B$4<Справочник!$B$3,1,0)+IF(MIN(Комплектация!AK5:'Комплектация'!AL5)-Справочник!$B$4<Справочник!$B$3,1,0)+IF(MIN(Комплектация!AU5:'Комплектация'!AV5)-Справочник!$B$4<Справочник!$B$3,1,0)+IF(MIN(Комплектация!BE5:'Комплектация'!BF5)-Справочник!$B$4<Справочник!$B$3,1,0) -> 0 | Y16: =Справочник!$B$8 -> 4650000 | Z16: =Y16*O16/100 -> 3198508.4
A17: =Комплектация!A6 -> 77206126 | B17: =Комплектация!C6 -> 15-1755П | C17: =Комплектация!E6 -> 2013 | D17: =MAX(0,YEAR($B$5)-C17) -> 13 | E17: =MIN(100,D17/$B$6*100) -> 40.625 | F17: =TEXT(Комплектация!V6,"0")&"/"&TEXT(Комплектация!AF6,"0")&"/"&TEXT(Комплектация!AP6,"0")&"/"&TEXT(Комплектация!AZ6,"0") -> 2014/2019/2008/1990 | G17: =AVERAGE(Комплектация!V6,Комплектация!AF6,Комплектация!AP6,Комплектация!AZ6) -> 2007.75 | H17: =MAX(0,YEAR($B$5)-G17) -> 18.25 | I17: =AVERAGE(Комплектация!AA6:'Комплектация'!AB6,Комплектация!AK6:'Комплектация'!AL6,Комплектация!AU6:'Комплектация'!AV6,Комплектация!BE6:'Комплектация'!BF6) -> 72.5 | J17: =MIN(Комплектация!AA6:'Комплектация'!AB6,Комплектация!AK6:'Комплектация'!AL6,Комплектация!AU6:'Комплектация'!AV6,Комплектация!BE6:'Комплектация'!BF6) -> 72 | K17: =MAX(0,MIN(100,($B$7-J17)/($B$7-$B$8)*100)) -> 0 | L17: =MAX(0,MIN(100,H17/$B$9*100)) -> 60.833333 | M17: =MAX(K17,X17/4*100)*$B$10+L17*$B$11 -> 18.25 | N17: =MIN(100,E17*$B$12+M17*$B$13+V17) -> 31.821062 | O17: =100-N17 -> 68.178938 | Q17: =IF(P17="","",P17*O17/100) | R17: =IF(Комплектация!G6="",Комплектация!I6,IF(Комплектация!I6="",Комплектация!G6,IF(DATE(VALUE(RIGHT(Комплектация!G6,4)),VALUE(MID(Комплектация!G6,4,2)),VALUE(LEFT(Комплектация!G6,2)))>=DATE(VALUE(RIGHT(Комплектация!I6,4)),VALUE(MID(Комплектация!I6,4,2)),VALUE(LEFT(Комплектация!I6,2))),Комплектация!G6,Комплектация!I6))) -> 12.02.2026 | S17: =Комплектация!L6 -> 12.02.2028 | T17: =IF(S17="","",MAX(0,(DATE(VALUE(RIGHT(S17,4)),VALUE(MID(S17,4,2)),VALUE(LEFT(S17,2)))-$B$5)/365.25)) -> 1.522245 | U17: =IF(OR(R17="",S17=""),"",MAX(0,MIN(100,($B$5-DATE(VALUE(RIGHT(R17,4)),VALUE(MID(R17,4,2)),VALUE(LEFT(R17,2))))/(DATE(VALUE(RIGHT(S17,4)),VALUE(MID(S17,4,2)),VALUE(LEFT(S17,2)))-DATE(VALUE(RIGHT(R17,4)),VALUE(MID(R17,4,2)),VALUE(LEFT(R17,2))))*100))) -> 23.835616 | V17: =IF(U17="","",U17*Справочник!$B$7/100) -> 2.3835616 | W17: =J17-Справочник!$B$4 -> 57 | X17: =IF(MIN(Комплектация!AA6:'Комплектация'!AB6)-Справочник!$B$4<Справочник!$B$3,1,0)+IF(MIN(Комплектация!AK6:'Комплектация'!AL6)-Справочник!$B$4<Справочник!$B$3,1,0)+IF(MIN(Комплектация!AU6:'Комплектация'!AV6)-Справочник!$B$4<Справочник!$B$3,1,0)+IF(MIN(Комплектация!BE6:'Комплектация'!BF6)-Справочник!$B$4<Справочник!$B$3,1,0) -> 0 | Y17: =Справочник!$B$8 -> 4650000 | Z17: =Y17*O17/100 -> 3170320.6
A18: =Комплектация!A7 -> 77205912 | B18: =Комплектация!C7 -> 15-1755П | C18: =Комплектация!E7 -> 2013 | D18: =MAX(0,YEAR($B$5)-C18) -> 13 | E18: =MIN(100,D18/$B$6*100) -> 40.625 | F18: =TEXT(Комплектация!V7,"0")&"/"&TEXT(Комплектация!AF7,"0")&"/"&TEXT(Комплектация!AP7,"0")&"/"&TEXT(Комплектация!AZ7,"0") -> 2013/2012/2013/2013 | G18: =AVERAGE(Комплектация!V7,Комплектация!AF7,Комплектация!AP7,Комплектация!AZ7) -> 2012.75 | H18: =MAX(0,YEAR($B$5)-G18) -> 13.25 | I18: =AVERAGE(Комплектация!AA7:'Комплектация'!AB7,Комплектация!AK7:'Комплектация'!AL7,Комплектация!AU7:'Комплектация'!AV7,Комплектация!BE7:'Комплектация'!BF7) -> 36.25 | J18: =MIN(Комплектация!AA7:'Комплектация'!AB7,Комплектация!AK7:'Комплектация'!AL7,Комплектация!AU7:'Комплектация'!AV7,Комплектация!BE7:'Комплектация'!BF7) -> 32 | K18: =MAX(0,MIN(100,($B$7-J18)/($B$7-$B$8)*100)) -> 78.26087 | L18: =MAX(0,MIN(100,H18/$B$9*100)) -> 44.166667 | M18: =MAX(K18,X18/4*100)*$B$10+L18*$B$11 -> 83.25 | N18: =MIN(100,E18*$B$12+M18*$B$13+V18) -> 64.321062 | O18: =100-N18 -> 35.678938 | Q18: =IF(P18="","",P18*O18/100) | R18: =IF(Комплектация!G7="",Комплектация!I7,IF(Комплектация!I7="",Комплектация!G7,IF(DATE(VALUE(RIGHT(Комплектация!G7,4)),VALUE(MID(Комплектация!G7,4,2)),VALUE(LEFT(Комплектация!G7,2)))>=DATE(VALUE(RIGHT(Комплектация!I7,4)),VALUE(MID(Комплектация!I7,4,2)),VALUE(LEFT(Комплектация!I7,2))),Комплектация!G7,Комплектация!I7))) -> 12.02.2026 | S18: =Комплектация!L7 -> 12.02.2028 | T18: =IF(S18="","",MAX(0,(DATE(VALUE(RIGHT(S18,4)),VALUE(MID(S18,4,2)),VALUE(LEFT(S18,2)))-$B$5)/365.25)) -> 1.522245 | U18: =IF(OR(R18="",S18=""),"",MAX(0,MIN(100,($B$5-DATE(VALUE(RIGHT(R18,4)),VALUE(MID(R18,4,2)),VALUE(LEFT(R18,2))))/(DATE(VALUE(RIGHT(S18,4)),VALUE(MID(S18,4,2)),VALUE(LEFT(S18,2)))-DATE(VALUE(RIGHT(R18,4)),VALUE(MID(R18,4,2)),VALUE(LEFT(R18,2))))*100))) -> 23.835616 | V18: =IF(U18="","",U18*Справочник!$B$7/100) -> 2.3835616 | W18: =J18-Справочник!$B$4 -> 17 | X18: =IF(MIN(Комплектация!AA7:'Комплектация'!AB7)-Справочник!$B$4<Справочник!$B$3,1,0)+IF(MIN(Комплектация!AK7:'Комплектация'!AL7)-Справочник!$B$4<Справочник!$B$3,1,0)+IF(MIN(Комплектация!AU7:'Комплектация'!AV7)-Справочник!$B$4<Справочник!$B$3,1,0)+IF(MIN(Комплектация!BE7:'Комплектация'!BF7)-Справочник!$B$4<Справочник!$B$3,1,0) -> 4 | Y18: =Справочник!$B$8 -> 4650000 | Z18: =Y18*O18/100 -> 1659070.6
A19: =Комплектация!A8 -> 77206159 | B19: =Комплектация!C8 -> 15-1755П | C19: =Комплектация!E8 -> 2013 | D19: =MAX(0,YEAR($B$5)-C19) -> 13 | E19: =MIN(100,D19/$B$6*100) -> 40.625 | F19: =TEXT(Комплектация!V8,"0")&"/"&TEXT(Комплектация!AF8,"0")&"/"&TEXT(Комплектация!AP8,"0")&"/"&TEXT(Комплектация!AZ8,"0") -> 2011/2010/2010/2008 | G19: =AVERAGE(Комплектация!V8,Комплектация!AF8,Комплектация!AP8,Комплектация!AZ8) -> 2009.75 | H19: =MAX(0,YEAR($B$5)-G19) -> 16.25 | I19: =AVERAGE(Комплектация!AA8:'Комплектация'!AB8,Комплектация!AK8:'Комплектация'!AL8,Комплектация!AU8:'Комплектация'!AV8,Комплектация!BE8:'Комплектация'!BF8) -> 72.75 | J19: =MIN(Комплектация!AA8:'Комплектация'!AB8,Комплектация!AK8:'Комплектация'!AL8,Комплектация!AU8:'Комплектация'!AV8,Комплектация!BE8:'Комплектация'!BF8) -> 66 | K19: =MAX(0,MIN(100,($B$7-J19)/($B$7-$B$8)*100)) -> 0 | L19: =MAX(0,MIN(100,H19/$B$9*100)) -> 54.166667 | M19: =MAX(K19,X19/4*100)*$B$10+L19*$B$11 -> 16.25 | N19: =MIN(100,E19*$B$12+M19*$B$13+V19) -> 30.821062 | O19: =100-N19 -> 69.178938 | Q19: =IF(P19="","",P19*O19/100) | R19: =IF(Комплектация!G8="",Комплектация!I8,IF(Комплектация!I8="",Комплектация!G8,IF(DATE(VALUE(RIGHT(Комплектация!G8,4)),VALUE(MID(Комплектация!G8,4,2)),VALUE(LEFT(Комплектация!G8,2)))>=DATE(VALUE(RIGHT(Комплектация!I8,4)),VALUE(MID(Комплектация!I8,4,2)),VALUE(LEFT(Комплектация!I8,2))),Комплектация!G8,Комплектация!I8))) -> 12.02.2026 | S19: =Комплектация!L8 -> 12.02.2028 | T19: =IF(S19="","",MAX(0,(DATE(VALUE(RIGHT(S19,4)),VALUE(MID(S19,4,2)),VALUE(LEFT(S19,2)))-$B$5)/365.25)) -> 1.522245 | U19: =IF(OR(R19="",S19=""),"",MAX(0,MIN(100,($B$5-DATE(VALUE(RIGHT(R19,4)),VALUE(MID(R19,4,2)),VALUE(LEFT(R19,2))))/(DATE(VALUE(RIGHT(S19,4)),VALUE(MID(S19,4,2)),VALUE(LEFT(S19,2)))-DATE(VALUE(RIGHT(R19,4)),VALUE(MID(R19,4,2)),VALUE(LEFT(R19,2))))*100))) -> 23.835616 | V19: =IF(U19="","",U19*Справочник!$B$7/100) -> 2.3835616 | W19: =J19-Справочник!$B$4 -> 51 | X19: =IF(MIN(Комплектация!AA8:'Комплектация'!AB8)-Справочник!$B$4<Справочник!$B$3,1,0)+IF(MIN(Комплектация!AK8:'Комплектация'!AL8)-Справочник!$B$4<Справочник!$B$3,1,0)+IF(MIN(Комплектация!AU8:'Комплектация'!AV8)-Справочник!$B$4<Справочник!$B$3,1,0)+IF(MIN(Комплектация!BE8:'Комплектация'!BF8)-Справочник!$B$4<Справочник!$B$3,1,0) -> 0 | Y19: =Справочник!$B$8 -> 4650000 | Z19: =Y19*O19/100 -> 3216820.6
A20: =Комплектация!A9 -> 77222149 | B20: =Комплектация!C9 -> 15-1755П | C20: =Комплектация!E9 -> 2014 | D20: =MAX(0,YEAR($B$5)-C20) -> 12 | E20: =MIN(100,D20/$B$6*100) -> 37.5 | F20: =TEXT(Комплектация!V9,"0")&"/"&TEXT(Комплектация!AF9,"0")&"/"&TEXT(Комплектация!AP9,"0")&"/"&TEXT(Комплектация!AZ9,"0") -> 2013/2013/2014/2014 | G20: =AVERAGE(Комплектация!V9,Комплектация!AF9,Комплектация!AP9,Комплектация!AZ9) -> 2013.5 | H20: =MAX(0,YEAR($B$5)-G20) -> 12.5 | I20: =AVERAGE(Комплектация!AA9:'Комплектация'!AB9,Комплектация!AK9:'Комплектация'!AL9,Комплектация!AU9:'Комплектация'!AV9,Комплектация!BE9:'Комплектация'!BF9) -> 75 | J20: =MIN(Комплектация!AA9:'Комплектация'!AB9,Комплектация!AK9:'Комплектация'!AL9,Комплектация!AU9:'Комплектация'!AV9,Комплектация!BE9:'Комплектация'!BF9) -> 75 | K20: =MAX(0,MIN(100,($B$7-J20)/($B$7-$B$8)*100)) -> 0 | L20: =MAX(0,MIN(100,H20/$B$9*100)) -> 41.666667 | M20: =MAX(K20,X20/4*100)*$B$10+L20*$B$11 -> 12.5 | N20: =MIN(100,E20*$B$12+M20*$B$13+V20) -> 31.958904 | O20: =100-N20 -> 68.041096 | Q20: =IF(P20="","",P20*O20/100) | R20: =IF(Комплектация!G9="",Комплектация!I9,IF(Комплектация!I9="",Комплектация!G9,IF(DATE(VALUE(RIGHT(Комплектация!G9,4)),VALUE(MID(Комплектация!G9,4,2)),VALUE(LEFT(Комплектация!G9,2)))>=DATE(VALUE(RIGHT(Комплектация!I9,4)),VALUE(MID(Комплектация!I9,4,2)),VALUE(LEFT(Комплектация!I9,2))),Комплектация!G9,Комплектация!I9))) -> 15.03.2025 | S20: =Комплектация!L9 -> 15.03.2027 | T20: =IF(S20="","",MAX(0,(DATE(VALUE(RIGHT(S20,4)),VALUE(MID(S20,4,2)),VALUE(LEFT(S20,2)))-$B$5)/365.25)) -> 0.60780287 | U20: =IF(OR(R20="",S20=""),"",MAX(0,MIN(100,($B$5-DATE(VALUE(RIGHT(R20,4)),VALUE(MID(R20,4,2)),VALUE(LEFT(R20,2))))/(DATE(VALUE(RIGHT(S20,4)),VALUE(MID(S20,4,2)),VALUE(LEFT(S20,2)))-DATE(VALUE(RIGHT(R20,4)),VALUE(MID(R20,4,2)),VALUE(LEFT(R20,2))))*100))) -> 69.589041 | V20: =IF(U20="","",U20*Справочник!$B$7/100) -> 6.9589041 | W20: =J20-Справочник!$B$4 -> 60 | X20: =IF(MIN(Комплектация!AA9:'Комплектация'!AB9)-Справочник!$B$4<Справочник!$B$3,1,0)+IF(MIN(Комплектация!AK9:'Комплектация'!AL9)-Справочник!$B$4<Справочник!$B$3,1,0)+IF(MIN(Комплектация!AU9:'Комплектация'!AV9)-Справочник!$B$4<Справочник!$B$3,1,0)+IF(MIN(Комплектация!BE9:'Комплектация'!BF9)-Справочник!$B$4<Справочник!$B$3,1,0) -> 0 | Y20: =Справочник!$B$8 -> 4650000 | Z20: =Y20*O20/100 -> 3163911
A21: =Комплектация!A10 -> 77222214 | B21: =Комплектация!C10 -> 15-1755П | C21: =Комплектация!E10 -> 2014 | D21: =MAX(0,YEAR($B$5)-C21) -> 12 | E21: =MIN(100,D21/$B$6*100) -> 37.5 | F21: =TEXT(Комплектация!V10,"0")&"/"&TEXT(Комплектация!AF10,"0")&"/"&TEXT(Комплектация!AP10,"0")&"/"&TEXT(Комплектация!AZ10,"0") -> 2013/2013/2014/2014 | G21: =AVERAGE(Комплектация!V10,Комплектация!AF10,Комплектация!AP10,Комплектация!AZ10) -> 2013.5 | H21: =MAX(0,YEAR($B$5)-G21) -> 12.5 | I21: =AVERAGE(Комплектация!AA10:'Комплектация'!AB10,Комплектация!AK10:'Комплектация'!AL10,Комплектация!AU10:'Комплектация'!AV10,Комплектация!BE10:'Комплектация'!BF10) -> 75 | J21: =MIN(Комплектация!AA10:'Комплектация'!AB10,Комплектация!AK10:'Комплектация'!AL10,Комплектация!AU10:'Комплектация'!AV10,Комплектация!BE10:'Комплектация'!BF10) -> 75 | K21: =MAX(0,MIN(100,($B$7-J21)/($B$7-$B$8)*100)) -> 0 | L21: =MAX(0,MIN(100,H21/$B$9*100)) -> 41.666667 | M21: =MAX(K21,X21/4*100)*$B$10+L21*$B$11 -> 12.5 | N21: =MIN(100,E21*$B$12+M21*$B$13+V21) -> 31.69863 | O21: =100-N21 -> 68.30137 | Q21: =IF(P21="","",P21*O21/100) | R21: =IF(Комплектация!G10="",Комплектация!I10,IF(Комплектация!I10="",Комплектация!G10,IF(DATE(VALUE(RIGHT(Комплектация!G10,4)),VALUE(MID(Комплектация!G10,4,2)),VALUE(LEFT(Комплектация!G10,2)))>=DATE(VALUE(RIGHT(Комплектация!I10,4)),VALUE(MID(Комплектация!I10,4,2)),VALUE(LEFT(Комплектация!I10,2))),Комплектация!G10,Комплектация!I10))) -> 03.04.2025 | S21: =Комплектация!L10 -> 03.04.2027 | T21: =IF(S21="","",MAX(0,(DATE(VALUE(RIGHT(S21,4)),VALUE(MID(S21,4,2)),VALUE(LEFT(S21,2)))-$B$5)/365.25)) -> 0.65982204 | U21: =IF(OR(R21="",S21=""),"",MAX(0,MIN(100,($B$5-DATE(VALUE(RIGHT(R21,4)),VALUE(MID(R21,4,2)),VALUE(LEFT(R21,2))))/(DATE(VALUE(RIGHT(S21,4)),VALUE(MID(S21,4,2)),VALUE(LEFT(S21,2)))-DATE(VALUE(RIGHT(R21,4)),VALUE(MID(R21,4,2)),VALUE(LEFT(R21,2))))*100))) -> 66.986301 | V21: =IF(U21="","",U21*Справочник!$B$7/100) -> 6.6986301 | W21: =J21-Справочник!$B$4 -> 60 | X21: =IF(MIN(Комплектация!AA10:'Комплектация'!AB10)-Справочник!$B$4<Справочник!$B$3,1,0)+IF(MIN(Комплектация!AK10:'Комплектация'!AL10)-Справочник!$B$4<Справочник!$B$3,1,0)+IF(MIN(Комплектация!AU10:'Комплектация'!AV10)-Справочник!$B$4<Справочник!$B$3,1,0)+IF(MIN(Комплектация!BE10:'Комплектация'!BF10)-Справочник!$B$4<Справочник!$B$3,1,0) -> 0 | Y21: =Справочник!$B$8 -> 4650000 | Z21: =Y21*O21/100 -> 3176013.7
A22: =Комплектация!A11 -> 77206076 | B22: =Комплектация!C11 -> 15-1755П | C22: =Комплектация!E11 -> 2013 | D22: =MAX(0,YEAR($B$5)-C22) -> 13 | E22: =MIN(100,D22/$B$6*100) -> 40.625 | F22: =TEXT(Комплектация!V11,"0")&"/"&TEXT(Комплектация!AF11,"0")&"/"&TEXT(Комплектация!AP11,"0")&"/"&TEXT(Комплектация!AZ11,"0") -> 2005/2013/2007/2010 | G22: =AVERAGE(Комплектация!V11,Комплектация!AF11,Комплектация!AP11,Комплектация!AZ11) -> 2008.75 | H22: =MAX(0,YEAR($B$5)-G22) -> 17.25 | I22: =AVERAGE(Комплектация!AA11:'Комплектация'!AB11,Комплектация!AK11:'Комплектация'!AL11,Комплектация!AU11:'Комплектация'!AV11,Комплектация!BE11:'Комплектация'!BF11) -> 72 | J22: =MIN(Комплектация!AA11:'Комплектация'!AB11,Комплектация!AK11:'Комплектация'!AL11,Комплектация!AU11:'Комплектация'!AV11,Комплектация!BE11:'Комплектация'!BF11) -> 70 | K22: =MAX(0,MIN(100,($B$7-J22)/($B$7-$B$8)*100)) -> 0 | L22: =MAX(0,MIN(100,H22/$B$9*100)) -> 57.5 | M22: =MAX(K22,X22/4*100)*$B$10+L22*$B$11 -> 17.25 | N22: =MIN(100,E22*$B$12+M22*$B$13+V22) -> 31.293664 | O22: =100-N22 -> 68.706336 | Q22: =IF(P22="","",P22*O22/100) | R22: =IF(Комплектация!G11="",Комплектация!I11,IF(Комплектация!I11="",Комплектация!G11,IF(DATE(VALUE(RIGHT(Комплектация!G11,4)),VALUE(MID(Комплектация!G11,4,2)),VALUE(LEFT(Комплектация!G11,2)))>=DATE(VALUE(RIGHT(Комплектация!I11,4)),VALUE(MID(Комплектация!I11,4,2)),VALUE(LEFT(Комплектация!I11,2))),Комплектация!G11,Комплектация!I11))) -> 14.02.2026 | S22: =Комплектация!L11 -> 14.02.2028 | T22: =IF(S22="","",MAX(0,(DATE(VALUE(RIGHT(S22,4)),VALUE(MID(S22,4,2)),VALUE(LEFT(S22,2)))-$B$5)/365.25)) -> 1.5277207 | U22: =IF(OR(R22="",S22=""),"",MAX(0,MIN(100,($B$5-DATE(VALUE(RIGHT(R22,4)),VALUE(MID(R22,4,2)),VALUE(LEFT(R22,2))))/(DATE(VALUE(RIGHT(S22,4)),VALUE(MID(S22,4,2)),VALUE(LEFT(S22,2)))-DATE(VALUE(RIGHT(R22,4)),VALUE(MID(R22,4,2)),VALUE(LEFT(R22,2))))*100))) -> 23.561644 | V22: =IF(U22="","",U22*Справочник!$B$7/100) -> 2.3561644 | W22: =J22-Справочник!$B$4 -> 55 | X22: =IF(MIN(Комплектация!AA11:'Комплектация'!AB11)-Справочник!$B$4<Справочник!$B$3,1,0)+IF(MIN(Комплектация!AK11:'Комплектация'!AL11)-Справочник!$B$4<Справочник!$B$3,1,0)+IF(MIN(Комплектация!AU11:'Комплектация'!AV11)-Справочник!$B$4<Справочник!$B$3,1,0)+IF(MIN(Комплектация!BE11:'Комплектация'!BF11)-Справочник!$B$4<Справочник!$B$3,1,0) -> 0 | Y22: =Справочник!$B$8 -> 4650000 | Z22: =Y22*O22/100 -> 3194844.6
A23: =Комплектация!A12 -> 77228781 | B23: =Комплектация!C12 -> 15-5103-7П | C23: =Комплектация!E12 -> 2015 | D23: =MAX(0,YEAR($B$5)-C23) -> 11 | E23: =MIN(100,D23/$B$6*100) -> 34.375 | F23: =TEXT(Комплектация!V12,"0")&"/"&TEXT(Комплектация!AF12,"0")&"/"&TEXT(Комплектация!AP12,"0")&"/"&TEXT(Комплектация!AZ12,"0") -> 2010/2014/2014/2013 | G23: =AVERAGE(Комплектация!V12,Комплектация!AF12,Комплектация!AP12,Комплектация!AZ12) -> 2012.75 | H23: =MAX(0,YEAR($B$5)-G23) -> 13.25 | I23: =AVERAGE(Комплектация!AA12:'Комплектация'!AB12,Комплектация!AK12:'Комплектация'!AL12,Комплектация!AU12:'Комплектация'!AV12,Комплектация!BE12:'Комплектация'!BF12) -> 59.125 | J23: =MIN(Комплектация!AA12:'Комплектация'!AB12,Комплектация!AK12:'Комплектация'!AL12,Комплектация!AU12:'Комплектация'!AV12,Комплектация!BE12:'Комплектация'!BF12) -> 58 | K23: =MAX(0,MIN(100,($B$7-J23)/($B$7-$B$8)*100)) -> 0 | L23: =MAX(0,MIN(100,H23/$B$9*100)) -> 44.166667 | M23: =MAX(K23,X23/4*100)*$B$10+L23*$B$11 -> 13.25 | N23: =MIN(100,E23*$B$12+M23*$B$13+V23) -> 27.005931 | O23: =100-N23 -> 72.994069 | Q23: =IF(P23="","",P23*O23/100) | R23: =IF(Комплектация!G12="",Комплектация!I12,IF(Комплектация!I12="",Комплектация!G12,IF(DATE(VALUE(RIGHT(Комплектация!G12,4)),VALUE(MID(Комплектация!G12,4,2)),VALUE(LEFT(Комплектация!G12,2)))>=DATE(VALUE(RIGHT(Комплектация!I12,4)),VALUE(MID(Комплектация!I12,4,2)),VALUE(LEFT(Комплектация!I12,2))),Комплектация!G12,Комплектация!I12))) -> 20.08.2025 | S23: =Комплектация!L12 -> 20.08.2028 | T23: =IF(S23="","",MAX(0,(DATE(VALUE(RIGHT(S23,4)),VALUE(MID(S23,4,2)),VALUE(LEFT(S23,2)))-$B$5)/365.25)) -> 2.0424367 | U23: =IF(OR(R23="",S23=""),"",MAX(0,MIN(100,($B$5-DATE(VALUE(RIGHT(R23,4)),VALUE(MID(R23,4,2)),VALUE(LEFT(R23,2))))/(DATE(VALUE(RIGHT(S23,4)),VALUE(MID(S23,4,2)),VALUE(LEFT(S23,2)))-DATE(VALUE(RIGHT(R23,4)),VALUE(MID(R23,4,2)),VALUE(LEFT(R23,2))))*100))) -> 31.934307 | V23: =IF(U23="","",U23*Справочник!$B$7/100) -> 3.1934307 | W23: =J23-Справочник!$B$4 -> 43 | X23: =IF(MIN(Комплектация!AA12:'Комплектация'!AB12)-Справочник!$B$4<Справочник!$B$3,1,0)+IF(MIN(Комплектация!AK12:'Комплектация'!AL12)-Справочник!$B$4<Справочник!$B$3,1,0)+IF(MIN(Комплектация!AU12:'Комплектация'!AV12)-Справочник!$B$4<Справочник!$B$3,1,0)+IF(MIN(Комплектация!BE12:'Комплектация'!BF12)-Справочник!$B$4<Справочник!$B$3,1,0) -> 0 | Y23: =Справочник!$B$8 -> 4650000 | Z23: =Y23*O23/100 -> 3394224.2
A24: =Комплектация!A13 -> 77221810 | B24: =Комплектация!C13 -> 15-5103-7П | C24: =Комплектация!E13 -> 2011 | D24: =MAX(0,YEAR($B$5)-C24) -> 15 | E24: =MIN(100,D24/$B$6*100) -> 46.875 | F24: =TEXT(Комплектация!V13,"0")&"/"&TEXT(Комплектация!AF13,"0")&"/"&TEXT(Комплектация!AP13,"0")&"/"&TEXT(Комплектация!AZ13,"0") -> 2013/2011/2014/2011 | G24: =AVERAGE(Комплектация!V13,Комплектация!AF13,Комплектация!AP13,Комплектация!AZ13) -> 2012.25 | H24: =MAX(0,YEAR($B$5)-G24) -> 13.75 | I24: =AVERAGE(Комплектация!AA13:'Комплектация'!AB13,Комплектация!AK13:'Комплектация'!AL13,Комплектация!AU13:'Комплектация'!AV13,Комплектация!BE13:'Комплектация'!BF13) -> 72.125 | J24: =MIN(Комплектация!AA13:'Комплектация'!AB13,Комплектация!AK13:'Комплектация'!AL13,Комплектация!AU13:'Комплектация'!AV13,Комплектация!BE13:'Комплектация'!BF13) -> 70 | K24: =MAX(0,MIN(100,($B$7-J24)/($B$7-$B$8)*100)) -> 0 | L24: =MAX(0,MIN(100,H24/$B$9*100)) -> 45.833333 | M24: =MAX(K24,X24/4*100)*$B$10+L24*$B$11 -> 13.75 | N24: =MIN(100,E24*$B$12+M24*$B$13+V24) -> 33.496807 | O24: =100-N24 -> 66.503193 | Q24: =IF(P24="","",P24*O24/100) | R24: =IF(Комплектация!G13="",Комплектация!I13,IF(Комплектация!I13="",Комплектация!G13,IF(DATE(VALUE(RIGHT(Комплектация!G13,4)),VALUE(MID(Комплектация!G13,4,2)),VALUE(LEFT(Комплектация!G13,2)))>=DATE(VALUE(RIGHT(Комплектация!I13,4)),VALUE(MID(Комплектация!I13,4,2)),VALUE(LEFT(Комплектация!I13,2))),Комплектация!G13,Комплектация!I13))) -> 21.08.2025 | S24: =Комплектация!L13 -> 21.08.2028 | T24: =IF(S24="","",MAX(0,(DATE(VALUE(RIGHT(S24,4)),VALUE(MID(S24,4,2)),VALUE(LEFT(S24,2)))-$B$5)/365.25)) -> 2.0451745 | U24: =IF(OR(R24="",S24=""),"",MAX(0,MIN(100,($B$5-DATE(VALUE(RIGHT(R24,4)),VALUE(MID(R24,4,2)),VALUE(LEFT(R24,2))))/(DATE(VALUE(RIGHT(S24,4)),VALUE(MID(S24,4,2)),VALUE(LEFT(S24,2)))-DATE(VALUE(RIGHT(R24,4)),VALUE(MID(R24,4,2)),VALUE(LEFT(R24,2))))*100))) -> 31.843066 | V24: =IF(U24="","",U24*Справочник!$B$7/100) -> 3.1843066 | W24: =J24-Справочник!$B$4 -> 55 | X24: =IF(MIN(Комплектация!AA13:'Комплектация'!AB13)-Справочник!$B$4<Справочник!$B$3,1,0)+IF(MIN(Комплектация!AK13:'Комплектация'!AL13)-Справочник!$B$4<Справочник!$B$3,1,0)+IF(MIN(Комплектация!AU13:'Комплектация'!AV13)-Справочник!$B$4<Справочник!$B$3,1,0)+IF(MIN(Комплектация!BE13:'Комплектация'!BF13)-Справочник!$B$4<Справочник!$B$3,1,0) -> 0 | Y24: =Справочник!$B$8 -> 4650000 | Z24: =Y24*O24/100 -> 3092398.5
A25: =Комплектация!A14 -> 77228724 | B25: =Комплектация!C14 -> 15-5103-7П | C25: =Комплектация!E14 -> 2015 | D25: =MAX(0,YEAR($B$5)-C25) -> 11 | E25: =MIN(100,D25/$B$6*100) -> 34.375 | F25: =TEXT(Комплектация!V14,"0")&"/"&TEXT(Комплектация!AF14,"0")&"/"&TEXT(Комплектация!AP14,"0")&"/"&TEXT(Комплектация!AZ14,"0") -> 2015/2015/2015/2014 | G25: =AVERAGE(Комплектация!V14,Комплектация!AF14,Комплектация!AP14,Комплектация!AZ14) -> 2014.75 | H25: =MAX(0,YEAR($B$5)-G25) -> 11.25 | I25: =AVERAGE(Комплектация!AA14:'Комплектация'!AB14,Комплектация!AK14:'Комплектация'!AL14,Комплектация!AU14:'Комплектация'!AV14,Комплектация!BE14:'Комплектация'!BF14) -> 43.25 | J25: =MIN(Комплектация!AA14:'Комплектация'!AB14,Комплектация!AK14:'Комплектация'!AL14,Комплектация!AU14:'Комплектация'!AV14,Комплектация!BE14:'Комплектация'!BF14) -> 41 | K25: =MAX(0,MIN(100,($B$7-J25)/($B$7-$B$8)*100)) -> 39.130435 | L25: =MAX(0,MIN(100,H25/$B$9*100)) -> 37.5 | M25: =MAX(K25,X25/4*100)*$B$10+L25*$B$11 -> 81.25 | N25: =MIN(100,E25*$B$12+M25*$B$13+V25) -> 61.005931 | O25: =100-N25 -> 38.994069 | Q25: =IF(P25="","",P25*O25/100) | R25: =IF(Комплектация!G14="",Комплектация!I14,IF(Комплектация!I14="",Комплектация!G14,IF(DATE(VALUE(RIGHT(Комплектация!G14,4)),VALUE(MID(Комплектация!G14,4,2)),VALUE(LEFT(Комплектация!G14,2)))>=DATE(VALUE(RIGHT(Комплектация!I14,4)),VALUE(MID(Комплектация!I14,4,2)),VALUE(LEFT(Комплектация!I14,2))),Комплектация!G14,Комплектация!I14))) -> 20.08.2025 | S25: =Комплектация!L14 -> 20.08.2028 | T25: =IF(S25="","",MAX(0,(DATE(VALUE(RIGHT(S25,4)),VALUE(MID(S25,4,2)),VALUE(LEFT(S25,2)))-$B$5)/365.25)) -> 2.0424367 | U25: =IF(OR(R25="",S25=""),"",MAX(0,MIN(100,($B$5-DATE(VALUE(RIGHT(R25,4)),VALUE(MID(R25,4,2)),VALUE(LEFT(R25,2))))/(DATE(VALUE(RIGHT(S25,4)),VALUE(MID(S25,4,2)),VALUE(LEFT(S25,2)))-DATE(VALUE(RIGHT(R25,4)),VALUE(MID(R25,4,2)),VALUE(LEFT(R25,2))))*100))) -> 31.934307 | V25: =IF(U25="","",U25*Справочник!$B$7/100) -> 3.1934307 | W25: =J25-Справочник!$B$4 -> 26 | X25: =IF(MIN(Комплектация!AA14:'Комплектация'!AB14)-Справочник!$B$4<Справочник!$B$3,1,0)+IF(MIN(Комплектация!AK14:'Комплектация'!AL14)-Справочник!$B$4<Справочник!$B$3,1,0)+IF(MIN(Комплектация!AU14:'Комплектация'!AV14)-Справочник!$B$4<Справочник!$B$3,1,0)+IF(MIN(Комплектация!BE14:'Комплектация'!BF14)-Справочник!$B$4<Справочник!$B$3,1,0) -> 4 | Y25: =Справочник!$B$8 -> 4650000 | Z25: =Y25*O25/100 -> 1813224.2
A26: =Комплектация!A15 -> 77222040 | B26: =Комплектация!C15 -> 15-150-04П | C26: =Комплектация!E15 -> 2011 | D26: =MAX(0,YEAR($B$5)-C26) -> 15 | E26: =MIN(100,D26/$B$6*100) -> 46.875 | F26: =TEXT(Комплектация!V15,"0")&"/"&TEXT(Комплектация!AF15,"0")&"/"&TEXT(Комплектация!AP15,"0")&"/"&TEXT(Комплектация!AZ15,"0") -> 2013/2011/2013/2014 | G26: =AVERAGE(Комплектация!V15,Комплектация!AF15,Комплектация!AP15,Комплектация!AZ15) -> 2012.75 | H26: =MAX(0,YEAR($B$5)-G26) -> 13.25 | I26: =AVERAGE(Комплектация!AA15:'Комплектация'!AB15,Комплектация!AK15:'Комплектация'!AL15,Комплектация!AU15:'Комплектация'!AV15,Комплектация!BE15:'Комплектация'!BF15) -> 66.25 | J26: =MIN(Комплектация!AA15:'Комплектация'!AB15,Комплектация!AK15:'Комплектация'!AL15,Комплектация!AU15:'Комплектация'!AV15,Комплектация!BE15:'Комплектация'!BF15) -> 63 | K26: =MAX(0,MIN(100,($B$7-J26)/($B$7-$B$8)*100)) -> 0 | L26: =MAX(0,MIN(100,H26/$B$9*100)) -> 44.166667 | M26: =MAX(K26,X26/4*100)*$B$10+L26*$B$11 -> 13.25 | N26: =MIN(100,E26*$B$12+M26*$B$13+V26) -> 33.237682 | O26: =100-N26 -> 66.762318 | Q26: =IF(P26="","",P26*O26/100) | R26: =IF(Комплектация!G15="",Комплектация!I15,IF(Комплектация!I15="",Комплектация!G15,IF(DATE(VALUE(RIGHT(Комплектация!G15,4)),VALUE(MID(Комплектация!G15,4,2)),VALUE(LEFT(Комплектация!G15,2)))>=DATE(VALUE(RIGHT(Комплектация!I15,4)),VALUE(MID(Комплектация!I15,4,2)),VALUE(LEFT(Комплектация!I15,2))),Комплектация!G15,Комплектация!I15))) -> 22.08.2025 | S26: =Комплектация!L15 -> 22.08.2028 | T26: =IF(S26="","",MAX(0,(DATE(VALUE(RIGHT(S26,4)),VALUE(MID(S26,4,2)),VALUE(LEFT(S26,2)))-$B$5)/365.25)) -> 2.0479124 | U26: =IF(OR(R26="",S26=""),"",MAX(0,MIN(100,($B$5-DATE(VALUE(RIGHT(R26,4)),VALUE(MID(R26,4,2)),VALUE(LEFT(R26,2))))/(DATE(VALUE(RIGHT(S26,4)),VALUE(MID(S26,4,2)),VALUE(LEFT(S26,2)))-DATE(VALUE(RIGHT(R26,4)),VALUE(MID(R26,4,2)),VALUE(LEFT(R26,2))))*100))) -> 31.751825 | V26: =IF(U26="","",U26*Справочник!$B$7/100) -> 3.1751825 | W26: =J26-Справочник!$B$4 -> 48 | X26: =IF(MIN(Комплектация!AA15:'Комплектация'!AB15)-Справочник!$B$4<Справочник!$B$3,1,0)+IF(MIN(Комплектация!AK15:'Комплектация'!AL15)-Справочник!$B$4<Справочник!$B$3,1,0)+IF(MIN(Комплектация!AU15:'Комплектация'!AV15)-Справочник!$B$4<Справочник!$B$3,1,0)+IF(MIN(Комплектация!BE15:'Комплектация'!BF15)-Справочник!$B$4<Справочник!$B$3,1,0) -> 0 | Y26: =Справочник!$B$8 -> 4650000 | Z26: =Y26*O26/100 -> 3104447.8
A27: =Комплектация!A16 -> 77227080 | B27: =Комплектация!C16 -> 15-5103-7П | C27: =Комплектация!E16 -> 2012 | D27: =MAX(0,YEAR($B$5)-C27) -> 14 | E27: =MIN(100,D27/$B$6*100) -> 43.75 | F27: =TEXT(Комплектация!V16,"0")&"/"&TEXT(Комплектация!AF16,"0")&"/"&TEXT(Комплектация!AP16,"0")&"/"&TEXT(Комплектация!AZ16,"0") -> 2012/2012/2011/2011 | G27: =AVERAGE(Комплектация!V16,Комплектация!AF16,Комплектация!AP16,Комплектация!AZ16) -> 2011.5 | H27: =MAX(0,YEAR($B$5)-G27) -> 14.5 | I27: =AVERAGE(Комплектация!AA16:'Комплектация'!AB16,Комплектация!AK16:'Комплектация'!AL16,Комплектация!AU16:'Комплектация'!AV16,Комплектация!BE16:'Комплектация'!BF16) -> 71.5 | J27: =MIN(Комплектация!AA16:'Комплектация'!AB16,Комплектация!AK16:'Комплектация'!AL16,Комплектация!AU16:'Комплектация'!AV16,Комплектация!BE16:'Комплектация'!BF16) -> 71 | K27: =MAX(0,MIN(100,($B$7-J27)/($B$7-$B$8)*100)) -> 0 | L27: =MAX(0,MIN(100,H27/$B$9*100)) -> 48.333333 | M27: =MAX(K27,X27/4*100)*$B$10+L27*$B$11 -> 14.5 | N27: =MIN(100,E27*$B$12+M27*$B$13+V27) -> 32.008212 | O27: =100-N27 -> 67.991788 | Q27: =IF(P27="","",P27*O27/100) | R27: =IF(Комплектация!G16="",Комплектация!I16,IF(Комплектация!I16="",Комплектация!G16,IF(DATE(VALUE(RIGHT(Комплектация!G16,4)),VALUE(MID(Комплектация!G16,4,2)),VALUE(LEFT(Комплектация!G16,2)))>=DATE(VALUE(RIGHT(Комплектация!I16,4)),VALUE(MID(Комплектация!I16,4,2)),VALUE(LEFT(Комплектация!I16,2))),Комплектация!G16,Комплектация!I16))) -> 23.09.2025 | S27: =Комплектация!L16 -> 23.09.2028 | T27: =IF(S27="","",MAX(0,(DATE(VALUE(RIGHT(S27,4)),VALUE(MID(S27,4,2)),VALUE(LEFT(S27,2)))-$B$5)/365.25)) -> 2.1355236 | U27: =IF(OR(R27="",S27=""),"",MAX(0,MIN(100,($B$5-DATE(VALUE(RIGHT(R27,4)),VALUE(MID(R27,4,2)),VALUE(LEFT(R27,2))))/(DATE(VALUE(RIGHT(S27,4)),VALUE(MID(S27,4,2)),VALUE(LEFT(S27,2)))-DATE(VALUE(RIGHT(R27,4)),VALUE(MID(R27,4,2)),VALUE(LEFT(R27,2))))*100))) -> 28.832117 | V27: =IF(U27="","",U27*Справочник!$B$7/100) -> 2.8832117 | W27: =J27-Справочник!$B$4 -> 56 | X27: =IF(MIN(Комплектация!AA16:'Комплектация'!AB16)-Справочник!$B$4<Справочник!$B$3,1,0)+IF(MIN(Комплектация!AK16:'Комплектация'!AL16)-Справочник!$B$4<Справочник!$B$3,1,0)+IF(MIN(Комплектация!AU16:'Комплектация'!AV16)-Справочник!$B$4<Справочник!$B$3,1,0)+IF(MIN(Комплектация!BE16:'Комплектация'!BF16)-Справочник!$B$4<Справочник!$B$3,1,0) -> 0 | Y27: =Справочник!$B$8 -> 4650000 | Z27: =Y27*O27/100 -> 3161618.2
... A181: =Комплектация!A170 -> 77205714 | B181: =Комплектация!C170 -> 15-1755П | C181: =Комплектация!E170 -> 2013 | D181: =MAX(0,YEAR($B$5)-C181) -> 13 | E181: =MIN(100,D181/$B$6*100) -> 40.625 | F181: =TEXT(Комплектация!V170,"0")&"/"&TEXT(Комплектация!AF170,"0")&"/"&TEXT(Комплектация!AP170,"0")&"/"&TEXT(Комплектация!AZ170,"0") -> 2013/2013/2013/2013 | G181: =AVERAGE(Комплектация!V170,Комплектация!AF170,Комплектация!AP170,Комплектация!AZ170) -> 2013 | H181: =MAX(0,YEAR($B$5)-G181) -> 13 | I181: =AVERAGE(Комплектация!AA170:'Комплектация'!AB170,Комплектация!AK170:'Комплектация'!AL170,Комплектация!AU170:'Комплектация'!AV170,Комплектация!BE170:'Комплектация'!BF170) -> 59 | J181: =MIN(Комплектация!AA170:'Комплектация'!AB170,Комплектация!AK170:'Комплектация'!AL170,Комплектация!AU170:'Комплектация'!AV170,Комплектация!BE170:'Комплектация'!BF170) -> 58 | K181: =MAX(0,MIN(100,($B$7-J181)/($B$7-$B$8)*100)) -> 0 | L181: =MAX(0,MIN(100,H181/$B$9*100)) -> 43.333333 | M181: =MAX(K181,X181/4*100)*$B$10+L181*$B$11 -> 13 | N181: =MIN(100,E181*$B$12+M181*$B$13+V181) -> 30.71661 | O181: =100-N181 -> 69.28339 | Q181: =IF(P181="","",P181*O181/100) | R181: =IF(Комплектация!G170="",Комплектация!I170,IF(Комплектация!I170="",Комплектация!G170,IF(DATE(VALUE(RIGHT(Комплектация!G170,4)),VALUE(MID(Комплектация!G170,4,2)),VALUE(LEFT(Комплектация!G170,2)))>=DATE(VALUE(RIGHT(Комплектация!I170,4)),VALUE(MID(Комплектация!I170,4,2)),VALUE(LEFT(Комплектация!I170,2))),Комплектация!G170,Комплектация!I170))) -> 24.10.2025 | S181: =Комплектация!L170 -> 24.10.2027 | T181: =IF(S181="","",MAX(0,(DATE(VALUE(RIGHT(S181,4)),VALUE(MID(S181,4,2)),VALUE(LEFT(S181,2)))-$B$5)/365.25)) -> 1.2183436 | U181: =IF(OR(R181="",S181=""),"",MAX(0,MIN(100,($B$5-DATE(VALUE(RIGHT(R181,4)),VALUE(MID(R181,4,2)),VALUE(LEFT(R181,2))))/(DATE(VALUE(RIGHT(S181,4)),VALUE(MID(S181,4,2)),VALUE(LEFT(S181,2)))-DATE(VALUE(RIGHT(R181,4)),VALUE(MID(R181,4,2)),VALUE(LEFT(R181,2))))*100))) -> 39.041096 | V181: =IF(U181="","",U181*Справочник!$B$7/100) -> 3.9041096 | W181: =J181-Справочник!$B$4 -> 43 | X181: =IF(MIN(Комплектация!AA170:'Комплектация'!AB170)-Справочник!$B$4<Справочник!$B$3,1,0)+IF(MIN(Комплектация!AK170:'Комплектация'!AL170)-Справочник!$B$4<Справочник!$B$3,1,0)+IF(MIN(Комплектация!AU170:'Комплектация'!AV170)-Справочник!$B$4<Справочник!$B$3,1,0)+IF(MIN(Комплектация!BE170:'Комплектация'!BF170)-Справочник!$B$4<Справочник!$B$3,1,0) -> 0 | Y181: =Справочник!$B$8 -> 4650000 | Z181: =Y181*O181/100 -> 3221677.7
Y182: =SUM(Y16:Y181) -> 771900000 | Z182: =SUM(Z16:Z181) -> 5.3868808e+08

Sheet Справочник
A1: Справочник технических порогов и амортизации
A2: Параметр | B2: Значение | C2: Ед. | D2: Как используется
A3: Мин. обод после обточки при ДР | B3: 35 | C3: мм | D3: После обточки колесо должно иметь не менее 35 мм
A4: Съем металла при обточке | B4: 15 | C4: мм | D4: По условию расчета при обточке снимается 15 мм
A5: Порог до ДР | B5: =B3+B4 -> 50 | C5: мм | D5: 35 мм + 15 мм = 50 мм: ниже порога колесная пара не проходит условие после обточки
A6: Текущий эксплуатационный предел | B6: 27 | C6: мм | D6: Предельное текущее значение; не заменяет требование 35 мм после обточки
A7: Макс. поправка на близость ДР | B7: 10 | C7: п.п. | D7: Модельное допущение: дополнительная амортизация при наступившем ДР; изменить при наличии фактической стоимости ДР
A8: Цена новой цистерны | B8: 4650000 | C8: ₽ / вагон | D8: Рыночная база пользователя; 100% стоимости нового вагона
A10: Сводная рыночная оценка 166 цистерн
A11: Показатель | B11: Значение
A12: Количество вагонов | B12: =COUNT(Амортизация!Z16:Z181) -> 166
A13: Средняя оценочная цена, ₽ | B13: =AVERAGE(Амортизация!Z16:Z181) -> 3245108.9
A14: Минимальная оценочная цена, ₽ | B14: =MIN(Амортизация!Z16:Z181) -> 1165512.3
A15: Максимальная оценочная цена, ₽ | B15: =MAX(Амортизация!Z16:Z181) -> 3976600.8

Sheet Комплектация
A1: Номер вагона / контейнера | B1: Род вагона | C1: Модель | D1: Дата постройки | E1: Год постройки | F1: Срок службы | G1: Дата последнего деповского ремонта | H1: Депопоследнего деповского ремонта | I1: Дата капитального | J1: Депо капитального | K1: Очередной вид ремонта | L1: Дата очередного плановго ремонта | M1: Собственник | N1: Норма пробега | O1: Пробег общий | P1: Остаточный пробег | Q1: Дата ремонта по пробегу | R1: Дата изменения комплектации | T1: Колесная пара 1 | AD1: Колесная пара 2 | AN1: Колесная пара 3 | AX1: Колесная пара 4 | BH1: Надрессорная балка 1 | BN1: Надрессорная балка 2 | BT1: Боковая рама 1 | BZ1: Боковая рама 2 | CF1: Боковая рама 3 | CL1: Боковая рама 4
T2: Номер детали | U2: Клеймо | V2: Год постр | W2: Депо | X2: Дата | Y2: Толщина гребня | AA2: Толщина обода | AD2: Номер детали | AE2: Клеймо | AF2: Год постр | AG2: Депо | AH2: Дата | AI2: Толщина гребня | AK2: Толщина обода | AN2: Номер детали | AO2: Клеймо | AP2: Год постр | AQ2: Депо | AR2: Дата | AS2: Толщина гребня | AU2: Толщина обода | AX2: Номер детали | AY2: Клеймо | AZ2: Год постр | BA2: Депо | BB2: Дата | BC2: Толщина гребня | BE2: Толщина обода | BH2: Номер детали | BI2: Клеймо | BJ2: Год постр | BK2: Депо | BL2: Дата | BN2: Номер детали | BO2: Клеймо | BP2: Год постр | BQ2: Депо | BR2: Дата | BT2: Номер детали | BU2: Клеймо | BV2: Год постр | BW2: Депо | BX2: Дата | BZ2: Номер детали | CA2: Клеймо | CB2: Год постр | CC2: Депо | CD2: Дата | CF2: Номер детали | CG2: Клеймо | CH2: Год постр | CI2: Депо | CJ2: Дата | CL2: Номер детали | CM2: Клеймо | CN2: Год постр | CO2: Депо | CP2: Дата
Y3: ЛЕВ. | Z3: ПРАВ. | AA3: ЛЕВ. | AB3: ПРАВ. | AI3: ЛЕВ. | AJ3: ПРАВ. | AK3: ЛЕВ. | AL3: ПРАВ. | AS3: ЛЕВ. | AT3: ПРАВ. | AU3: ЛЕВ. | AV3: ПРАВ. | BC3: ЛЕВ. | BD3: ПРАВ. | BE3: ЛЕВ. | BF3: ПРАВ.
A5: 77223766 | B5: Цистерна для перевозки продуктов | C5: 15-5103-7П | D5: 12.09.2011 | E5: 2011 | F5: 12.09.2043 | G5: 31.03.2023 | H5: ВРД Кочетовка – филиал ООО "НВК" | I5: 18.03.2026 | J5: Усть-Каменогорское ВРД | K5: Деповской | L5: 18.03.2029 | M5: ООО "ТрансАльянс Запад" | N5: 160000 | O5: 7663 | P5: 152337 | Q5: 11.07.2033 | R5: 18.03.2026 | T5: 107741 | U5: 0005 | V5: 2005 | W5: 745 | X5: мар.26 | Y5: 0 | Z5: 0 | AA5: 73 | AB5: 73 | AD5: 52282 | AE5: 1175 | AF5: 2012 | AG5: 745 | AH5: мар.26 | AI5: 0 | AJ5: 0 | AK5: 71 | AL5: 71 | AN5: 750688 | AO5: 0005 | AP5: 2017 | AQ5: 745 | AR5: мар.26 | AS5: 0 | AT5: 0 | AU5: 73 | AV5: 73 | AX5: 812280 | AY5: 0005 | AZ5: 2018 | BA5: 745 | BB5: мар.26 | BC5: 0 | BD5: 0 | BE5: 74 | BF5: 74 | BH5: 69894 | BI5: 0014 | BJ5: 2011 | BN5: 66505 | BO5: 0014 | BP5: 2011 | BT5: 117185 | BU5: 0014 | BV5: 2011 | BZ5: 117258 | CA5: 0014 | CB5: 2011 | CF5: 116917 | CG5: 0014 | CH5: 2011 | CL5: 117136 | CM5: 0014 | CN5: 2011
A6: 77206126 | B6: Цистерна для перевозки продуктов | C6: 15-1755П | D6: 20.06.2013 | E6: 2013 | F6: 20.06.2043 | G6: 12.02.2026 | H6: Усть-Каменогорское ВРД | I6: 02.02.2024 | J6: ВЧД Унеча-ООО "НВК" | K6: Деповской | L6: 12.02.2028 | M6: ООО "ТрансАльянс Запад" | N6: 160000 | O6: 20933 | P6: 139067 | Q6: 04.07.2029 | R6: 12.02.2026 | T6: 107656 | U6: 0005 | V6: 2014 | W6: 745 | X6: фев.26 | Y6: 0 | Z6: 0 | AA6: 72 | AB6: 72 | AD6: 227365 | AE6: 0005 | AF6: 2019 | AG6: 745 | AH6: фев.26 | AI6: 0 | AJ6: 0 | AK6: 72 | AL6: 72 | AN6: 16504 | AO6: 1175 | AP6: 2008 | AQ6: 745 | AR6: фев.26 | AS6: 0 | AT6: 0 | AU6: 74 | AV6: 74 | AX6: 844904 | AY6: 0029 | AZ6: 1990 | BA6: 745 | BB6: фев.26 | BC6: 0 | BD6: 0 | BE6: 72 | BF6: 72 | BH6: 15188 | BI6: 1291 | BJ6: 2013 | BN6: 15246 | BO6: 1291 | BP6: 2013 | BT6: 42930 | BU6: 1291 | BV6: 2013 | BZ6: 42424 | CA6: 1291 | CB6: 2013 | CF6: 38356 | CG6: 1291 | CH6: 2013 | CL6: 43316 | CM6: 1291 | CN6: 2013
A7: 77205912 | B7: Цистерна для перевозки продуктов | C7: 15-1755П | D7: 20.06.2013 | E7: 2013 | F7: 20.06.2043 | G7: 12.02.2026 | H7: Усть-Каменогорское ВРД | I7: 08.02.2024 | J7: ВРД Кочетовка – филиал ООО "НВК" | K7: Деповской | L7: 12.02.2028 | M7: ООО "ТрансАльянс Запад" | N7: 160000 | O7: 15958 | P7: 144042 | Q7: 25.07.2030 | R7: 15.06.2026 | T7: 392521 | U7: 0029 | V7: 2013 | W7: 4036 | X7: июнь.26 | Y7: 0 | Z7: 0 | AA7: 38 | AB7: 38 | AD7: 370222 | AE7: 0029 | AF7: 2012 | AG7: 4036 | AH7: июнь.26 | AI7: 0 | AJ7: 0 | AK7: 38 | AL7: 38 | AN7: 459384 | AO7: 0029 | AP7: 2013 | AQ7: 4036 | AR7: июнь.26 | AS7: 0 | AT7: 0 | AU7: 32 | AV7: 32 | AX7: 460013 | AY7: 0029 | AZ7: 2013 | BA7: 4036 | BB7: июнь.26 | BC7: 0 | BD7: 0 | BE7: 37 | BF7: 37 | BH7: 15648 | BI7: 1291 | BJ7: 2013 | BN7: 15896 | BO7: 1291 | BP7: 2013 | BT7: 46279 | BU7: 1291 | BV7: 2013 | BZ7: 45962 | CA7: 1291 | CB7: 2013 | CF7: 37854 | CG7: 1291 | CH7: 2013 | CL7: 45456 | CM7: 1291 | CN7: 2013
A8: 77206159 | B8: Цистерна для перевозки продуктов | C8: 15-1755П | D8: 20.06.2013 | E8: 2013 | F8: 20.06.2043 | G8: 12.02.2026 | H8: Усть-Каменогорское ВРД | I8: 05.02.2024 | J8: ТОО "Аждар и К" | K8: Деповской | L8: 12.02.2028 | M8: ООО "ТрансАльянс Запад" | N8: 160000 | O8: 15958 | P8: 144042 | Q8: 25.07.2030 | R8: 15.06.2026 | T8: 3029 | U8: 1175 | V8: 2011 | W8: 4036 | X8: июнь.26 | Y8: 0 | Z8: 0 | AA8: 75 | AB8: 75 | AD8: 884003 | AE8: 0029 | AF8: 2010 | AG8: 4036 | AH8: июнь.26 | AI8: 0 | AJ8: 0 | AK8: 75 | AL8: 75 | AN8: 134498 | AO8: 0005 | AP8: 2010 | AQ8: 4036 | AR8: июнь.26 | AS8: 0 | AT8: 0 | AU8: 66 | AV8: 66 | AX8: 696276 | AY8: 0029 | AZ8: 2008 | BA8: 4036 | BB8: июнь.26 | BC8: 0 | BD8: 0 | BE8: 75 | BF8: 75 | BH8: 15682 | BI8: 1291 | BJ8: 2013 | BN8: 52443 | BO8: 1291 | BP8: 2013 | BT8: 42733 | BU8: 1291 | BV8: 2013 | BZ8: 45183 | CA8: 1291 | CB8: 2013 | CF8: 42604 | CG8: 1291 | CH8: 2013 | CL8: 46047 | CM8: 1291 | CN8: 2013
A9: 77222149 | B9: Цистерна для перевозки продуктов | C9: 15-1755П | D9: 16.04.2014 | E9: 2014 | F9: 16.04.2044 | G9: 16.04.2023 | H9: ТОО "Аждар и К" | I9: 15.03.2025 | J9: ВРД Кочетовка – филиал ООО "НВК" | K9: Деповской | L9: 15.03.2027 | M9: ООО "ТрансАльянс Запад" | N9: 160000 | O9: 45837 | P9: 114163 | Q9: 10.12.2029 | R9: 15.03.2025 | T9: 444025 | U9: 0029 | V9: 2013 | W9: 301 | X9: мар.25 | Y9: 33 | Z9: 33 | AA9: 75 | AB9: 75 | AD9: 458607 | AE9: 0029 | AF9: 2013 | AG9: 301 | AH9: мар.25 | AI9: 33 | AJ9: 33 | AK9: 75 | AL9: 75 | AN9: 523344 | AO9: 0029 | AP9: 2014 | AQ9: 301 | AR9: мар.25 | AS9: 33 | AT9: 33 | AU9: 75 | AV9: 75 | AX9: 523382 | AY9: 0029 | AZ9: 2014 | BA9: 301 | BB9: мар.25 | BC9: 33 | BD9: 33 | BE9: 75 | BF9: 75 | BH9: 50753 | BI9: 1291 | BJ9: 2014 | BN9: 50876 | BO9: 1291 | BP9: 2014 | BT9: 3954 | BU9: 1291 | BV9: 2014 | BZ9: 3946 | CA9: 1291 | CB9: 2014 | CF9: 4551 | CG9: 1291 | CH9: 2014 | CL9: 3969 | CM9: 1291 | CN9: 2014
A10: 77222214 | B10: Цистерна для перевозки продуктов | C10: 15-1755П | D10: 16.04.2014 | E10: 2014 | F10: 16.04.2044 | G10: 22.03.2023 | H10: ВРД Кочетовка – филиал ООО "НВК" | I10: 03.04.2025 | J10: ВРД Кочетовка – филиал ООО "НВК" | K10: Деповской | L10: 03.04.2027 | M10: ООО "ТрансАльянс Запад" | N10: 160000 | O10: 48240 | P10: 111760 | Q10: 02.08.2029 | R10: 16.03.2026 | T10: 516474 | U10: 0029 | V10: 2013 | W10: 4046 | X10: мар.26 | Y10: 0 | Z10: 0 | AA10: 75 | AB10: 75 | AD10: 516476 | AE10: 0029 | AF10: 2013 | AG10: 4046 | AH10: мар.26 | AI10: 0 | AJ10: 0 | AK10: 75 | AL10: 75 | AN10: 523018 | AO10: 0029 | AP10: 2014 | AQ10: 4046 | AR10: мар.26 | AS10: 0 | AT10: 0 | AU10: 75 | AV10: 75 | AX10: 522934 | AY10: 0029 | AZ10: 2014 | BA10: 4046 | BB10: мар.26 | BC10: 0 | BD10: 0 | BE10: 75 | BF10: 75 | BH10: 51520 | BI10: 1291 | BJ10: 2014 | BN10: 51484 | BO10: 1291 | BP10: 2014 | BT10: 3898 | BU10: 1291 | BV10: 2014 | BZ10: 3949 | CA10: 1291 | CB10: 2014 | CF10: 403 | CG10: 1291 | CH10: 2014 | CL10: 2470 | CM10: 1291 | CN10: 2014
A11: 77206076 | B11: Цистерна для перевозки продуктов | C11: 15-1755П | D11: 20.06.2013 | E11: 2013 | F11: 20.06.2043 | G11: 14.02.2026 | H11: Усть-Каменогорское ВРД | I11: 04.02.2024 | J11: ТОО "Аждар и К" | K11: Деповской | L11: 14.02.2028 | M11: ООО "ТрансАльянс Запад" | N11: 160000 | O11: 15959 | P11: 144041 | Q11: 07.07.2030 | R11: 14.02.2026 | T11: 17411 | U11: 0039 | V11: 2005 | W11: 745 | X11: фев.26 | Y11: 0 | Z11: 0 | AA11: 75 | AB11: 75 | AD11: 61059 | AE11: 1175 | AF11: 2013 | AG11: 745 | AH11: фев.26 | AI11: 0 | AJ11: 0 | AK11: 72 | AL11: 72 | AN11: 27784 | AO11: 1175 | AP11: 2007 | AQ11: 745 | AR11: фев.26 | AS11: 0 | AT11: 0 | AU11: 71 | AV11: 71 | AX11: 61686 | AY11: 0039 | AZ11: 2010 | BA11: 745 | BB11: фев.26 | BC11: 0 | BD11: 0 | BE11: 70 | BF11: 70 | BH11: 14096 | BI11: 1291 | BJ11: 2013 | BN11: 13922 | BO11: 1291 | BP11: 2013 | BT11: 41746 | BU11: 1291 | BV11: 2013 | BZ11: 41214 | CA11: 1291 | CB11: 2013 | CF11: 42087 | CG11: 1291 | CH11: 2013 | CL11: 41710 | CM11: 1291 | CN11: 2013
A12: 77228781 | B12: Цистерна для перевозки продуктов | C12: 15-5103-7П | D12: 19.01.2015 | E12: 2015 | F12: 19.01.2047 | G12: 20.08.2025 | H12: Орский ВРЗ-филиал ООО "НВК" | K12: Капитальный | L12: 20.08.2028 | M12: ООО "ТрансАльянс Запад" | N12: 160000 | O12: 45251 | P12: 114749 | Q12: 27.11.2028 | R12: 20.08.2025 | T12: 881967 | U12: 0029 | V12: 2010 | W12: 2348 | X12: авг.25 | Y12: 30 | Z12: 30 | AA12: 60 | AB12: 60 | AD12: 133082 | AE12: 0005 | AF12: 2014 | AG12: 2348 | AH12: авг.25 | AI12: 30 | AJ12: 30 | AK12: 60 | AL12: 60 | AN12: 132197 | AO12: 0005 | AP12: 2014 | AQ12: 2348 | AR12: авг.25 | AS12: 30 | AT12: 30 | AU12: 58 | AV12: 58 | AX12: 389220 | AY12: 0005 | AZ12: 2013 | BA12: 2348 | BB12: авг.25 | BC12: 30 | BD12: 30 | BE12: 59 | BF12: 58 | BH12: 34861 | BI12: 0005 | BJ12: 2014 | BN12: 35626 | BO12: 0005 | BP12: 2014 | BT12: 920 | BU12: 0005 | BV12: 2015 | BZ12: 1398 | CA12: 0005 | CB12: 2015 | CF12: 1466 | CG12: 0005 | CH12: 2015 | CL12: 1898 | CM12: 0005 | CN12: 2015
A13: 77221810 | B13: Цистерна для перевозки продуктов | C13: 15-5103-7П | D13: 06.09.2011 | E13: 2011 | F13: 06.09.2043 | G13: 21.12.2022 | H13: ВЧДР Ульяновск – ОСП АО "ОМК Стальной путь" | I13: 21.08.2025 | J13: ВРЗ Челябинск – филиал ООО "НВК" | K13: Деповской | L13: 21.08.2028 | M13: ООО "ТрансАльянс Запад" | N13: 160000 | O13: 36954 | P13: 123046 | Q13: 19.08.2029 | R13: 21.08.2025 | T13: 387818 | U13: 0005 | V13: 2013 | W13: 600 | X13: авг.25 | Y13: 33 | Z13: 33 | AA13: 71 | AB13: 70 | AD13: 285936 | AE13: 0005 | AF13: 2011 | AG13: 600 | AH13: авг.25 | AI13: 33 | AJ13: 33 | AK13: 74 | AL13: 74 | AN13: 144857 | AO13: 0005 | AP13: 2014 | AQ13: 600 | AR13: авг.25 | AS13: 33 | AT13: 33 | AU13: 71 | AV13: 71 | AX13: 285133 | AY13: 0005 | AZ13: 2011 | BA13: 600 | BB13: авг.25 | BC13: 33 | BD13: 33 | BE13: 73 | BF13: 73 | BH13: 38533 | BI13: 0005 | BJ13: 2011 | BN13: 38400 | BO13: 0005 | BP13: 2011 | BT13: 64559 | BU13: 0005 | BV13: 2011 | BZ13: 67459 | CA13: 0005 | CB13: 2011 | CF13: 67635 | CG13: 0005 | CH13: 2011 | CL13: 66238 | CM13: 0005 | CN13: 2011
A14: 77228724 | B14: Цистерна для перевозки продуктов | C14: 15-5103-7П | D14: 19.01.2015 | E14: 2015 | F14: 19.01.2047 | G14: 20.08.2025 | H14: Орский ВРЗ-филиал ООО "НВК" | K14: Капитальный | L14: 20.08.2028 | M14: ООО "ТрансАльянс Запад" | N14: 160000 | O14: 36244 | P14: 123756 | Q14: 20.09.2029 | R14: 20.08.2025 | T14: 300837 | U14: 0005 | V14: 2015 | W14: 2348 | X14: авг.25 | Y14: 30 | Z14: 30 | AA14: 47 | AB14: 47 | AD14: 303165 | AE14: 0005 | AF14: 2015 | AG14: 2348 | AH14: авг.25 | AI14: 30 | AJ14: 30 | AK14: 43 | AL14: 43 | AN14: 301420 | AO14: 0005 | AP14: 2015 | AQ14: 2348 | AR14: авг.25 | AS14: 30 | AT14: 30 | AU14: 41 | AV14: 41 | AX14: 207759 | AY14: 0005 | AZ14: 2014 | BA14: 2348 | BB14: авг.25 | BC14: 30 | BD14: 30 | BE14: 42 | BF14: 42 | BH14: 35428 | BI14: 0005 | BJ14: 2014 | BN14: 35655 | BO14: 0005 | BP14: 2014 | BT14: 2572 | BU14: 0005 | BV14: 2015 | BZ14: 1213 | CA14: 0005 | CB14: 2015 | CF14: 1582 | CG14: 0005 | CH14: 2015 | CL14: 1625 | CM14: 0005 | CN14: 2015
A15: 77222040 | B15: Цистерна для перевозки продуктов | C15: 15-150-04П | D15: 31.08.2011 | E15: 2011 | F15: 31.08.2043 | G15: 19.01.2023 | H15: ВРД Кочетовка – филиал ООО "НВК" | I15: 22.08.2025 | J15: ВРЗ Челябинск – филиал ООО "НВК" | K15: Деповской | L15: 22.08.2028 | M15: ООО "ТрансАльянс Запад" | N15: 160000 | O15: 36020 | P15: 123980 | Q15: 23.09.2029 | R15: 22.08.2025 | T15: 361758 | U15: 0005 | V15: 2013 | W15: 600 | X15: авг.25 | Y15: 29 | Z15: 29 | AA15: 64 | AB15: 63 | AD15: 283089 | AE15: 0005 | AF15: 2011 | AG15: 600 | AH15: авг.25 | AI15: 29 | AJ15: 29 | AK15: 66 | AL15: 67 | AN15: 361783 | AO15: 0005 | AP15: 2013 | AQ15: 600 | AR15: авг.25 | AS15: 29 | AT15: 29 | AU15: 67 | AV15: 67 | AX15: 178288 | AY15: 0005 | AZ15: 2014 | BA15: 600 | BB15: авг.25 | BC15: 29 | BD15: 29 | BE15: 68 | BF15: 68 | BH15: 37526 | BI15: 0005 | BJ15: 2011 | BN15: 36840 | BO15: 0005 | BP15: 2011 | BT15: 65174 | BU15: 0005 | BV15: 2011 | BZ15: 64960 | CA15: 0005 | CB15: 2011 | CF15: 66375 | CG15: 0005 | CH15: 2011 | CL15: 66315 | CM15: 0005 | CN15: 2011
A16: 77227080 | B16: Цистерна для перевозки продуктов | C16: 15-5103-7П | D16: 19.01.2012 | E16: 2012 | F16: 19.01.2044 | G16: 29.09.2022 | H16: ВЧД Унеча-ООО "НВК" | I16: 23.09.2025 | J16: ВРЗ Челябинск – филиал ООО "НВК" | K16: Деповской | L16: 23.09.2028 | M16: ООО "ТрансАльянс Запад" | N16: 160000 | O16: 42876 | P16: 117124 | Q16: 31.10.2028 | R16: 23.09.2025 | T16: 122882 | U16: 0005 | V16: 2012 | W16: 600 | X16: сен.25 | Y16: 29 | Z16: 29 | AA16: 71 | AB16: 71 | AD16: 123143 | AE16: 0005 | AF16: 2012 | AG16: 600 | AH16: сен.25 | AI16: 29 | AJ16: 29 | AK16: 71 | AL16: 71 | AN16: 305740 | AO16: 0005 | AP16: 2011 | AQ16: 600 | AR16: сен.25 | AS16: 29 | AT16: 29 | AU16: 72 | AV16: 71 | AX16: 315082 | AY16: 0005 | AZ16: 2011 | BA16: 600 | BB16: сен.25 | BC16: 29 | BD16: 29 | BE16: 72 | BF16: 73 | BH16: 49779 | BI16: 0005 | BJ16: 2011 | BN16: 3063 | BO16: 0005 | BP16: 2012 | BT16: 88660 | BU16: 0005 | BV16: 2011 | BZ16: 86578 | CA16: 0005 | CB16: 2011 | CF16: 95277 | CG16: 0005 | CH16: 2012 | CL16: 5895 | CM16: 0005 | CN16: 2012
A17: 77228773 | B17: Цистерна для перевозки продуктов | C17: 15-5103-7П | D17: 19.01.2015 | E17: 2015 | F17: 19.01.2047 | G17: 24.08.2025 | H17: Орский ВРЗ-филиал ООО "НВК" | K17: Капитальный | L17: 24.08.2028 | M17: ООО "ТрансАльянс Запад" | N17: 160000 | O17: 39135 | P17: 120865 | Q17: 21.05.2029 | R17: 24.08.2025 | T17: 975384 | U17: 0029 | V17: 2011 | W17: 2348 | X17: авг.25 | Y17: 30 | Z17: 30 | AA17: 53 | AB17: 51 | AD17: 26652 | AE17: 0039 | AF17: 2006 | AG17: 2348 | AH17: авг.25 | AI17: 30 | AJ17: 30 | AK17: 56 | AL17: 55 | AN17: 861974 | AO17: 0029 | AP17: 1990 | AQ17: 2348 | AR17: авг.25 | AS17: 30 | AT17: 30 | AU17: 58 | AV17: 58 | AX17: 108425 | AY17: 0005 | AZ17: 2006 | BA17: 2348 | BB17: авг.25 | BC17: 30 | BD17: 30 | BE17: 58 | BF17: 57 | BH17: 35195 | BI17: 0005 | BJ17: 2014 | BN17: 34646 | BO17: 0005 | BP17: 2014 | BT17: 69675 | BU17: 0005 | BV17: 2014 | BZ17: 69237 | CA17: 0005 | CB17: 2014 | CF17: 69365 | CG17: 0005 | CH17: 2014 | CL17: 69725 | CM17: 0005 | CN17: 2014
A18: 77221950 | B18: Цистерна для перевозки продуктов | C18: 15-150-04П | D18: 28.02.2012 | E18: 2012 | F18: 28.02.2044 | G18: 19.09.2022 | H18: ВРД Кочетовка – филиал ООО "НВК" | I18: 21.08.2025 | J18: ВРЗ Челябинск – филиал ООО "НВК" | K18: Деповской | L18: 21.08.2028 | M18: ООО "ТрансАльянс Запад" | N18: 160000 | O18: 34259 | P18: 125741 | Q18: 12.12.2029 | R18: 21.08.2025 | T18: 170868 | U18: 0005 | V18: 2007 | W18: 600 | X18: авг.25 | Y18: 33 | Z18: 33 | AA18: 73 | AB18: 73 | AD18: 151700 | AE18: 0029 | AF18: 1992 | AG18: 600 | AH18: авг.25 | AI18: 33 | AJ18: 33 | AK18: 74 | AL18: 74 | AN18: 122486 | AO18: 0005 | AP18: 2012 | AQ18: 600 | AR18: авг.25 | AS18: 33 | AT18: 33 | AU18: 74 | AV18: 74 | AX18: 123286 | AY18: 0005 | AZ18: 2012 | BA18: 600 | BB18: авг.25 | BC18: 33 | BD18: 33 | BE18: 74 | BF18: 73 | BH18: 10219 | BI18: 0014 | BJ18: 2012 | BN18: 3246 | BO18: 0014 | BP18: 2012 | BT18: 10126 | BU18: 0014 | BV18: 2012 | BZ18: 504892 | CA18: 0014 | CB18: 2012 | CF18: 14196 | CG18: 0014 | CH18: 2012 | CL18: 306 | CM18: 0014 | CN18: 2012
A19: 77205664 | B19: Цистерна для перевозки продуктов | C19: 15-1755П | D19: 20.06.2013 | E19: 2013 | F19: 20.06.2043 | G19: 29.08.2025 | H19: Орский ВРЗ-филиал ООО "НВК" | I19: 27.01.2024 | J19: ВРЗ Челябинск – филиал ООО "НВК" | K19: Деповской | L19: 29.08.2027 | M19: ООО "ТрансАльянс Запад" | N19: 160000 | O19: 35111 | P19: 124889 | Q19: 06.10.2029 | R19: 29.08.2025 | T19: 442976 | U19: 0029 | V19: 2013 | W19: 2348 | X19: авг.25 | Y19: 33 | Z19: 33 | AA19: 74 | AB19: 74 | AD19: 459729 | AE19: 0029 | AF19: 2013 | AG19: 2348 | AH19: авг.25 | AI19: 33 | AJ19: 33 | AK19: 74 | AL19: 74 | AN19: 459998 | AO19: 0029 | AP19: 2013 | AQ19: 2348 | AR19: авг.25 | AS19: 33 | AT19: 33 | AU19: 74 | AV19: 74 | AX19: 459372 | AY19: 0029 | AZ19: 2013 | BA19: 2348 | BB19: авг.25 | BC19: 33 | BD19: 33 | BE19: 74 | BF19: 74 | BH19: 52104 | BI19: 1291 | BJ19: 2013 | BN19: 14349 | BO19: 1291 | BP19: 2013 | BT19: 37899 | BU19: 1291 | BV19: 2013 | BZ19: 38264 | CA19: 1291 | CB19: 2013 | CF19: 42407 | CG19: 1291 | CH19: 2013 | CL19: 42444 | CM19: 1291 | CN19: 2013
A20: 77205706 | B20: Цистерна для перевозки продуктов | C20: 15-1755П | D20: 20.06.2013 | E20: 2013 | F20: 20.06.2043 | G20: 06.09.2025 | H20: Орский ВРЗ-филиал ООО "НВК" | I20: 17.01.2024 | J20: ВЧД Унеча-ООО "НВК" | K20: Деповской | L20: 06.09.2027 | M20: ООО "ТрансАльянс Запад" | N20: 160000 | O20: 36116 | P20: 123884 | Q20: 29.07.2029 | R20: 06.09.2025 | T20: 369126 | U20: 0029 | V20: 2012 | W20: 2348 | X20: сен.25 | Y20: 30 | Z20: 30 | AA20: 55 | AB20: 55 | AD20: 51638 | AE20: 2412 | AF20: 2024 | AG20: 2348 | AH20: сен.25 | AI20: 30 | AJ20: 30 | AK20: 54 | AL20: 54 | AN20: 325321 | AO20: 0029 | AP20: 2012 | AQ20: 2348 | AR20: сен.25 | AS20: 30 | AT20: 30 | AU20: 48 | AV20: 48 | AX20: 308575 | AY20: 0029 | AZ20: 2012 | BA20: 2348 | BB20: сен.25 | BC20: 30 | BD20: 30 | BE20: 51 | BF20: 51 | BH20: 14317 | BI20: 1291 | BJ20: 2013 | BN20: 14674 | BO20: 1291 | BP20: 2013 | BT20: 42624 | BU20: 1291 | BV20: 2013 | BZ20: 40631 | CA20: 1291 | CB20: 2013 | CF20: 44747 | CG20: 1291 | CH20: 2013 | CL20: 44767 | CM20: 1291 | CN20: 2013
A21: 77205888 | B21: Цистерна для перевозки продуктов | C21: 15-1755П | D21: 20.06.2013 | E21: 2013 | F21: 20.06.2043 | G21: 24.08.2025 | H21: Орский ВРЗ-филиал ООО "НВК" | I21: 31.01.2024 | J21: ВРД Кочетовка – филиал ООО "НВК" | K21: Деповской | L21: 24.08.2027 | M21: ООО "ТрансАльянс Запад" | N21: 160000 | O21: 31425 | P21: 128575 | Q21: 21.04.2030 | R21: 24.08.2025 | T21: 444796 | U21: 0029 | V21: 2013 | W21: 2348 | X21: авг.25 | Y21: 30 | Z21: 30 | AA21: 62 | AB21: 61 | AD21: 443687 | AE21: 0029 | AF21: 2013 | AG21: 2348 | AH21: авг.25 | AI21: 30 | AJ21: 30 | AK21: 63 | AL21: 63 | AN21: 443345 | AO21: 0029 | AP21: 2013 | AQ21: 2348 | AR21: авг.25 | AS21: 30 | AT21: 30 | AU21: 59 | AV21: 59 | AX21: 455903 | AY21: 0029 | AZ21: 2013 | BA21: 2348 | BB21: авг.25 | BC21: 30 | BD21: 30 | BE21: 62 | BF21: 62 | BH21: 15045 | BI21: 1291 | BJ21: 2013 | BN21: 15233 | BO21: 1291 | BP21: 2013 | BT21: 44652 | BU21: 1291 | BV21: 2013 | BZ21: 44087 | CA21: 1291 | CB21: 2013 | CF21: 42795 | CG21: 1291 | CH21: 2013 | CL21: 42357 | CM21: 1291 | CN21: 2013
A22: 77221919 | B22: Цистерна для перевозки продуктов | C22: 15-5103-7П | D22: 06.09.2011 | E22: 2011 | F22: 06.09.2043 | G22: 20.02.2023 | H22: ВРД Кочетовка – филиал ООО "НВК" | I22: 02.02.2025 | J22: ВЧД Унеча-ООО "НВК" | K22: Деповской | L22: 02.02.2028 | M22: ООО "ТрансАльянс Запад" | N22: 160000 | O22: 45858 | P22: 114142 | Q22: 22.03.2030 | R22: 02.02.2025 | T22: 285774 | U22: 0005 | V22: 2011 | W22: 357 | X22: фев.25 | Y22: 33 | Z22: 33 | AA22: 74 | AB22: 74 | AD22: 285824 | AE22: 0005 | AF22: 2011 | AG22: 357 | AH22: фев.25 | AI22: 33 | AJ22: 33 | AK22: 73 | AL22: 73 | AN22: 180370 | AO22: 0005 | AP22: 2014 | AQ22: 357 | AR22: фев.25 | AS22: 33 | AT22: 33 | AU22: 73 | AV22: 73 | AX22: 286908 | AY22: 0005 | AZ22: 2011 | BA22: 357 | BB22: фев.25 | BC22: 33 | BD22: 33 | BE22: 73 | BF22: 73 | BH22: 38613 | BI22: 0005 | BJ22: 2011 | BN22: 38286 | BO22: 0005 | BP22: 2011 | BT22: 63621 | BU22: 0005 | BV22: 2011 | BZ22: 67432 | CA22: 0005 | CB22: 2011 | CF22: 67508 | CG22: 0005 | CH22: 2011 | CL22: 67584 | CM22: 0005 | CN22: 2011
A23: 77221844 | B23: Цистерна для перевозки продуктов | C23: 15-150-04П | D23: 31.08.2011 | E23: 2011 | F23: 31.08.2043 | G23: 18.02.2023 | H23: ВРД Кочетовка – филиал ООО "НВК" | I23: 26.03.2026 | J23: Усть-Каменогорское ВРД | K23: Деповской | L23: 26.03.2029 | M23: ООО "ТрансАльянс Запад" | N23: 160000 | O23: 8028 | P23: 151972 | Q23: 12.10.2032 | R23: 26.03.2026 | T23: 363178 | U23: 0005 | V23: 2013 | W23: 745 | X23: мар.26 | Y23: 0 | Z23: 0 | AA23: 73 | AB23: 73 | AD23: 285305 | AE23: 0005 | AF23: 2011 | AG23: 745 | AH23: мар.26 | AI23: 0 | AJ23: 0 | AK23: 73 | AL23: 73 | AN23: 282111 | AO23: 0005 | AP23: 2011 | AQ23: 745 | AR23: мар.26 | AS23: 0 | AT23: 0 | AU23: 72 | AV23: 72 | AX23: 285278 | AY23: 0005 | AZ23: 2011 | BA23: 745 | BB23: мар.26 | BC23: 0 | BD23: 0 | BE23: 73 | BF23: 73 | BH23: 37070 | BI23: 0005 | BJ23: 2011 | BN23: 37413 | BO23: 0005 | BP23: 2011 | BT23: 66136 | BU23: 0005 | BV23: 2011 | BZ23: 65255 | CA23: 0005 | CB23: 2011 | CF23: 66052 | CG23: 0005 | CH23: 2011 | CL23: 63648 | CM23: 0005 | CN23: 2011
A24: 75183491 | B24: Цистерна для перевозки продуктов | C24: 15-1219-1П | D24: 08.10.2020 | E24: 2020 | F24: 08.10.2050 | G24: 30.10.2025 | H24: ВРД Зелецино - филиал ООО "НВК" | K24: Деповской | L24: 30.10.2027 | M24: ООО "ТрансАльянс Запад" | N24: 160000 | O24: 25151 | P24: 134849 | Q24: 25.06.2030 | R24: 30.10.2025 | T24: 12278 | U24: 2002 | V24: 2020 | W24: 1173 | X24: окт.25 | Y24: 30 | Z24: 30 | AA24: 50 | AB24: 52 | AD24: 446185 | AE24: 0005 | AF24: 2020 | AG24: 1173 | AH24: окт.25 | AI24: 30 | AJ24: 30 | AK24: 43 | AL24: 45 | AN24: 446107 | AO24: 0005 | AP24: 2020 | AQ24: 1173 | AR24: окт.25 | AS24: 30 | AT24: 30 | AU24: 51 | AV24: 53 | AX24: 446117 | AY24: 0005 | AZ24: 2020 | BA24: 1173 | BB24: окт.25 | BC24: 30 | BD24: 29 | BE24: 53 | BF24: 55 | BH24: 27363 | BI24: 1275 | BJ24: 2020 | BN24: 27358 | BO24: 1275 | BP24: 2020 | BT24: 45585 | BU24: 1275 | BV24: 2020 | BZ24: 45569 | CA24: 1275 | CB24: 2020 | CF24: 41311 | CG24: 1275 | CH24: 2020 | CL24: 45586 | CM24: 1275 | CN24: 2020
A25: 75184093 | B25: Цистерна для перевозки продуктов | C25: 15-1219-1П | D25: 08.10.2020 | E25: 2020 | F25: 08.10.2050 | G25: 19.10.2025 | H25: ВРД Зелецино - филиал ООО "НВК" | K25: Деповской | L25: 19.10.2027 | M25: ООО "ТрансАльянс Запад" | N25: 160000 | O25: 26103 | P25: 133897 | Q25: 19.06.2030 | R25: 19.10.2025 | T25: 735030 | U25: 0029 | V25: 2020 | W25: 1173 | X25: окт.25 | Y25: 30 | Z25: 30 | AA25: 61 | AB25: 60 | AD25: 753604 | AE25: 0029 | AF25: 2020 | AG25: 1173 | AH25: окт.25 | AI25: 29 | AJ25: 29 | AK25: 59 | AL25: 61 | AN25: 448491 | AO25: 0005 | AP25: 2020 | AQ25: 1173 | AR25: окт.25 | AS25: 29 | AT25: 29 | AU25: 56 | AV25: 54 | AX25: 449053 | AY25: 0005 | AZ25: 2020 | BA25: 1173 | BB25: окт.25 | BC25: 29 | BD25: 30 | BE25: 61 | BF25: 62 | BH25: 27088 | BI25: 1275 | BJ25: 2020 | BN25: 27518 | BO25: 1275 | BP25: 2020 | BT25: 46122 | BU25: 1275 | BV25: 2020 | BZ25: 45988 | CA25: 1275 | CB25: 2020 | CF25: 44631 | CG25: 1275 | CH25: 2020 | CL25: 45967 | CM25: 1275 | CN25: 2020
A26: 75184598 | B26: Цистерна для перевозки продуктов | C26: 15-1219-1П | D26: 08.10.2020 | E26: 2020 | F26: 08.10.2050 | G26: 22.09.2025 | H26: ВРД Зелецино - филиал ООО "НВК" | K26: Деповской | L26: 22.09.2027 | M26: ООО "ТрансАльянс Запад" | N26: 160000 | O26: 19620 | P26: 140380 | Q26: 14.07.2032 | R26: 22.09.2025 | T26: 741894 | U26: 0029 | V26: 2020 | W26: 1173 | X26: сен.25 | Y26: 29 | Z26: 30 | AA26: 57 | AB26: 56 | AD26: 12169 | AE26: 2002 | AF26: 2020 | AG26: 1173 | AH26: сен.25 | AI26: 30 | AJ26: 30 | AK26: 58 | AL26: 58 | AN26: 12264 | AO26: 2002 | AP26: 2020 | AQ26: 1173 | AR26: сен.25 | AS26: 30 | AT26: 30 | AU26: 58 | AV26: 60 | AX26: 742389 | AY26: 0029 | AZ26: 2020 | BA26: 1173 | BB26: сен.25 | BC26: 30 | BD26: 30 | BE26: 64 | BF26: 64 | BH26: 27548 | BI26: 1275 | BJ26: 2020 | BN26: 25966 | BO26: 1275 | BP26: 2020 | BT26: 46331 | BU26: 1275 | BV26: 2020 | BZ26: 46029 | CA26: 1275 | CB26: 2020 | CF26: 46344 | CG26: 1275 | CH26: 2020 | CL26: 46300 | CM26: 1275 | CN26: 2020
A27: 75186890 | B27: Цистерна для перевозки продуктов | C27: 15-1219-1П | D27: 14.10.2020 | E27: 2020 | F27: 14.10.2050 | G27: 10.12.2025 | H27: ВРД Зелецино - филиал ООО "НВК" | K27: Деповской | L27: 10.12.2027 | M27: ООО "ТрансАльянс Запад" | N27: 160000 | O27: 27005 | P27: 132995 | Q27: 10.08.2029 | R27: 10.12.2025 | T27: 751445 | U27: 0029 | V27: 2020 | W27: 1173 | X27: дек.25 | Y27: 30 | Z27: 29 | AA27: 64 | AB27: 65 | AD27: 749474 | AE27: 0029 | AF27: 2020 | AG27: 1173 | AH27: дек.25 | AI27: 29 | AJ27: 30 | AK27: 68 | AL27: 68 | AN27: 753559 | AO27: 0029 | AP27: 2020 | AQ27: 1173 | AR27: дек.25 | AS27: 29 | AT27: 29 | AU27: 55 | AV27: 55 | AX27: 753540 | AY27: 0029 | AZ27: 2020 | BA27: 1173 | BB27: дек.25 | BC27: 30 | BD27: 30 | BE27: 63 | BF27: 62 | BH27: 25753 | BI27: 1275 | BJ27: 2020 | BN27: 25641 | BO27: 1275 | BP27: 2020 | BT27: 41210 | BU27: 1275 | BV27: 2020 | BZ27: 42182 | CA27: 1275 | CB27: 2020 | CF27: 42410 | CG27: 1275 | CH27: 2020 | CL27: 42415 | CM27: 1275 | CN27: 2020
